[2025-01-10 05:46:00 +0000] [37131] [INFO] Starting gunicorn 23.0.0
[2025-01-10 05:46:00 +0000] [37131] [INFO] Listening at: http://127.0.0.1:8000 (37131)
[2025-01-10 05:46:00 +0000] [37131] [INFO] Using worker: sync
[2025-01-10 05:46:00 +0000] [37133] [INFO] Booting worker with pid: 37133
[2025-01-10 05:46:00 +0000] [37136] [INFO] Booting worker with pid: 37136
[2025-01-10 05:46:00 +0000] [37137] [INFO] Booting worker with pid: 37137
[2025-01-10 05:46:00 +0000] [37138] [INFO] Booting worker with pid: 37138
[2025-01-10 05:46:02 +0000] [37133] [INFO] Worker exiting (pid: 37133)
[2025-01-10 05:46:02 +0000] [37137] [INFO] Worker exiting (pid: 37137)
[2025-01-10 05:46:02 +0000] [37136] [INFO] Worker exiting (pid: 37136)
[2025-01-10 05:46:02 +0000] [37138] [INFO] Worker exiting (pid: 37138)
[2025-01-10 05:46:02 +0000] [37131] [ERROR] Worker (pid:37133) exited with code 4
[2025-01-10 05:46:02 +0000] [37131] [ERROR] Worker (pid:37137) was sent SIGTERM!
[2025-01-10 05:46:02 +0000] [37131] [ERROR] Worker (pid:37136) was sent SIGTERM!
[2025-01-10 05:46:02 +0000] [37131] [ERROR] Worker (pid:37138) was sent SIGTERM!
[2025-01-10 05:46:02 +0000] [37131] [ERROR] Shutting down: Master
[2025-01-10 05:46:02 +0000] [37131] [ERROR] Reason: App failed to load.
[2025-01-10 05:48:44 +0000] [38281] [INFO] Starting gunicorn 23.0.0
[2025-01-10 05:48:44 +0000] [38281] [INFO] Listening at: http://127.0.0.1:8000 (38281)
[2025-01-10 05:48:44 +0000] [38281] [INFO] Using worker: sync
[2025-01-10 05:48:44 +0000] [38283] [INFO] Booting worker with pid: 38283
[2025-01-10 05:48:44 +0000] [38285] [INFO] Booting worker with pid: 38285
[2025-01-10 05:48:44 +0000] [38287] [INFO] Booting worker with pid: 38287
[2025-01-10 05:48:44 +0000] [38288] [INFO] Booting worker with pid: 38288
[2025-01-10 05:48:46 +0000] [38283] [INFO] Worker exiting (pid: 38283)
[2025-01-10 05:48:46 +0000] [38285] [INFO] Worker exiting (pid: 38285)
[2025-01-10 05:48:46 +0000] [38287] [INFO] Worker exiting (pid: 38287)
[2025-01-10 05:48:46 +0000] [38288] [INFO] Worker exiting (pid: 38288)
[2025-01-10 05:48:47 +0000] [38281] [ERROR] Worker (pid:38283) exited with code 4
[2025-01-10 05:48:47 +0000] [38281] [ERROR] Worker (pid:38285) was sent SIGTERM!
[2025-01-10 05:48:47 +0000] [38281] [ERROR] Worker (pid:38288) was sent SIGTERM!
[2025-01-10 05:48:47 +0000] [38281] [ERROR] Worker (pid:38287) was sent SIGTERM!
[2025-01-10 05:48:47 +0000] [38281] [ERROR] Shutting down: Master
[2025-01-10 05:48:47 +0000] [38281] [ERROR] Reason: App failed to load.
[2025-01-10 05:51:11 +0000] [40144] [INFO] Starting gunicorn 23.0.0
[2025-01-10 05:51:11 +0000] [40144] [INFO] Listening at: http://127.0.0.1:8000 (40144)
[2025-01-10 05:51:11 +0000] [40144] [INFO] Using worker: sync
[2025-01-10 05:51:11 +0000] [40145] [INFO] Booting worker with pid: 40145
[2025-01-10 05:51:11 +0000] [40148] [INFO] Booting worker with pid: 40148
[2025-01-10 05:51:11 +0000] [40149] [INFO] Booting worker with pid: 40149
[2025-01-10 05:51:11 +0000] [40150] [INFO] Booting worker with pid: 40150
[2025-01-10 05:57:00 +0000] [40144] [INFO] Handling signal: term
[2025-01-10 05:57:00 +0000] [40145] [INFO] Worker exiting (pid: 40145)
[2025-01-10 05:57:00 +0000] [40148] [INFO] Worker exiting (pid: 40148)
[2025-01-10 05:57:00 +0000] [40149] [INFO] Worker exiting (pid: 40149)
[2025-01-10 05:57:00 +0000] [40150] [INFO] Worker exiting (pid: 40150)
[2025-01-10 05:57:00 +0000] [40144] [ERROR] Worker (pid:40145) was sent SIGTERM!
[2025-01-10 05:57:00 +0000] [40144] [ERROR] Worker (pid:40148) was sent SIGTERM!
[2025-01-10 05:57:00 +0000] [40144] [ERROR] Worker (pid:40149) was sent SIGTERM!
[2025-01-10 05:57:00 +0000] [40144] [INFO] Shutting down: Master
[2025-01-10 05:57:05 +0000] [43620] [INFO] Starting gunicorn 23.0.0
[2025-01-10 05:57:05 +0000] [43620] [INFO] Listening at: http://127.0.0.1:8000 (43620)
[2025-01-10 05:57:05 +0000] [43620] [INFO] Using worker: sync
[2025-01-10 05:57:05 +0000] [43622] [INFO] Booting worker with pid: 43622
[2025-01-10 05:57:05 +0000] [43625] [INFO] Booting worker with pid: 43625
[2025-01-10 05:57:05 +0000] [43626] [INFO] Booting worker with pid: 43626
[2025-01-10 05:57:05 +0000] [43627] [INFO] Booting worker with pid: 43627
[2025-01-10 05:57:07 +0000] [43622] [ERROR] Exception in worker process
Traceback (most recent call last):
  File "/home/ec2-user/test_form/.venv/lib64/python3.12/site-packages/gunicorn/arbiter.py", line 608, in spawn_worker
    worker.init_process()
  File "/home/ec2-user/test_form/.venv/lib64/python3.12/site-packages/gunicorn/workers/base.py", line 135, in init_process
    self.load_wsgi()
  File "/home/ec2-user/test_form/.venv/lib64/python3.12/site-packages/gunicorn/workers/base.py", line 147, in load_wsgi
    self.wsgi = self.app.wsgi()
                ^^^^^^^^^^^^^^^
  File "/home/ec2-user/test_form/.venv/lib64/python3.12/site-packages/gunicorn/app/base.py", line 66, in wsgi
    self.callable = self.load()
                    ^^^^^^^^^^^
  File "/home/ec2-user/test_form/.venv/lib64/python3.12/site-packages/gunicorn/app/wsgiapp.py", line 57, in load
    return self.load_wsgiapp()
           ^^^^^^^^^^^^^^^^^^^
  File "/home/ec2-user/test_form/.venv/lib64/python3.12/site-packages/gunicorn/app/wsgiapp.py", line 47, in load_wsgiapp
    return util.import_app(self.app_uri)
           ^^^^^^^^^^^^^^^^^^^^^^^^^^^^^
  File "/home/ec2-user/test_form/.venv/lib64/python3.12/site-packages/gunicorn/util.py", line 370, in import_app
    mod = importlib.import_module(module)
          ^^^^^^^^^^^^^^^^^^^^^^^^^^^^^^^
  File "/usr/lib64/python3.12/importlib/__init__.py", line 90, in import_module
    return _bootstrap._gcd_import(name[level:], package, level)
           ^^^^^^^^^^^^^^^^^^^^^^^^^^^^^^^^^^^^^^^^^^^^^^^^^^^^
  File "<frozen importlib._bootstrap>", line 1387, in _gcd_import
  File "<frozen importlib._bootstrap>", line 1360, in _find_and_load
  File "<frozen importlib._bootstrap>", line 1331, in _find_and_load_unlocked
  File "<frozen importlib._bootstrap>", line 935, in _load_unlocked
  File "<frozen importlib._bootstrap_external>", line 995, in exec_module
  File "<frozen importlib._bootstrap>", line 488, in _call_with_frames_removed
  File "/home/ec2-user/test_form/wsgi.py", line 1, in <module>
    from app import create_app
  File "/home/ec2-user/test_form/app/__init__.py", line 4, in <module>
    from app.routes import routes
  File "/home/ec2-user/test_form/app/routes.py", line 2, in <module>
    from app.views import users
ModuleNotFoundError: No module named 'app.views'
[2025-01-10 05:57:07 +0000] [43622] [INFO] Worker exiting (pid: 43622)
[2025-01-10 05:57:07 +0000] [43626] [ERROR] Exception in worker process
Traceback (most recent call last):
  File "/home/ec2-user/test_form/.venv/lib64/python3.12/site-packages/gunicorn/arbiter.py", line 608, in spawn_worker
    worker.init_process()
  File "/home/ec2-user/test_form/.venv/lib64/python3.12/site-packages/gunicorn/workers/base.py", line 135, in init_process
    self.load_wsgi()
  File "/home/ec2-user/test_form/.venv/lib64/python3.12/site-packages/gunicorn/workers/base.py", line 147, in load_wsgi
    self.wsgi = self.app.wsgi()
                ^^^^^^^^^^^^^^^
  File "/home/ec2-user/test_form/.venv/lib64/python3.12/site-packages/gunicorn/app/base.py", line 66, in wsgi
    self.callable = self.load()
                    ^^^^^^^^^^^
  File "/home/ec2-user/test_form/.venv/lib64/python3.12/site-packages/gunicorn/app/wsgiapp.py", line 57, in load
    return self.load_wsgiapp()
           ^^^^^^^^^^^^^^^^^^^
  File "/home/ec2-user/test_form/.venv/lib64/python3.12/site-packages/gunicorn/app/wsgiapp.py", line 47, in load_wsgiapp
    return util.import_app(self.app_uri)
           ^^^^^^^^^^^^^^^^^^^^^^^^^^^^^
  File "/home/ec2-user/test_form/.venv/lib64/python3.12/site-packages/gunicorn/util.py", line 370, in import_app
    mod = importlib.import_module(module)
          ^^^^^^^^^^^^^^^^^^^^^^^^^^^^^^^
  File "/usr/lib64/python3.12/importlib/__init__.py", line 90, in import_module
    return _bootstrap._gcd_import(name[level:], package, level)
           ^^^^^^^^^^^^^^^^^^^^^^^^^^^^^^^^^^^^^^^^^^^^^^^^^^^^
  File "<frozen importlib._bootstrap>", line 1387, in _gcd_import
  File "<frozen importlib._bootstrap>", line 1360, in _find_and_load
  File "<frozen importlib._bootstrap>", line 1331, in _find_and_load_unlocked
  File "<frozen importlib._bootstrap>", line 935, in _load_unlocked
  File "<frozen importlib._bootstrap_external>", line 995, in exec_module
  File "<frozen importlib._bootstrap>", line 488, in _call_with_frames_removed
  File "/home/ec2-user/test_form/wsgi.py", line 1, in <module>
    from app import create_app
  File "/home/ec2-user/test_form/app/__init__.py", line 4, in <module>
    from app.routes import routes
  File "/home/ec2-user/test_form/app/routes.py", line 2, in <module>
    from app.views import users
ModuleNotFoundError: No module named 'app.views'
[2025-01-10 05:57:07 +0000] [43626] [INFO] Worker exiting (pid: 43626)
[2025-01-10 05:57:07 +0000] [43625] [ERROR] Exception in worker process
Traceback (most recent call last):
  File "/home/ec2-user/test_form/.venv/lib64/python3.12/site-packages/gunicorn/arbiter.py", line 608, in spawn_worker
    worker.init_process()
  File "/home/ec2-user/test_form/.venv/lib64/python3.12/site-packages/gunicorn/workers/base.py", line 135, in init_process
    self.load_wsgi()
  File "/home/ec2-user/test_form/.venv/lib64/python3.12/site-packages/gunicorn/workers/base.py", line 147, in load_wsgi
    self.wsgi = self.app.wsgi()
                ^^^^^^^^^^^^^^^
  File "/home/ec2-user/test_form/.venv/lib64/python3.12/site-packages/gunicorn/app/base.py", line 66, in wsgi
    self.callable = self.load()
                    ^^^^^^^^^^^
  File "/home/ec2-user/test_form/.venv/lib64/python3.12/site-packages/gunicorn/app/wsgiapp.py", line 57, in load
    return self.load_wsgiapp()
           ^^^^^^^^^^^^^^^^^^^
  File "/home/ec2-user/test_form/.venv/lib64/python3.12/site-packages/gunicorn/app/wsgiapp.py", line 47, in load_wsgiapp
    return util.import_app(self.app_uri)
           ^^^^^^^^^^^^^^^^^^^^^^^^^^^^^
  File "/home/ec2-user/test_form/.venv/lib64/python3.12/site-packages/gunicorn/util.py", line 370, in import_app
    mod = importlib.import_module(module)
          ^^^^^^^^^^^^^^^^^^^^^^^^^^^^^^^
  File "/usr/lib64/python3.12/importlib/__init__.py", line 90, in import_module
    return _bootstrap._gcd_import(name[level:], package, level)
           ^^^^^^^^^^^^^^^^^^^^^^^^^^^^^^^^^^^^^^^^^^^^^^^^^^^^
  File "<frozen importlib._bootstrap>", line 1387, in _gcd_import
  File "<frozen importlib._bootstrap>", line 1360, in _find_and_load
  File "<frozen importlib._bootstrap>", line 1331, in _find_and_load_unlocked
  File "<frozen importlib._bootstrap>", line 935, in _load_unlocked
  File "<frozen importlib._bootstrap_external>", line 995, in exec_module
  File "<frozen importlib._bootstrap>", line 488, in _call_with_frames_removed
  File "/home/ec2-user/test_form/wsgi.py", line 1, in <module>
    from app import create_app
  File "/home/ec2-user/test_form/app/__init__.py", line 4, in <module>
    from app.routes import routes
  File "/home/ec2-user/test_form/app/routes.py", line 2, in <module>
    from app.views import users
ModuleNotFoundError: No module named 'app.views'
[2025-01-10 05:57:07 +0000] [43625] [INFO] Worker exiting (pid: 43625)
[2025-01-10 05:57:07 +0000] [43627] [ERROR] Exception in worker process
Traceback (most recent call last):
  File "/home/ec2-user/test_form/.venv/lib64/python3.12/site-packages/gunicorn/arbiter.py", line 608, in spawn_worker
    worker.init_process()
  File "/home/ec2-user/test_form/.venv/lib64/python3.12/site-packages/gunicorn/workers/base.py", line 135, in init_process
    self.load_wsgi()
  File "/home/ec2-user/test_form/.venv/lib64/python3.12/site-packages/gunicorn/workers/base.py", line 147, in load_wsgi
    self.wsgi = self.app.wsgi()
                ^^^^^^^^^^^^^^^
  File "/home/ec2-user/test_form/.venv/lib64/python3.12/site-packages/gunicorn/app/base.py", line 66, in wsgi
    self.callable = self.load()
                    ^^^^^^^^^^^
  File "/home/ec2-user/test_form/.venv/lib64/python3.12/site-packages/gunicorn/app/wsgiapp.py", line 57, in load
    return self.load_wsgiapp()
           ^^^^^^^^^^^^^^^^^^^
  File "/home/ec2-user/test_form/.venv/lib64/python3.12/site-packages/gunicorn/app/wsgiapp.py", line 47, in load_wsgiapp
    return util.import_app(self.app_uri)
           ^^^^^^^^^^^^^^^^^^^^^^^^^^^^^
  File "/home/ec2-user/test_form/.venv/lib64/python3.12/site-packages/gunicorn/util.py", line 370, in import_app
    mod = importlib.import_module(module)
          ^^^^^^^^^^^^^^^^^^^^^^^^^^^^^^^
  File "/usr/lib64/python3.12/importlib/__init__.py", line 90, in import_module
    return _bootstrap._gcd_import(name[level:], package, level)
           ^^^^^^^^^^^^^^^^^^^^^^^^^^^^^^^^^^^^^^^^^^^^^^^^^^^^
  File "<frozen importlib._bootstrap>", line 1387, in _gcd_import
  File "<frozen importlib._bootstrap>", line 1360, in _find_and_load
  File "<frozen importlib._bootstrap>", line 1331, in _find_and_load_unlocked
  File "<frozen importlib._bootstrap>", line 935, in _load_unlocked
  File "<frozen importlib._bootstrap_external>", line 995, in exec_module
  File "<frozen importlib._bootstrap>", line 488, in _call_with_frames_removed
  File "/home/ec2-user/test_form/wsgi.py", line 1, in <module>
    from app import create_app
  File "/home/ec2-user/test_form/app/__init__.py", line 4, in <module>
    from app.routes import routes
  File "/home/ec2-user/test_form/app/routes.py", line 2, in <module>
    from app.views import users
ModuleNotFoundError: No module named 'app.views'
[2025-01-10 05:57:07 +0000] [43627] [INFO] Worker exiting (pid: 43627)
[2025-01-10 05:57:07 +0000] [43620] [ERROR] Worker (pid:43622) exited with code 3
[2025-01-10 05:57:07 +0000] [43620] [ERROR] Worker (pid:43627) was sent SIGTERM!
[2025-01-10 05:57:07 +0000] [43620] [ERROR] Worker (pid:43625) was sent SIGTERM!
[2025-01-10 05:57:07 +0000] [43620] [ERROR] Worker (pid:43626) was sent SIGTERM!
[2025-01-10 05:57:07 +0000] [43620] [ERROR] Shutting down: Master
[2025-01-10 05:57:07 +0000] [43620] [ERROR] Reason: Worker failed to boot.
[2025-01-10 05:58:09 +0000] [44345] [INFO] Starting gunicorn 23.0.0
[2025-01-10 05:58:09 +0000] [44345] [INFO] Listening at: http://127.0.0.1:8000 (44345)
[2025-01-10 05:58:09 +0000] [44345] [INFO] Using worker: sync
[2025-01-10 05:58:09 +0000] [44347] [INFO] Booting worker with pid: 44347
[2025-01-10 05:58:09 +0000] [44348] [INFO] Booting worker with pid: 44348
[2025-01-10 05:58:09 +0000] [44351] [INFO] Booting worker with pid: 44351
[2025-01-10 05:58:09 +0000] [44352] [INFO] Booting worker with pid: 44352
[2025-01-10 06:53:46 +0000] [44345] [INFO] Handling signal: term
[2025-01-10 06:53:46 +0000] [44347] [INFO] Worker exiting (pid: 44347)
[2025-01-10 06:53:46 +0000] [44348] [INFO] Worker exiting (pid: 44348)
[2025-01-10 06:53:46 +0000] [44351] [INFO] Worker exiting (pid: 44351)
[2025-01-10 06:53:46 +0000] [44352] [INFO] Worker exiting (pid: 44352)
[2025-01-10 06:53:46 +0000] [44345] [ERROR] Worker (pid:44347) was sent SIGTERM!
[2025-01-10 06:53:46 +0000] [44345] [ERROR] Worker (pid:44348) was sent SIGTERM!
[2025-01-10 06:53:47 +0000] [44345] [ERROR] Worker (pid:44351) was sent SIGTERM!
[2025-01-10 06:53:47 +0000] [44345] [INFO] Shutting down: Master
[2025-01-10 06:54:14 +0000] [53274] [INFO] Starting gunicorn 23.0.0
[2025-01-10 06:54:14 +0000] [53274] [INFO] Listening at: http://127.0.0.1:8000 (53274)
[2025-01-10 06:54:14 +0000] [53274] [INFO] Using worker: sync
[2025-01-10 06:54:14 +0000] [53276] [INFO] Booting worker with pid: 53276
[2025-01-10 06:54:14 +0000] [53277] [INFO] Booting worker with pid: 53277
[2025-01-10 06:54:14 +0000] [53279] [INFO] Booting worker with pid: 53279
[2025-01-10 06:54:15 +0000] [53281] [INFO] Booting worker with pid: 53281
[2025-01-10 07:04:10 +0000] [53274] [INFO] Handling signal: term
[2025-01-10 07:04:10 +0000] [53276] [INFO] Worker exiting (pid: 53276)
[2025-01-10 07:04:10 +0000] [53277] [INFO] Worker exiting (pid: 53277)
[2025-01-10 07:04:10 +0000] [53279] [INFO] Worker exiting (pid: 53279)
[2025-01-10 07:04:10 +0000] [53281] [INFO] Worker exiting (pid: 53281)
[2025-01-10 07:04:10 +0000] [53274] [ERROR] Worker (pid:53276) was sent SIGTERM!
[2025-01-10 07:04:11 +0000] [53274] [ERROR] Worker (pid:53277) was sent SIGTERM!
[2025-01-10 07:04:11 +0000] [53274] [ERROR] Worker (pid:53279) was sent SIGTERM!
[2025-01-10 07:04:11 +0000] [53274] [INFO] Shutting down: Master
[2025-01-10 07:04:15 +0000] [55041] [INFO] Starting gunicorn 23.0.0
[2025-01-10 07:04:15 +0000] [55041] [INFO] Listening at: http://127.0.0.1:8000 (55041)
[2025-01-10 07:04:15 +0000] [55041] [INFO] Using worker: sync
[2025-01-10 07:04:15 +0000] [55043] [INFO] Booting worker with pid: 55043
[2025-01-10 07:04:15 +0000] [55046] [INFO] Booting worker with pid: 55046
[2025-01-10 07:04:15 +0000] [55047] [INFO] Booting worker with pid: 55047
[2025-01-10 07:04:15 +0000] [55048] [INFO] Booting worker with pid: 55048
[2025-01-10 07:04:17 +0000] [55043] [ERROR] Exception in worker process
Traceback (most recent call last):
  File "/home/ec2-user/test_form/.venv/lib64/python3.12/site-packages/gunicorn/arbiter.py", line 608, in spawn_worker
    worker.init_process()
  File "/home/ec2-user/test_form/.venv/lib64/python3.12/site-packages/gunicorn/workers/base.py", line 135, in init_process
    self.load_wsgi()
  File "/home/ec2-user/test_form/.venv/lib64/python3.12/site-packages/gunicorn/workers/base.py", line 147, in load_wsgi
    self.wsgi = self.app.wsgi()
                ^^^^^^^^^^^^^^^
  File "/home/ec2-user/test_form/.venv/lib64/python3.12/site-packages/gunicorn/app/base.py", line 66, in wsgi
    self.callable = self.load()
                    ^^^^^^^^^^^
  File "/home/ec2-user/test_form/.venv/lib64/python3.12/site-packages/gunicorn/app/wsgiapp.py", line 57, in load
    return self.load_wsgiapp()
           ^^^^^^^^^^^^^^^^^^^
  File "/home/ec2-user/test_form/.venv/lib64/python3.12/site-packages/gunicorn/app/wsgiapp.py", line 47, in load_wsgiapp
    return util.import_app(self.app_uri)
           ^^^^^^^^^^^^^^^^^^^^^^^^^^^^^
  File "/home/ec2-user/test_form/.venv/lib64/python3.12/site-packages/gunicorn/util.py", line 370, in import_app
    mod = importlib.import_module(module)
          ^^^^^^^^^^^^^^^^^^^^^^^^^^^^^^^
  File "/usr/lib64/python3.12/importlib/__init__.py", line 90, in import_module
    return _bootstrap._gcd_import(name[level:], package, level)
           ^^^^^^^^^^^^^^^^^^^^^^^^^^^^^^^^^^^^^^^^^^^^^^^^^^^^
  File "<frozen importlib._bootstrap>", line 1387, in _gcd_import
  File "<frozen importlib._bootstrap>", line 1360, in _find_and_load
  File "<frozen importlib._bootstrap>", line 1331, in _find_and_load_unlocked
  File "<frozen importlib._bootstrap>", line 935, in _load_unlocked
  File "<frozen importlib._bootstrap_external>", line 995, in exec_module
  File "<frozen importlib._bootstrap>", line 488, in _call_with_frames_removed
  File "/home/ec2-user/test_form/wsgi.py", line 1, in <module>
    from app import create_app
  File "/home/ec2-user/test_form/app/__init__.py", line 4, in <module>
    from app.routes import routes
  File "/home/ec2-user/test_form/app/routes.py", line 2, in <module>
    from app.services import users, images, quetions
ImportError: cannot import name 'quetions' from 'app.services' (unknown location)
[2025-01-10 07:04:17 +0000] [55043] [INFO] Worker exiting (pid: 55043)
[2025-01-10 07:04:17 +0000] [55047] [ERROR] Exception in worker process
Traceback (most recent call last):
  File "/home/ec2-user/test_form/.venv/lib64/python3.12/site-packages/gunicorn/arbiter.py", line 608, in spawn_worker
    worker.init_process()
  File "/home/ec2-user/test_form/.venv/lib64/python3.12/site-packages/gunicorn/workers/base.py", line 135, in init_process
    self.load_wsgi()
  File "/home/ec2-user/test_form/.venv/lib64/python3.12/site-packages/gunicorn/workers/base.py", line 147, in load_wsgi
    self.wsgi = self.app.wsgi()
                ^^^^^^^^^^^^^^^
  File "/home/ec2-user/test_form/.venv/lib64/python3.12/site-packages/gunicorn/app/base.py", line 66, in wsgi
    self.callable = self.load()
                    ^^^^^^^^^^^
  File "/home/ec2-user/test_form/.venv/lib64/python3.12/site-packages/gunicorn/app/wsgiapp.py", line 57, in load
    return self.load_wsgiapp()
           ^^^^^^^^^^^^^^^^^^^
  File "/home/ec2-user/test_form/.venv/lib64/python3.12/site-packages/gunicorn/app/wsgiapp.py", line 47, in load_wsgiapp
    return util.import_app(self.app_uri)
           ^^^^^^^^^^^^^^^^^^^^^^^^^^^^^
  File "/home/ec2-user/test_form/.venv/lib64/python3.12/site-packages/gunicorn/util.py", line 370, in import_app
    mod = importlib.import_module(module)
          ^^^^^^^^^^^^^^^^^^^^^^^^^^^^^^^
  File "/usr/lib64/python3.12/importlib/__init__.py", line 90, in import_module
    return _bootstrap._gcd_import(name[level:], package, level)
           ^^^^^^^^^^^^^^^^^^^^^^^^^^^^^^^^^^^^^^^^^^^^^^^^^^^^
  File "<frozen importlib._bootstrap>", line 1387, in _gcd_import
  File "<frozen importlib._bootstrap>", line 1360, in _find_and_load
  File "<frozen importlib._bootstrap>", line 1331, in _find_and_load_unlocked
  File "<frozen importlib._bootstrap>", line 935, in _load_unlocked
  File "<frozen importlib._bootstrap_external>", line 995, in exec_module
  File "<frozen importlib._bootstrap>", line 488, in _call_with_frames_removed
  File "/home/ec2-user/test_form/wsgi.py", line 1, in <module>
    from app import create_app
  File "/home/ec2-user/test_form/app/__init__.py", line 4, in <module>
    from app.routes import routes
  File "/home/ec2-user/test_form/app/routes.py", line 2, in <module>
    from app.services import users, images, quetions
ImportError: cannot import name 'quetions' from 'app.services' (unknown location)
[2025-01-10 07:04:17 +0000] [55047] [INFO] Worker exiting (pid: 55047)
[2025-01-10 07:04:17 +0000] [55046] [ERROR] Exception in worker process
Traceback (most recent call last):
  File "/home/ec2-user/test_form/.venv/lib64/python3.12/site-packages/gunicorn/arbiter.py", line 608, in spawn_worker
    worker.init_process()
  File "/home/ec2-user/test_form/.venv/lib64/python3.12/site-packages/gunicorn/workers/base.py", line 135, in init_process
    self.load_wsgi()
  File "/home/ec2-user/test_form/.venv/lib64/python3.12/site-packages/gunicorn/workers/base.py", line 147, in load_wsgi
    self.wsgi = self.app.wsgi()
                ^^^^^^^^^^^^^^^
  File "/home/ec2-user/test_form/.venv/lib64/python3.12/site-packages/gunicorn/app/base.py", line 66, in wsgi
    self.callable = self.load()
                    ^^^^^^^^^^^
  File "/home/ec2-user/test_form/.venv/lib64/python3.12/site-packages/gunicorn/app/wsgiapp.py", line 57, in load
    return self.load_wsgiapp()
           ^^^^^^^^^^^^^^^^^^^
  File "/home/ec2-user/test_form/.venv/lib64/python3.12/site-packages/gunicorn/app/wsgiapp.py", line 47, in load_wsgiapp
    return util.import_app(self.app_uri)
           ^^^^^^^^^^^^^^^^^^^^^^^^^^^^^
  File "/home/ec2-user/test_form/.venv/lib64/python3.12/site-packages/gunicorn/util.py", line 370, in import_app
    mod = importlib.import_module(module)
          ^^^^^^^^^^^^^^^^^^^^^^^^^^^^^^^
  File "/usr/lib64/python3.12/importlib/__init__.py", line 90, in import_module
    return _bootstrap._gcd_import(name[level:], package, level)
           ^^^^^^^^^^^^^^^^^^^^^^^^^^^^^^^^^^^^^^^^^^^^^^^^^^^^
  File "<frozen importlib._bootstrap>", line 1387, in _gcd_import
  File "<frozen importlib._bootstrap>", line 1360, in _find_and_load
  File "<frozen importlib._bootstrap>", line 1331, in _find_and_load_unlocked
  File "<frozen importlib._bootstrap>", line 935, in _load_unlocked
  File "<frozen importlib._bootstrap_external>", line 995, in exec_module
  File "<frozen importlib._bootstrap>", line 488, in _call_with_frames_removed
  File "/home/ec2-user/test_form/wsgi.py", line 1, in <module>
    from app import create_app
  File "/home/ec2-user/test_form/app/__init__.py", line 4, in <module>
    from app.routes import routes
  File "/home/ec2-user/test_form/app/routes.py", line 2, in <module>
    from app.services import users, images, quetions
ImportError: cannot import name 'quetions' from 'app.services' (unknown location)
[2025-01-10 07:04:17 +0000] [55046] [INFO] Worker exiting (pid: 55046)
[2025-01-10 07:04:17 +0000] [55048] [ERROR] Exception in worker process
Traceback (most recent call last):
  File "/home/ec2-user/test_form/.venv/lib64/python3.12/site-packages/gunicorn/arbiter.py", line 608, in spawn_worker
    worker.init_process()
  File "/home/ec2-user/test_form/.venv/lib64/python3.12/site-packages/gunicorn/workers/base.py", line 135, in init_process
    self.load_wsgi()
  File "/home/ec2-user/test_form/.venv/lib64/python3.12/site-packages/gunicorn/workers/base.py", line 147, in load_wsgi
    self.wsgi = self.app.wsgi()
                ^^^^^^^^^^^^^^^
  File "/home/ec2-user/test_form/.venv/lib64/python3.12/site-packages/gunicorn/app/base.py", line 66, in wsgi
    self.callable = self.load()
                    ^^^^^^^^^^^
  File "/home/ec2-user/test_form/.venv/lib64/python3.12/site-packages/gunicorn/app/wsgiapp.py", line 57, in load
    return self.load_wsgiapp()
           ^^^^^^^^^^^^^^^^^^^
  File "/home/ec2-user/test_form/.venv/lib64/python3.12/site-packages/gunicorn/app/wsgiapp.py", line 47, in load_wsgiapp
    return util.import_app(self.app_uri)
           ^^^^^^^^^^^^^^^^^^^^^^^^^^^^^
  File "/home/ec2-user/test_form/.venv/lib64/python3.12/site-packages/gunicorn/util.py", line 370, in import_app
    mod = importlib.import_module(module)
          ^^^^^^^^^^^^^^^^^^^^^^^^^^^^^^^
  File "/usr/lib64/python3.12/importlib/__init__.py", line 90, in import_module
    return _bootstrap._gcd_import(name[level:], package, level)
           ^^^^^^^^^^^^^^^^^^^^^^^^^^^^^^^^^^^^^^^^^^^^^^^^^^^^
  File "<frozen importlib._bootstrap>", line 1387, in _gcd_import
  File "<frozen importlib._bootstrap>", line 1360, in _find_and_load
  File "<frozen importlib._bootstrap>", line 1331, in _find_and_load_unlocked
  File "<frozen importlib._bootstrap>", line 935, in _load_unlocked
  File "<frozen importlib._bootstrap_external>", line 995, in exec_module
  File "<frozen importlib._bootstrap>", line 488, in _call_with_frames_removed
  File "/home/ec2-user/test_form/wsgi.py", line 1, in <module>
    from app import create_app
  File "/home/ec2-user/test_form/app/__init__.py", line 4, in <module>
    from app.routes import routes
  File "/home/ec2-user/test_form/app/routes.py", line 2, in <module>
    from app.services import users, images, quetions
ImportError: cannot import name 'quetions' from 'app.services' (unknown location)
[2025-01-10 07:04:17 +0000] [55048] [INFO] Worker exiting (pid: 55048)
[2025-01-10 07:04:17 +0000] [55041] [ERROR] Worker (pid:55043) exited with code 3
[2025-01-10 07:04:17 +0000] [55041] [ERROR] Worker (pid:55047) was sent SIGTERM!
[2025-01-10 07:04:17 +0000] [55041] [ERROR] Worker (pid:55048) was sent SIGTERM!
[2025-01-10 07:04:17 +0000] [55041] [ERROR] Worker (pid:55046) was sent SIGTERM!
[2025-01-10 07:04:17 +0000] [55041] [ERROR] Shutting down: Master
[2025-01-10 07:04:17 +0000] [55041] [ERROR] Reason: Worker failed to boot.
[2025-01-10 07:07:27 +0000] [55517] [INFO] Starting gunicorn 23.0.0
[2025-01-10 07:07:27 +0000] [55517] [INFO] Listening at: http://127.0.0.1:8000 (55517)
[2025-01-10 07:07:27 +0000] [55517] [INFO] Using worker: sync
[2025-01-10 07:07:27 +0000] [55519] [INFO] Booting worker with pid: 55519
[2025-01-10 07:07:27 +0000] [55522] [INFO] Booting worker with pid: 55522
[2025-01-10 07:07:27 +0000] [55523] [INFO] Booting worker with pid: 55523
[2025-01-10 07:07:27 +0000] [55524] [INFO] Booting worker with pid: 55524
[2025-01-10 07:07:29 +0000] [55519] [ERROR] Exception in worker process
Traceback (most recent call last):
  File "/home/ec2-user/test_form/.venv/lib64/python3.12/site-packages/gunicorn/arbiter.py", line 608, in spawn_worker
    worker.init_process()
  File "/home/ec2-user/test_form/.venv/lib64/python3.12/site-packages/gunicorn/workers/base.py", line 135, in init_process
    self.load_wsgi()
  File "/home/ec2-user/test_form/.venv/lib64/python3.12/site-packages/gunicorn/workers/base.py", line 147, in load_wsgi
    self.wsgi = self.app.wsgi()
                ^^^^^^^^^^^^^^^
  File "/home/ec2-user/test_form/.venv/lib64/python3.12/site-packages/gunicorn/app/base.py", line 66, in wsgi
    self.callable = self.load()
                    ^^^^^^^^^^^
  File "/home/ec2-user/test_form/.venv/lib64/python3.12/site-packages/gunicorn/app/wsgiapp.py", line 57, in load
    return self.load_wsgiapp()
           ^^^^^^^^^^^^^^^^^^^
  File "/home/ec2-user/test_form/.venv/lib64/python3.12/site-packages/gunicorn/app/wsgiapp.py", line 47, in load_wsgiapp
    return util.import_app(self.app_uri)
           ^^^^^^^^^^^^^^^^^^^^^^^^^^^^^
  File "/home/ec2-user/test_form/.venv/lib64/python3.12/site-packages/gunicorn/util.py", line 370, in import_app
    mod = importlib.import_module(module)
          ^^^^^^^^^^^^^^^^^^^^^^^^^^^^^^^
  File "/usr/lib64/python3.12/importlib/__init__.py", line 90, in import_module
    return _bootstrap._gcd_import(name[level:], package, level)
           ^^^^^^^^^^^^^^^^^^^^^^^^^^^^^^^^^^^^^^^^^^^^^^^^^^^^
  File "<frozen importlib._bootstrap>", line 1387, in _gcd_import
  File "<frozen importlib._bootstrap>", line 1360, in _find_and_load
  File "<frozen importlib._bootstrap>", line 1331, in _find_and_load_unlocked
  File "<frozen importlib._bootstrap>", line 935, in _load_unlocked
  File "<frozen importlib._bootstrap_external>", line 995, in exec_module
  File "<frozen importlib._bootstrap>", line 488, in _call_with_frames_removed
  File "/home/ec2-user/test_form/wsgi.py", line 1, in <module>
    from app import create_app
  File "/home/ec2-user/test_form/app/__init__.py", line 4, in <module>
    from app.routes import routes
  File "/home/ec2-user/test_form/app/routes.py", line 2, in <module>
    from app.services import users, images, quetions
ImportError: cannot import name 'quetions' from 'app.services' (unknown location)
[2025-01-10 07:07:29 +0000] [55519] [INFO] Worker exiting (pid: 55519)
[2025-01-10 07:07:29 +0000] [55523] [ERROR] Exception in worker process
Traceback (most recent call last):
  File "/home/ec2-user/test_form/.venv/lib64/python3.12/site-packages/gunicorn/arbiter.py", line 608, in spawn_worker
    worker.init_process()
  File "/home/ec2-user/test_form/.venv/lib64/python3.12/site-packages/gunicorn/workers/base.py", line 135, in init_process
    self.load_wsgi()
  File "/home/ec2-user/test_form/.venv/lib64/python3.12/site-packages/gunicorn/workers/base.py", line 147, in load_wsgi
    self.wsgi = self.app.wsgi()
                ^^^^^^^^^^^^^^^
  File "/home/ec2-user/test_form/.venv/lib64/python3.12/site-packages/gunicorn/app/base.py", line 66, in wsgi
    self.callable = self.load()
                    ^^^^^^^^^^^
  File "/home/ec2-user/test_form/.venv/lib64/python3.12/site-packages/gunicorn/app/wsgiapp.py", line 57, in load
    return self.load_wsgiapp()
           ^^^^^^^^^^^^^^^^^^^
  File "/home/ec2-user/test_form/.venv/lib64/python3.12/site-packages/gunicorn/app/wsgiapp.py", line 47, in load_wsgiapp
    return util.import_app(self.app_uri)
           ^^^^^^^^^^^^^^^^^^^^^^^^^^^^^
  File "/home/ec2-user/test_form/.venv/lib64/python3.12/site-packages/gunicorn/util.py", line 370, in import_app
    mod = importlib.import_module(module)
          ^^^^^^^^^^^^^^^^^^^^^^^^^^^^^^^
  File "/usr/lib64/python3.12/importlib/__init__.py", line 90, in import_module
    return _bootstrap._gcd_import(name[level:], package, level)
           ^^^^^^^^^^^^^^^^^^^^^^^^^^^^^^^^^^^^^^^^^^^^^^^^^^^^
  File "<frozen importlib._bootstrap>", line 1387, in _gcd_import
  File "<frozen importlib._bootstrap>", line 1360, in _find_and_load
  File "<frozen importlib._bootstrap>", line 1331, in _find_and_load_unlocked
  File "<frozen importlib._bootstrap>", line 935, in _load_unlocked
  File "<frozen importlib._bootstrap_external>", line 995, in exec_module
  File "<frozen importlib._bootstrap>", line 488, in _call_with_frames_removed
  File "/home/ec2-user/test_form/wsgi.py", line 1, in <module>
    from app import create_app
  File "/home/ec2-user/test_form/app/__init__.py", line 4, in <module>
    from app.routes import routes
  File "/home/ec2-user/test_form/app/routes.py", line 2, in <module>
    from app.services import users, images, quetions
ImportError: cannot import name 'quetions' from 'app.services' (unknown location)
[2025-01-10 07:07:29 +0000] [55523] [INFO] Worker exiting (pid: 55523)
[2025-01-10 07:07:29 +0000] [55522] [ERROR] Exception in worker process
Traceback (most recent call last):
  File "/home/ec2-user/test_form/.venv/lib64/python3.12/site-packages/gunicorn/arbiter.py", line 608, in spawn_worker
    worker.init_process()
  File "/home/ec2-user/test_form/.venv/lib64/python3.12/site-packages/gunicorn/workers/base.py", line 135, in init_process
    self.load_wsgi()
  File "/home/ec2-user/test_form/.venv/lib64/python3.12/site-packages/gunicorn/workers/base.py", line 147, in load_wsgi
    self.wsgi = self.app.wsgi()
                ^^^^^^^^^^^^^^^
  File "/home/ec2-user/test_form/.venv/lib64/python3.12/site-packages/gunicorn/app/base.py", line 66, in wsgi
    self.callable = self.load()
                    ^^^^^^^^^^^
  File "/home/ec2-user/test_form/.venv/lib64/python3.12/site-packages/gunicorn/app/wsgiapp.py", line 57, in load
    return self.load_wsgiapp()
           ^^^^^^^^^^^^^^^^^^^
  File "/home/ec2-user/test_form/.venv/lib64/python3.12/site-packages/gunicorn/app/wsgiapp.py", line 47, in load_wsgiapp
    return util.import_app(self.app_uri)
           ^^^^^^^^^^^^^^^^^^^^^^^^^^^^^
  File "/home/ec2-user/test_form/.venv/lib64/python3.12/site-packages/gunicorn/util.py", line 370, in import_app
    mod = importlib.import_module(module)
          ^^^^^^^^^^^^^^^^^^^^^^^^^^^^^^^
  File "/usr/lib64/python3.12/importlib/__init__.py", line 90, in import_module
    return _bootstrap._gcd_import(name[level:], package, level)
           ^^^^^^^^^^^^^^^^^^^^^^^^^^^^^^^^^^^^^^^^^^^^^^^^^^^^
  File "<frozen importlib._bootstrap>", line 1387, in _gcd_import
  File "<frozen importlib._bootstrap>", line 1360, in _find_and_load
  File "<frozen importlib._bootstrap>", line 1331, in _find_and_load_unlocked
  File "<frozen importlib._bootstrap>", line 935, in _load_unlocked
  File "<frozen importlib._bootstrap_external>", line 995, in exec_module
  File "<frozen importlib._bootstrap>", line 488, in _call_with_frames_removed
  File "/home/ec2-user/test_form/wsgi.py", line 1, in <module>
    from app import create_app
  File "/home/ec2-user/test_form/app/__init__.py", line 4, in <module>
    from app.routes import routes
  File "/home/ec2-user/test_form/app/routes.py", line 2, in <module>
    from app.services import users, images, quetions
ImportError: cannot import name 'quetions' from 'app.services' (unknown location)
[2025-01-10 07:07:29 +0000] [55522] [INFO] Worker exiting (pid: 55522)
[2025-01-10 07:07:29 +0000] [55524] [ERROR] Exception in worker process
Traceback (most recent call last):
  File "/home/ec2-user/test_form/.venv/lib64/python3.12/site-packages/gunicorn/arbiter.py", line 608, in spawn_worker
    worker.init_process()
  File "/home/ec2-user/test_form/.venv/lib64/python3.12/site-packages/gunicorn/workers/base.py", line 135, in init_process
    self.load_wsgi()
  File "/home/ec2-user/test_form/.venv/lib64/python3.12/site-packages/gunicorn/workers/base.py", line 147, in load_wsgi
    self.wsgi = self.app.wsgi()
                ^^^^^^^^^^^^^^^
  File "/home/ec2-user/test_form/.venv/lib64/python3.12/site-packages/gunicorn/app/base.py", line 66, in wsgi
    self.callable = self.load()
                    ^^^^^^^^^^^
  File "/home/ec2-user/test_form/.venv/lib64/python3.12/site-packages/gunicorn/app/wsgiapp.py", line 57, in load
    return self.load_wsgiapp()
           ^^^^^^^^^^^^^^^^^^^
  File "/home/ec2-user/test_form/.venv/lib64/python3.12/site-packages/gunicorn/app/wsgiapp.py", line 47, in load_wsgiapp
    return util.import_app(self.app_uri)
           ^^^^^^^^^^^^^^^^^^^^^^^^^^^^^
  File "/home/ec2-user/test_form/.venv/lib64/python3.12/site-packages/gunicorn/util.py", line 370, in import_app
    mod = importlib.import_module(module)
          ^^^^^^^^^^^^^^^^^^^^^^^^^^^^^^^
  File "/usr/lib64/python3.12/importlib/__init__.py", line 90, in import_module
    return _bootstrap._gcd_import(name[level:], package, level)
           ^^^^^^^^^^^^^^^^^^^^^^^^^^^^^^^^^^^^^^^^^^^^^^^^^^^^
  File "<frozen importlib._bootstrap>", line 1387, in _gcd_import
  File "<frozen importlib._bootstrap>", line 1360, in _find_and_load
  File "<frozen importlib._bootstrap>", line 1331, in _find_and_load_unlocked
  File "<frozen importlib._bootstrap>", line 935, in _load_unlocked
  File "<frozen importlib._bootstrap_external>", line 995, in exec_module
  File "<frozen importlib._bootstrap>", line 488, in _call_with_frames_removed
  File "/home/ec2-user/test_form/wsgi.py", line 1, in <module>
    from app import create_app
  File "/home/ec2-user/test_form/app/__init__.py", line 4, in <module>
    from app.routes import routes
  File "/home/ec2-user/test_form/app/routes.py", line 2, in <module>
    from app.services import users, images, quetions
ImportError: cannot import name 'quetions' from 'app.services' (unknown location)
[2025-01-10 07:07:29 +0000] [55524] [INFO] Worker exiting (pid: 55524)
[2025-01-10 07:07:30 +0000] [55517] [ERROR] Worker (pid:55519) exited with code 3
[2025-01-10 07:07:30 +0000] [55517] [ERROR] Worker (pid:55524) was sent SIGTERM!
[2025-01-10 07:07:30 +0000] [55517] [ERROR] Worker (pid:55523) was sent SIGTERM!
[2025-01-10 07:07:30 +0000] [55517] [ERROR] Worker (pid:55522) was sent SIGTERM!
[2025-01-10 07:07:30 +0000] [55517] [ERROR] Shutting down: Master
[2025-01-10 07:07:30 +0000] [55517] [ERROR] Reason: Worker failed to boot.
[2025-01-13 02:15:03 +0000] [191047] [INFO] Starting gunicorn 23.0.0
[2025-01-13 02:15:03 +0000] [191047] [INFO] Listening at: http://127.0.0.1:8000 (191047)
[2025-01-13 02:15:03 +0000] [191047] [INFO] Using worker: sync
[2025-01-13 02:15:03 +0000] [191048] [INFO] Booting worker with pid: 191048
[2025-01-13 02:15:03 +0000] [191049] [INFO] Booting worker with pid: 191049
[2025-01-13 02:15:03 +0000] [191052] [INFO] Booting worker with pid: 191052
[2025-01-13 02:15:03 +0000] [191053] [INFO] Booting worker with pid: 191053
[2025-01-13 02:16:56,377] ERROR in app: Exception on /choice [POST]
Traceback (most recent call last):
  File "/home/ec2-user/test_form/.venv/lib64/python3.12/site-packages/sqlalchemy/engine/base.py", line 1964, in _exec_single_context
    self.dialect.do_execute(
  File "/home/ec2-user/test_form/.venv/lib64/python3.12/site-packages/sqlalchemy/engine/default.py", line 942, in do_execute
    cursor.execute(statement, parameters)
  File "/home/ec2-user/test_form/.venv/lib64/python3.12/site-packages/pymysql/cursors.py", line 153, in execute
    result = self._query(query)
             ^^^^^^^^^^^^^^^^^^
  File "/home/ec2-user/test_form/.venv/lib64/python3.12/site-packages/pymysql/cursors.py", line 322, in _query
    conn.query(q)
  File "/home/ec2-user/test_form/.venv/lib64/python3.12/site-packages/pymysql/connections.py", line 563, in query
    self._affected_rows = self._read_query_result(unbuffered=unbuffered)
                          ^^^^^^^^^^^^^^^^^^^^^^^^^^^^^^^^^^^^^^^^^^^^^^
  File "/home/ec2-user/test_form/.venv/lib64/python3.12/site-packages/pymysql/connections.py", line 825, in _read_query_result
    result.read()
  File "/home/ec2-user/test_form/.venv/lib64/python3.12/site-packages/pymysql/connections.py", line 1199, in read
    first_packet = self.connection._read_packet()
                   ^^^^^^^^^^^^^^^^^^^^^^^^^^^^^^
  File "/home/ec2-user/test_form/.venv/lib64/python3.12/site-packages/pymysql/connections.py", line 775, in _read_packet
    packet.raise_for_error()
  File "/home/ec2-user/test_form/.venv/lib64/python3.12/site-packages/pymysql/protocol.py", line 219, in raise_for_error
    err.raise_mysql_exception(self._data)
  File "/home/ec2-user/test_form/.venv/lib64/python3.12/site-packages/pymysql/err.py", line 150, in raise_mysql_exception
    raise errorclass(errno, errval)
pymysql.err.IntegrityError: (1452, 'Cannot add or update a child row: a foreign key constraint fails (`form`.`choices`, CONSTRAINT `choices_ibfk_1` FOREIGN KEY (`question_id`) REFERENCES `questions` (`id`))')

The above exception was the direct cause of the following exception:

Traceback (most recent call last):
  File "/home/ec2-user/test_form/.venv/lib64/python3.12/site-packages/flask/app.py", line 1511, in wsgi_app
    response = self.full_dispatch_request()
               ^^^^^^^^^^^^^^^^^^^^^^^^^^^^
  File "/home/ec2-user/test_form/.venv/lib64/python3.12/site-packages/flask/app.py", line 919, in full_dispatch_request
    rv = self.handle_user_exception(e)
         ^^^^^^^^^^^^^^^^^^^^^^^^^^^^^
  File "/home/ec2-user/test_form/.venv/lib64/python3.12/site-packages/flask/app.py", line 917, in full_dispatch_request
    rv = self.dispatch_request()
         ^^^^^^^^^^^^^^^^^^^^^^^
  File "/home/ec2-user/test_form/.venv/lib64/python3.12/site-packages/flask/app.py", line 902, in dispatch_request
    return self.ensure_sync(self.view_functions[rule.endpoint])(**view_args)  # type: ignore[no-any-return]
           ^^^^^^^^^^^^^^^^^^^^^^^^^^^^^^^^^^^^^^^^^^^^^^^^^^^^^^^^^^^^^^^^^
  File "/home/ec2-user/test_form/app/routes.py", line 49, in create_choice
    choice = choices.create_choice()
             ^^^^^^^^^^^^^^^^^^^^^^^
  File "/home/ec2-user/test_form/app/services/choices.py", line 15, in create_choice
    db.session.commit()
  File "/home/ec2-user/test_form/.venv/lib64/python3.12/site-packages/sqlalchemy/orm/scoping.py", line 599, in commit
    return self._proxied.commit()
           ^^^^^^^^^^^^^^^^^^^^^^
  File "/home/ec2-user/test_form/.venv/lib64/python3.12/site-packages/sqlalchemy/orm/session.py", line 2032, in commit
    trans.commit(_to_root=True)
  File "<string>", line 2, in commit
  File "/home/ec2-user/test_form/.venv/lib64/python3.12/site-packages/sqlalchemy/orm/state_changes.py", line 139, in _go
    ret_value = fn(self, *arg, **kw)
                ^^^^^^^^^^^^^^^^^^^^
  File "/home/ec2-user/test_form/.venv/lib64/python3.12/site-packages/sqlalchemy/orm/session.py", line 1313, in commit
    self._prepare_impl()
  File "<string>", line 2, in _prepare_impl
  File "/home/ec2-user/test_form/.venv/lib64/python3.12/site-packages/sqlalchemy/orm/state_changes.py", line 139, in _go
    ret_value = fn(self, *arg, **kw)
                ^^^^^^^^^^^^^^^^^^^^
  File "/home/ec2-user/test_form/.venv/lib64/python3.12/site-packages/sqlalchemy/orm/session.py", line 1288, in _prepare_impl
    self.session.flush()
  File "/home/ec2-user/test_form/.venv/lib64/python3.12/site-packages/sqlalchemy/orm/session.py", line 4353, in flush
    self._flush(objects)
  File "/home/ec2-user/test_form/.venv/lib64/python3.12/site-packages/sqlalchemy/orm/session.py", line 4488, in _flush
    with util.safe_reraise():
         ^^^^^^^^^^^^^^^^^^^
  File "/home/ec2-user/test_form/.venv/lib64/python3.12/site-packages/sqlalchemy/util/langhelpers.py", line 146, in __exit__
    raise exc_value.with_traceback(exc_tb)
  File "/home/ec2-user/test_form/.venv/lib64/python3.12/site-packages/sqlalchemy/orm/session.py", line 4449, in _flush
    flush_context.execute()
  File "/home/ec2-user/test_form/.venv/lib64/python3.12/site-packages/sqlalchemy/orm/unitofwork.py", line 466, in execute
    rec.execute(self)
  File "/home/ec2-user/test_form/.venv/lib64/python3.12/site-packages/sqlalchemy/orm/unitofwork.py", line 642, in execute
    util.preloaded.orm_persistence.save_obj(
  File "/home/ec2-user/test_form/.venv/lib64/python3.12/site-packages/sqlalchemy/orm/persistence.py", line 93, in save_obj
    _emit_insert_statements(
  File "/home/ec2-user/test_form/.venv/lib64/python3.12/site-packages/sqlalchemy/orm/persistence.py", line 1233, in _emit_insert_statements
    result = connection.execute(
             ^^^^^^^^^^^^^^^^^^^
  File "/home/ec2-user/test_form/.venv/lib64/python3.12/site-packages/sqlalchemy/engine/base.py", line 1416, in execute
    return meth(
           ^^^^^
  File "/home/ec2-user/test_form/.venv/lib64/python3.12/site-packages/sqlalchemy/sql/elements.py", line 515, in _execute_on_connection
    return connection._execute_clauseelement(
           ^^^^^^^^^^^^^^^^^^^^^^^^^^^^^^^^^^
  File "/home/ec2-user/test_form/.venv/lib64/python3.12/site-packages/sqlalchemy/engine/base.py", line 1638, in _execute_clauseelement
    ret = self._execute_context(
          ^^^^^^^^^^^^^^^^^^^^^^
  File "/home/ec2-user/test_form/.venv/lib64/python3.12/site-packages/sqlalchemy/engine/base.py", line 1843, in _execute_context
    return self._exec_single_context(
           ^^^^^^^^^^^^^^^^^^^^^^^^^^
  File "/home/ec2-user/test_form/.venv/lib64/python3.12/site-packages/sqlalchemy/engine/base.py", line 1983, in _exec_single_context
    self._handle_dbapi_exception(
  File "/home/ec2-user/test_form/.venv/lib64/python3.12/site-packages/sqlalchemy/engine/base.py", line 2352, in _handle_dbapi_exception
    raise sqlalchemy_exception.with_traceback(exc_info[2]) from e
  File "/home/ec2-user/test_form/.venv/lib64/python3.12/site-packages/sqlalchemy/engine/base.py", line 1964, in _exec_single_context
    self.dialect.do_execute(
  File "/home/ec2-user/test_form/.venv/lib64/python3.12/site-packages/sqlalchemy/engine/default.py", line 942, in do_execute
    cursor.execute(statement, parameters)
  File "/home/ec2-user/test_form/.venv/lib64/python3.12/site-packages/pymysql/cursors.py", line 153, in execute
    result = self._query(query)
             ^^^^^^^^^^^^^^^^^^
  File "/home/ec2-user/test_form/.venv/lib64/python3.12/site-packages/pymysql/cursors.py", line 322, in _query
    conn.query(q)
  File "/home/ec2-user/test_form/.venv/lib64/python3.12/site-packages/pymysql/connections.py", line 563, in query
    self._affected_rows = self._read_query_result(unbuffered=unbuffered)
                          ^^^^^^^^^^^^^^^^^^^^^^^^^^^^^^^^^^^^^^^^^^^^^^
  File "/home/ec2-user/test_form/.venv/lib64/python3.12/site-packages/pymysql/connections.py", line 825, in _read_query_result
    result.read()
  File "/home/ec2-user/test_form/.venv/lib64/python3.12/site-packages/pymysql/connections.py", line 1199, in read
    first_packet = self.connection._read_packet()
                   ^^^^^^^^^^^^^^^^^^^^^^^^^^^^^^
  File "/home/ec2-user/test_form/.venv/lib64/python3.12/site-packages/pymysql/connections.py", line 775, in _read_packet
    packet.raise_for_error()
  File "/home/ec2-user/test_form/.venv/lib64/python3.12/site-packages/pymysql/protocol.py", line 219, in raise_for_error
    err.raise_mysql_exception(self._data)
  File "/home/ec2-user/test_form/.venv/lib64/python3.12/site-packages/pymysql/err.py", line 150, in raise_mysql_exception
    raise errorclass(errno, errval)
sqlalchemy.exc.IntegrityError: (pymysql.err.IntegrityError) (1452, 'Cannot add or update a child row: a foreign key constraint fails (`form`.`choices`, CONSTRAINT `choices_ibfk_1` FOREIGN KEY (`question_id`) REFERENCES `questions` (`id`))')
[SQL: INSERT INTO choices (content, is_active, sqe, question_id, created_at, updated_at) VALUES (%(content)s, %(is_active)s, %(sqe)s, %(question_id)s, %(created_at)s, %(updated_at)s)]
[parameters: {'content': '나는 누구인가', 'is_active': 1, 'sqe': 3, 'question_id': 1, 'created_at': datetime.datetime(2025, 1, 13, 11, 16, 56, 352786, tzinfo=zoneinfo.ZoneInfo(key='Asia/Seoul')), 'updated_at': datetime.datetime(2025, 1, 13, 11, 16, 56, 352795, tzinfo=zoneinfo.ZoneInfo(key='Asia/Seoul'))}]
(Background on this error at: https://sqlalche.me/e/20/gkpj)
[2025-01-13 02:47:58 +0000] [192921] [INFO] Starting gunicorn 23.0.0
[2025-01-13 02:47:58 +0000] [192921] [ERROR] Connection in use: ('127.0.0.1', 8000)
[2025-01-13 02:47:58 +0000] [192921] [ERROR] connection to ('127.0.0.1', 8000) failed: [Errno 98] Address already in use
[2025-01-13 02:47:59 +0000] [192921] [ERROR] Connection in use: ('127.0.0.1', 8000)
[2025-01-13 02:47:59 +0000] [192921] [ERROR] connection to ('127.0.0.1', 8000) failed: [Errno 98] Address already in use
[2025-01-13 02:48:00 +0000] [192921] [ERROR] Connection in use: ('127.0.0.1', 8000)
[2025-01-13 02:48:00 +0000] [192921] [ERROR] connection to ('127.0.0.1', 8000) failed: [Errno 98] Address already in use
[2025-01-13 02:48:01 +0000] [192921] [ERROR] Connection in use: ('127.0.0.1', 8000)
[2025-01-13 02:48:01 +0000] [192921] [ERROR] connection to ('127.0.0.1', 8000) failed: [Errno 98] Address already in use
[2025-01-13 02:48:02 +0000] [192921] [ERROR] Connection in use: ('127.0.0.1', 8000)
[2025-01-13 02:48:02 +0000] [192921] [ERROR] connection to ('127.0.0.1', 8000) failed: [Errno 98] Address already in use
[2025-01-13 02:48:03 +0000] [192921] [ERROR] Can't connect to ('127.0.0.1', 8000)
[2025-01-13 03:57:58 +0000] [191047] [INFO] Handling signal: term
[2025-01-13 03:57:58 +0000] [191048] [INFO] Worker exiting (pid: 191048)
[2025-01-13 03:57:58 +0000] [191049] [INFO] Worker exiting (pid: 191049)
[2025-01-13 03:57:58 +0000] [191052] [INFO] Worker exiting (pid: 191052)
[2025-01-13 03:57:58 +0000] [191053] [INFO] Worker exiting (pid: 191053)
[2025-01-13 03:57:59 +0000] [191047] [ERROR] Worker (pid:191048) was sent SIGTERM!
[2025-01-13 03:57:59 +0000] [191047] [ERROR] Worker (pid:191049) was sent SIGTERM!
[2025-01-13 03:57:59 +0000] [191047] [ERROR] Worker (pid:191052) was sent SIGTERM!
[2025-01-13 03:57:59 +0000] [191047] [INFO] Shutting down: Master
[2025-01-13 03:58:01 +0000] [197166] [INFO] Starting gunicorn 23.0.0
[2025-01-13 03:58:01 +0000] [197166] [INFO] Listening at: http://127.0.0.1:8000 (197166)
[2025-01-13 03:58:01 +0000] [197166] [INFO] Using worker: sync
[2025-01-13 03:58:01 +0000] [197168] [INFO] Booting worker with pid: 197168
[2025-01-13 03:58:01 +0000] [197169] [INFO] Booting worker with pid: 197169
[2025-01-13 03:58:01 +0000] [197172] [INFO] Booting worker with pid: 197172
[2025-01-13 03:58:01 +0000] [197173] [INFO] Booting worker with pid: 197173
[2025-01-13 03:58:03 +0000] [197169] [ERROR] Exception in worker process
Traceback (most recent call last):
  File "/home/ec2-user/test_form/.venv/lib64/python3.12/site-packages/gunicorn/arbiter.py", line 608, in spawn_worker
    worker.init_process()
  File "/home/ec2-user/test_form/.venv/lib64/python3.12/site-packages/gunicorn/workers/base.py", line 135, in init_process
    self.load_wsgi()
  File "/home/ec2-user/test_form/.venv/lib64/python3.12/site-packages/gunicorn/workers/base.py", line 147, in load_wsgi
    self.wsgi = self.app.wsgi()
                ^^^^^^^^^^^^^^^
  File "/home/ec2-user/test_form/.venv/lib64/python3.12/site-packages/gunicorn/app/base.py", line 66, in wsgi
    self.callable = self.load()
                    ^^^^^^^^^^^
  File "/home/ec2-user/test_form/.venv/lib64/python3.12/site-packages/gunicorn/app/wsgiapp.py", line 57, in load
    return self.load_wsgiapp()
           ^^^^^^^^^^^^^^^^^^^
  File "/home/ec2-user/test_form/.venv/lib64/python3.12/site-packages/gunicorn/app/wsgiapp.py", line 47, in load_wsgiapp
    return util.import_app(self.app_uri)
           ^^^^^^^^^^^^^^^^^^^^^^^^^^^^^
  File "/home/ec2-user/test_form/.venv/lib64/python3.12/site-packages/gunicorn/util.py", line 370, in import_app
    mod = importlib.import_module(module)
          ^^^^^^^^^^^^^^^^^^^^^^^^^^^^^^^
  File "/usr/lib64/python3.12/importlib/__init__.py", line 90, in import_module
    return _bootstrap._gcd_import(name[level:], package, level)
           ^^^^^^^^^^^^^^^^^^^^^^^^^^^^^^^^^^^^^^^^^^^^^^^^^^^^
  File "<frozen importlib._bootstrap>", line 1387, in _gcd_import
  File "<frozen importlib._bootstrap>", line 1360, in _find_and_load
  File "<frozen importlib._bootstrap>", line 1331, in _find_and_load_unlocked
  File "<frozen importlib._bootstrap>", line 935, in _load_unlocked
  File "<frozen importlib._bootstrap_external>", line 995, in exec_module
  File "<frozen importlib._bootstrap>", line 488, in _call_with_frames_removed
  File "/home/ec2-user/test_form/wsgi.py", line 3, in <module>
    application = create_app()
                  ^^^^^^^^^^^^
  File "/home/ec2-user/test_form/app/__init__.py", line 21, in create_app
    application.register_blueprint(routes)
  File "/home/ec2-user/test_form/.venv/lib64/python3.12/site-packages/flask/sansio/scaffold.py", line 47, in wrapper_func
    return f(self, *args, **kwargs)
           ^^^^^^^^^^^^^^^^^^^^^^^^
  File "/home/ec2-user/test_form/.venv/lib64/python3.12/site-packages/flask/sansio/app.py", line 595, in register_blueprint
    blueprint.register(self, options)
  File "/home/ec2-user/test_form/.venv/lib64/python3.12/site-packages/flask/sansio/blueprints.py", line 335, in register
    deferred(state)
  File "/home/ec2-user/test_form/.venv/lib64/python3.12/site-packages/flask/sansio/blueprints.py", line 434, in <lambda>
    lambda s: s.add_url_rule(
              ^^^^^^^^^^^^^^^
  File "/home/ec2-user/test_form/.venv/lib64/python3.12/site-packages/flask/sansio/blueprints.py", line 110, in add_url_rule
    self.app.add_url_rule(
  File "/home/ec2-user/test_form/.venv/lib64/python3.12/site-packages/flask/sansio/scaffold.py", line 47, in wrapper_func
    return f(self, *args, **kwargs)
           ^^^^^^^^^^^^^^^^^^^^^^^^
  File "/home/ec2-user/test_form/.venv/lib64/python3.12/site-packages/flask/sansio/app.py", line 653, in add_url_rule
    self.url_map.add(rule_obj)
  File "/home/ec2-user/test_form/.venv/lib64/python3.12/site-packages/werkzeug/routing/map.py", line 177, in add
    rule.bind(self)
  File "/home/ec2-user/test_form/.venv/lib64/python3.12/site-packages/werkzeug/routing/rules.py", line 581, in bind
    self.compile()
  File "/home/ec2-user/test_form/.venv/lib64/python3.12/site-packages/werkzeug/routing/rules.py", line 726, in compile
    self._parts.extend(self._parse_rule(rule))
  File "/home/ec2-user/test_form/.venv/lib64/python3.12/site-packages/werkzeug/routing/rules.py", line 618, in _parse_rule
    raise ValueError(f"malformed url rule: {rule!r}")
ValueError: malformed url rule: '/quetions/<int: questions_id>'
[2025-01-13 03:58:03 +0000] [197169] [INFO] Worker exiting (pid: 197169)
[2025-01-13 03:58:03 +0000] [197168] [ERROR] Exception in worker process
Traceback (most recent call last):
  File "/home/ec2-user/test_form/.venv/lib64/python3.12/site-packages/gunicorn/arbiter.py", line 608, in spawn_worker
    worker.init_process()
  File "/home/ec2-user/test_form/.venv/lib64/python3.12/site-packages/gunicorn/workers/base.py", line 135, in init_process
    self.load_wsgi()
  File "/home/ec2-user/test_form/.venv/lib64/python3.12/site-packages/gunicorn/workers/base.py", line 147, in load_wsgi
    self.wsgi = self.app.wsgi()
                ^^^^^^^^^^^^^^^
  File "/home/ec2-user/test_form/.venv/lib64/python3.12/site-packages/gunicorn/app/base.py", line 66, in wsgi
    self.callable = self.load()
                    ^^^^^^^^^^^
  File "/home/ec2-user/test_form/.venv/lib64/python3.12/site-packages/gunicorn/app/wsgiapp.py", line 57, in load
    return self.load_wsgiapp()
           ^^^^^^^^^^^^^^^^^^^
  File "/home/ec2-user/test_form/.venv/lib64/python3.12/site-packages/gunicorn/app/wsgiapp.py", line 47, in load_wsgiapp
    return util.import_app(self.app_uri)
           ^^^^^^^^^^^^^^^^^^^^^^^^^^^^^
  File "/home/ec2-user/test_form/.venv/lib64/python3.12/site-packages/gunicorn/util.py", line 370, in import_app
    mod = importlib.import_module(module)
          ^^^^^^^^^^^^^^^^^^^^^^^^^^^^^^^
  File "/usr/lib64/python3.12/importlib/__init__.py", line 90, in import_module
    return _bootstrap._gcd_import(name[level:], package, level)
           ^^^^^^^^^^^^^^^^^^^^^^^^^^^^^^^^^^^^^^^^^^^^^^^^^^^^
  File "<frozen importlib._bootstrap>", line 1387, in _gcd_import
  File "<frozen importlib._bootstrap>", line 1360, in _find_and_load
  File "<frozen importlib._bootstrap>", line 1331, in _find_and_load_unlocked
  File "<frozen importlib._bootstrap>", line 935, in _load_unlocked
  File "<frozen importlib._bootstrap_external>", line 995, in exec_module
  File "<frozen importlib._bootstrap>", line 488, in _call_with_frames_removed
  File "/home/ec2-user/test_form/wsgi.py", line 3, in <module>
    application = create_app()
                  ^^^^^^^^^^^^
  File "/home/ec2-user/test_form/app/__init__.py", line 21, in create_app
    application.register_blueprint(routes)
  File "/home/ec2-user/test_form/.venv/lib64/python3.12/site-packages/flask/sansio/scaffold.py", line 47, in wrapper_func
    return f(self, *args, **kwargs)
           ^^^^^^^^^^^^^^^^^^^^^^^^
  File "/home/ec2-user/test_form/.venv/lib64/python3.12/site-packages/flask/sansio/app.py", line 595, in register_blueprint
    blueprint.register(self, options)
  File "/home/ec2-user/test_form/.venv/lib64/python3.12/site-packages/flask/sansio/blueprints.py", line 335, in register
    deferred(state)
  File "/home/ec2-user/test_form/.venv/lib64/python3.12/site-packages/flask/sansio/blueprints.py", line 434, in <lambda>
    lambda s: s.add_url_rule(
              ^^^^^^^^^^^^^^^
  File "/home/ec2-user/test_form/.venv/lib64/python3.12/site-packages/flask/sansio/blueprints.py", line 110, in add_url_rule
    self.app.add_url_rule(
  File "/home/ec2-user/test_form/.venv/lib64/python3.12/site-packages/flask/sansio/scaffold.py", line 47, in wrapper_func
    return f(self, *args, **kwargs)
           ^^^^^^^^^^^^^^^^^^^^^^^^
  File "/home/ec2-user/test_form/.venv/lib64/python3.12/site-packages/flask/sansio/app.py", line 653, in add_url_rule
    self.url_map.add(rule_obj)
  File "/home/ec2-user/test_form/.venv/lib64/python3.12/site-packages/werkzeug/routing/map.py", line 177, in add
    rule.bind(self)
  File "/home/ec2-user/test_form/.venv/lib64/python3.12/site-packages/werkzeug/routing/rules.py", line 581, in bind
    self.compile()
  File "/home/ec2-user/test_form/.venv/lib64/python3.12/site-packages/werkzeug/routing/rules.py", line 726, in compile
    self._parts.extend(self._parse_rule(rule))
  File "/home/ec2-user/test_form/.venv/lib64/python3.12/site-packages/werkzeug/routing/rules.py", line 618, in _parse_rule
    raise ValueError(f"malformed url rule: {rule!r}")
ValueError: malformed url rule: '/quetions/<int: questions_id>'
[2025-01-13 03:58:03 +0000] [197168] [INFO] Worker exiting (pid: 197168)
[2025-01-13 03:58:03 +0000] [197172] [ERROR] Exception in worker process
Traceback (most recent call last):
  File "/home/ec2-user/test_form/.venv/lib64/python3.12/site-packages/gunicorn/arbiter.py", line 608, in spawn_worker
    worker.init_process()
  File "/home/ec2-user/test_form/.venv/lib64/python3.12/site-packages/gunicorn/workers/base.py", line 135, in init_process
    self.load_wsgi()
  File "/home/ec2-user/test_form/.venv/lib64/python3.12/site-packages/gunicorn/workers/base.py", line 147, in load_wsgi
    self.wsgi = self.app.wsgi()
                ^^^^^^^^^^^^^^^
  File "/home/ec2-user/test_form/.venv/lib64/python3.12/site-packages/gunicorn/app/base.py", line 66, in wsgi
    self.callable = self.load()
                    ^^^^^^^^^^^
  File "/home/ec2-user/test_form/.venv/lib64/python3.12/site-packages/gunicorn/app/wsgiapp.py", line 57, in load
    return self.load_wsgiapp()
           ^^^^^^^^^^^^^^^^^^^
  File "/home/ec2-user/test_form/.venv/lib64/python3.12/site-packages/gunicorn/app/wsgiapp.py", line 47, in load_wsgiapp
    return util.import_app(self.app_uri)
           ^^^^^^^^^^^^^^^^^^^^^^^^^^^^^
  File "/home/ec2-user/test_form/.venv/lib64/python3.12/site-packages/gunicorn/util.py", line 370, in import_app
    mod = importlib.import_module(module)
          ^^^^^^^^^^^^^^^^^^^^^^^^^^^^^^^
  File "/usr/lib64/python3.12/importlib/__init__.py", line 90, in import_module
    return _bootstrap._gcd_import(name[level:], package, level)
           ^^^^^^^^^^^^^^^^^^^^^^^^^^^^^^^^^^^^^^^^^^^^^^^^^^^^
  File "<frozen importlib._bootstrap>", line 1387, in _gcd_import
  File "<frozen importlib._bootstrap>", line 1360, in _find_and_load
  File "<frozen importlib._bootstrap>", line 1331, in _find_and_load_unlocked
  File "<frozen importlib._bootstrap>", line 935, in _load_unlocked
  File "<frozen importlib._bootstrap_external>", line 995, in exec_module
  File "<frozen importlib._bootstrap>", line 488, in _call_with_frames_removed
  File "/home/ec2-user/test_form/wsgi.py", line 3, in <module>
    application = create_app()
                  ^^^^^^^^^^^^
  File "/home/ec2-user/test_form/app/__init__.py", line 21, in create_app
    application.register_blueprint(routes)
  File "/home/ec2-user/test_form/.venv/lib64/python3.12/site-packages/flask/sansio/scaffold.py", line 47, in wrapper_func
    return f(self, *args, **kwargs)
           ^^^^^^^^^^^^^^^^^^^^^^^^
  File "/home/ec2-user/test_form/.venv/lib64/python3.12/site-packages/flask/sansio/app.py", line 595, in register_blueprint
    blueprint.register(self, options)
  File "/home/ec2-user/test_form/.venv/lib64/python3.12/site-packages/flask/sansio/blueprints.py", line 335, in register
    deferred(state)
  File "/home/ec2-user/test_form/.venv/lib64/python3.12/site-packages/flask/sansio/blueprints.py", line 434, in <lambda>
    lambda s: s.add_url_rule(
              ^^^^^^^^^^^^^^^
  File "/home/ec2-user/test_form/.venv/lib64/python3.12/site-packages/flask/sansio/blueprints.py", line 110, in add_url_rule
    self.app.add_url_rule(
  File "/home/ec2-user/test_form/.venv/lib64/python3.12/site-packages/flask/sansio/scaffold.py", line 47, in wrapper_func
    return f(self, *args, **kwargs)
           ^^^^^^^^^^^^^^^^^^^^^^^^
  File "/home/ec2-user/test_form/.venv/lib64/python3.12/site-packages/flask/sansio/app.py", line 653, in add_url_rule
    self.url_map.add(rule_obj)
  File "/home/ec2-user/test_form/.venv/lib64/python3.12/site-packages/werkzeug/routing/map.py", line 177, in add
    rule.bind(self)
  File "/home/ec2-user/test_form/.venv/lib64/python3.12/site-packages/werkzeug/routing/rules.py", line 581, in bind
    self.compile()
  File "/home/ec2-user/test_form/.venv/lib64/python3.12/site-packages/werkzeug/routing/rules.py", line 726, in compile
    self._parts.extend(self._parse_rule(rule))
  File "/home/ec2-user/test_form/.venv/lib64/python3.12/site-packages/werkzeug/routing/rules.py", line 618, in _parse_rule
    raise ValueError(f"malformed url rule: {rule!r}")
ValueError: malformed url rule: '/quetions/<int: questions_id>'
[2025-01-13 03:58:03 +0000] [197172] [INFO] Worker exiting (pid: 197172)
[2025-01-13 03:58:03 +0000] [197173] [ERROR] Exception in worker process
Traceback (most recent call last):
  File "/home/ec2-user/test_form/.venv/lib64/python3.12/site-packages/gunicorn/arbiter.py", line 608, in spawn_worker
    worker.init_process()
  File "/home/ec2-user/test_form/.venv/lib64/python3.12/site-packages/gunicorn/workers/base.py", line 135, in init_process
    self.load_wsgi()
  File "/home/ec2-user/test_form/.venv/lib64/python3.12/site-packages/gunicorn/workers/base.py", line 147, in load_wsgi
    self.wsgi = self.app.wsgi()
                ^^^^^^^^^^^^^^^
  File "/home/ec2-user/test_form/.venv/lib64/python3.12/site-packages/gunicorn/app/base.py", line 66, in wsgi
    self.callable = self.load()
                    ^^^^^^^^^^^
  File "/home/ec2-user/test_form/.venv/lib64/python3.12/site-packages/gunicorn/app/wsgiapp.py", line 57, in load
    return self.load_wsgiapp()
           ^^^^^^^^^^^^^^^^^^^
  File "/home/ec2-user/test_form/.venv/lib64/python3.12/site-packages/gunicorn/app/wsgiapp.py", line 47, in load_wsgiapp
    return util.import_app(self.app_uri)
           ^^^^^^^^^^^^^^^^^^^^^^^^^^^^^
  File "/home/ec2-user/test_form/.venv/lib64/python3.12/site-packages/gunicorn/util.py", line 370, in import_app
    mod = importlib.import_module(module)
          ^^^^^^^^^^^^^^^^^^^^^^^^^^^^^^^
  File "/usr/lib64/python3.12/importlib/__init__.py", line 90, in import_module
    return _bootstrap._gcd_import(name[level:], package, level)
           ^^^^^^^^^^^^^^^^^^^^^^^^^^^^^^^^^^^^^^^^^^^^^^^^^^^^
  File "<frozen importlib._bootstrap>", line 1387, in _gcd_import
  File "<frozen importlib._bootstrap>", line 1360, in _find_and_load
  File "<frozen importlib._bootstrap>", line 1331, in _find_and_load_unlocked
  File "<frozen importlib._bootstrap>", line 935, in _load_unlocked
  File "<frozen importlib._bootstrap_external>", line 995, in exec_module
  File "<frozen importlib._bootstrap>", line 488, in _call_with_frames_removed
  File "/home/ec2-user/test_form/wsgi.py", line 3, in <module>
    application = create_app()
                  ^^^^^^^^^^^^
  File "/home/ec2-user/test_form/app/__init__.py", line 21, in create_app
    application.register_blueprint(routes)
  File "/home/ec2-user/test_form/.venv/lib64/python3.12/site-packages/flask/sansio/scaffold.py", line 47, in wrapper_func
    return f(self, *args, **kwargs)
           ^^^^^^^^^^^^^^^^^^^^^^^^
  File "/home/ec2-user/test_form/.venv/lib64/python3.12/site-packages/flask/sansio/app.py", line 595, in register_blueprint
    blueprint.register(self, options)
  File "/home/ec2-user/test_form/.venv/lib64/python3.12/site-packages/flask/sansio/blueprints.py", line 335, in register
    deferred(state)
  File "/home/ec2-user/test_form/.venv/lib64/python3.12/site-packages/flask/sansio/blueprints.py", line 434, in <lambda>
    lambda s: s.add_url_rule(
              ^^^^^^^^^^^^^^^
  File "/home/ec2-user/test_form/.venv/lib64/python3.12/site-packages/flask/sansio/blueprints.py", line 110, in add_url_rule
    self.app.add_url_rule(
  File "/home/ec2-user/test_form/.venv/lib64/python3.12/site-packages/flask/sansio/scaffold.py", line 47, in wrapper_func
    return f(self, *args, **kwargs)
           ^^^^^^^^^^^^^^^^^^^^^^^^
  File "/home/ec2-user/test_form/.venv/lib64/python3.12/site-packages/flask/sansio/app.py", line 653, in add_url_rule
    self.url_map.add(rule_obj)
  File "/home/ec2-user/test_form/.venv/lib64/python3.12/site-packages/werkzeug/routing/map.py", line 177, in add
    rule.bind(self)
  File "/home/ec2-user/test_form/.venv/lib64/python3.12/site-packages/werkzeug/routing/rules.py", line 581, in bind
    self.compile()
  File "/home/ec2-user/test_form/.venv/lib64/python3.12/site-packages/werkzeug/routing/rules.py", line 726, in compile
    self._parts.extend(self._parse_rule(rule))
  File "/home/ec2-user/test_form/.venv/lib64/python3.12/site-packages/werkzeug/routing/rules.py", line 618, in _parse_rule
    raise ValueError(f"malformed url rule: {rule!r}")
ValueError: malformed url rule: '/quetions/<int: questions_id>'
[2025-01-13 03:58:03 +0000] [197173] [INFO] Worker exiting (pid: 197173)
[2025-01-13 03:58:04 +0000] [197166] [ERROR] Worker (pid:197169) exited with code 3
[2025-01-13 03:58:04 +0000] [197166] [ERROR] Worker (pid:197172) was sent SIGTERM!
[2025-01-13 03:58:04 +0000] [197166] [ERROR] Worker (pid:197173) was sent SIGTERM!
[2025-01-13 03:58:04 +0000] [197166] [ERROR] Worker (pid:197168) exited with code 3
[2025-01-13 04:01:14 +0000] [197940] [INFO] Starting gunicorn 23.0.0
[2025-01-13 04:01:14 +0000] [197940] [INFO] Listening at: http://127.0.0.1:8000 (197940)
[2025-01-13 04:01:14 +0000] [197940] [INFO] Using worker: sync
[2025-01-13 04:01:14 +0000] [197942] [INFO] Booting worker with pid: 197942
[2025-01-13 04:01:14 +0000] [197943] [INFO] Booting worker with pid: 197943
[2025-01-13 04:01:14 +0000] [197946] [INFO] Booting worker with pid: 197946
[2025-01-13 04:01:14 +0000] [197947] [INFO] Booting worker with pid: 197947
[2025-01-13 04:01:16 +0000] [197942] [ERROR] Exception in worker process
Traceback (most recent call last):
  File "/home/ec2-user/test_form/.venv/lib64/python3.12/site-packages/gunicorn/arbiter.py", line 608, in spawn_worker
    worker.init_process()
  File "/home/ec2-user/test_form/.venv/lib64/python3.12/site-packages/gunicorn/workers/base.py", line 135, in init_process
    self.load_wsgi()
  File "/home/ec2-user/test_form/.venv/lib64/python3.12/site-packages/gunicorn/workers/base.py", line 147, in load_wsgi
    self.wsgi = self.app.wsgi()
                ^^^^^^^^^^^^^^^
  File "/home/ec2-user/test_form/.venv/lib64/python3.12/site-packages/gunicorn/app/base.py", line 66, in wsgi
    self.callable = self.load()
                    ^^^^^^^^^^^
  File "/home/ec2-user/test_form/.venv/lib64/python3.12/site-packages/gunicorn/app/wsgiapp.py", line 57, in load
    return self.load_wsgiapp()
           ^^^^^^^^^^^^^^^^^^^
  File "/home/ec2-user/test_form/.venv/lib64/python3.12/site-packages/gunicorn/app/wsgiapp.py", line 47, in load_wsgiapp
    return util.import_app(self.app_uri)
           ^^^^^^^^^^^^^^^^^^^^^^^^^^^^^
  File "/home/ec2-user/test_form/.venv/lib64/python3.12/site-packages/gunicorn/util.py", line 370, in import_app
    mod = importlib.import_module(module)
          ^^^^^^^^^^^^^^^^^^^^^^^^^^^^^^^
  File "/usr/lib64/python3.12/importlib/__init__.py", line 90, in import_module
    return _bootstrap._gcd_import(name[level:], package, level)
           ^^^^^^^^^^^^^^^^^^^^^^^^^^^^^^^^^^^^^^^^^^^^^^^^^^^^
  File "<frozen importlib._bootstrap>", line 1387, in _gcd_import
  File "<frozen importlib._bootstrap>", line 1360, in _find_and_load
  File "<frozen importlib._bootstrap>", line 1331, in _find_and_load_unlocked
  File "<frozen importlib._bootstrap>", line 935, in _load_unlocked
  File "<frozen importlib._bootstrap_external>", line 995, in exec_module
  File "<frozen importlib._bootstrap>", line 488, in _call_with_frames_removed
  File "/home/ec2-user/test_form/wsgi.py", line 3, in <module>
    application = create_app()
                  ^^^^^^^^^^^^
  File "/home/ec2-user/test_form/app/__init__.py", line 21, in create_app
    application.register_blueprint(routes)
  File "/home/ec2-user/test_form/.venv/lib64/python3.12/site-packages/flask/sansio/scaffold.py", line 47, in wrapper_func
    return f(self, *args, **kwargs)
           ^^^^^^^^^^^^^^^^^^^^^^^^
  File "/home/ec2-user/test_form/.venv/lib64/python3.12/site-packages/flask/sansio/app.py", line 595, in register_blueprint
    blueprint.register(self, options)
  File "/home/ec2-user/test_form/.venv/lib64/python3.12/site-packages/flask/sansio/blueprints.py", line 335, in register
    deferred(state)
  File "/home/ec2-user/test_form/.venv/lib64/python3.12/site-packages/flask/sansio/blueprints.py", line 434, in <lambda>
    lambda s: s.add_url_rule(
              ^^^^^^^^^^^^^^^
  File "/home/ec2-user/test_form/.venv/lib64/python3.12/site-packages/flask/sansio/blueprints.py", line 110, in add_url_rule
    self.app.add_url_rule(
  File "/home/ec2-user/test_form/.venv/lib64/python3.12/site-packages/flask/sansio/scaffold.py", line 47, in wrapper_func
    return f(self, *args, **kwargs)
           ^^^^^^^^^^^^^^^^^^^^^^^^
  File "/home/ec2-user/test_form/.venv/lib64/python3.12/site-packages/flask/sansio/app.py", line 653, in add_url_rule
    self.url_map.add(rule_obj)
  File "/home/ec2-user/test_form/.venv/lib64/python3.12/site-packages/werkzeug/routing/map.py", line 177, in add
    rule.bind(self)
  File "/home/ec2-user/test_form/.venv/lib64/python3.12/site-packages/werkzeug/routing/rules.py", line 581, in bind
    self.compile()
  File "/home/ec2-user/test_form/.venv/lib64/python3.12/site-packages/werkzeug/routing/rules.py", line 726, in compile
    self._parts.extend(self._parse_rule(rule))
  File "/home/ec2-user/test_form/.venv/lib64/python3.12/site-packages/werkzeug/routing/rules.py", line 618, in _parse_rule
    raise ValueError(f"malformed url rule: {rule!r}")
ValueError: malformed url rule: '/quetions/<int: questions_id>'
[2025-01-13 04:01:16 +0000] [197942] [INFO] Worker exiting (pid: 197942)
[2025-01-13 04:01:16 +0000] [197943] [ERROR] Exception in worker process
Traceback (most recent call last):
  File "/home/ec2-user/test_form/.venv/lib64/python3.12/site-packages/gunicorn/arbiter.py", line 608, in spawn_worker
    worker.init_process()
  File "/home/ec2-user/test_form/.venv/lib64/python3.12/site-packages/gunicorn/workers/base.py", line 135, in init_process
    self.load_wsgi()
  File "/home/ec2-user/test_form/.venv/lib64/python3.12/site-packages/gunicorn/workers/base.py", line 147, in load_wsgi
    self.wsgi = self.app.wsgi()
                ^^^^^^^^^^^^^^^
  File "/home/ec2-user/test_form/.venv/lib64/python3.12/site-packages/gunicorn/app/base.py", line 66, in wsgi
    self.callable = self.load()
                    ^^^^^^^^^^^
  File "/home/ec2-user/test_form/.venv/lib64/python3.12/site-packages/gunicorn/app/wsgiapp.py", line 57, in load
    return self.load_wsgiapp()
           ^^^^^^^^^^^^^^^^^^^
  File "/home/ec2-user/test_form/.venv/lib64/python3.12/site-packages/gunicorn/app/wsgiapp.py", line 47, in load_wsgiapp
    return util.import_app(self.app_uri)
           ^^^^^^^^^^^^^^^^^^^^^^^^^^^^^
  File "/home/ec2-user/test_form/.venv/lib64/python3.12/site-packages/gunicorn/util.py", line 370, in import_app
    mod = importlib.import_module(module)
          ^^^^^^^^^^^^^^^^^^^^^^^^^^^^^^^
  File "/usr/lib64/python3.12/importlib/__init__.py", line 90, in import_module
    return _bootstrap._gcd_import(name[level:], package, level)
           ^^^^^^^^^^^^^^^^^^^^^^^^^^^^^^^^^^^^^^^^^^^^^^^^^^^^
  File "<frozen importlib._bootstrap>", line 1387, in _gcd_import
  File "<frozen importlib._bootstrap>", line 1360, in _find_and_load
  File "<frozen importlib._bootstrap>", line 1331, in _find_and_load_unlocked
  File "<frozen importlib._bootstrap>", line 935, in _load_unlocked
  File "<frozen importlib._bootstrap_external>", line 995, in exec_module
  File "<frozen importlib._bootstrap>", line 488, in _call_with_frames_removed
  File "/home/ec2-user/test_form/wsgi.py", line 3, in <module>
    application = create_app()
                  ^^^^^^^^^^^^
  File "/home/ec2-user/test_form/app/__init__.py", line 21, in create_app
    application.register_blueprint(routes)
  File "/home/ec2-user/test_form/.venv/lib64/python3.12/site-packages/flask/sansio/scaffold.py", line 47, in wrapper_func
    return f(self, *args, **kwargs)
           ^^^^^^^^^^^^^^^^^^^^^^^^
  File "/home/ec2-user/test_form/.venv/lib64/python3.12/site-packages/flask/sansio/app.py", line 595, in register_blueprint
    blueprint.register(self, options)
  File "/home/ec2-user/test_form/.venv/lib64/python3.12/site-packages/flask/sansio/blueprints.py", line 335, in register
    deferred(state)
  File "/home/ec2-user/test_form/.venv/lib64/python3.12/site-packages/flask/sansio/blueprints.py", line 434, in <lambda>
    lambda s: s.add_url_rule(
              ^^^^^^^^^^^^^^^
  File "/home/ec2-user/test_form/.venv/lib64/python3.12/site-packages/flask/sansio/blueprints.py", line 110, in add_url_rule
    self.app.add_url_rule(
  File "/home/ec2-user/test_form/.venv/lib64/python3.12/site-packages/flask/sansio/scaffold.py", line 47, in wrapper_func
    return f(self, *args, **kwargs)
           ^^^^^^^^^^^^^^^^^^^^^^^^
  File "/home/ec2-user/test_form/.venv/lib64/python3.12/site-packages/flask/sansio/app.py", line 653, in add_url_rule
    self.url_map.add(rule_obj)
  File "/home/ec2-user/test_form/.venv/lib64/python3.12/site-packages/werkzeug/routing/map.py", line 177, in add
    rule.bind(self)
  File "/home/ec2-user/test_form/.venv/lib64/python3.12/site-packages/werkzeug/routing/rules.py", line 581, in bind
    self.compile()
  File "/home/ec2-user/test_form/.venv/lib64/python3.12/site-packages/werkzeug/routing/rules.py", line 726, in compile
    self._parts.extend(self._parse_rule(rule))
  File "/home/ec2-user/test_form/.venv/lib64/python3.12/site-packages/werkzeug/routing/rules.py", line 618, in _parse_rule
    raise ValueError(f"malformed url rule: {rule!r}")
ValueError: malformed url rule: '/quetions/<int: questions_id>'
[2025-01-13 04:01:16 +0000] [197943] [INFO] Worker exiting (pid: 197943)
[2025-01-13 04:01:16 +0000] [197946] [ERROR] Exception in worker process
Traceback (most recent call last):
  File "/home/ec2-user/test_form/.venv/lib64/python3.12/site-packages/gunicorn/arbiter.py", line 608, in spawn_worker
    worker.init_process()
  File "/home/ec2-user/test_form/.venv/lib64/python3.12/site-packages/gunicorn/workers/base.py", line 135, in init_process
    self.load_wsgi()
  File "/home/ec2-user/test_form/.venv/lib64/python3.12/site-packages/gunicorn/workers/base.py", line 147, in load_wsgi
    self.wsgi = self.app.wsgi()
                ^^^^^^^^^^^^^^^
  File "/home/ec2-user/test_form/.venv/lib64/python3.12/site-packages/gunicorn/app/base.py", line 66, in wsgi
    self.callable = self.load()
                    ^^^^^^^^^^^
  File "/home/ec2-user/test_form/.venv/lib64/python3.12/site-packages/gunicorn/app/wsgiapp.py", line 57, in load
    return self.load_wsgiapp()
           ^^^^^^^^^^^^^^^^^^^
  File "/home/ec2-user/test_form/.venv/lib64/python3.12/site-packages/gunicorn/app/wsgiapp.py", line 47, in load_wsgiapp
    return util.import_app(self.app_uri)
           ^^^^^^^^^^^^^^^^^^^^^^^^^^^^^
  File "/home/ec2-user/test_form/.venv/lib64/python3.12/site-packages/gunicorn/util.py", line 370, in import_app
    mod = importlib.import_module(module)
          ^^^^^^^^^^^^^^^^^^^^^^^^^^^^^^^
  File "/usr/lib64/python3.12/importlib/__init__.py", line 90, in import_module
    return _bootstrap._gcd_import(name[level:], package, level)
           ^^^^^^^^^^^^^^^^^^^^^^^^^^^^^^^^^^^^^^^^^^^^^^^^^^^^
  File "<frozen importlib._bootstrap>", line 1387, in _gcd_import
  File "<frozen importlib._bootstrap>", line 1360, in _find_and_load
  File "<frozen importlib._bootstrap>", line 1331, in _find_and_load_unlocked
  File "<frozen importlib._bootstrap>", line 935, in _load_unlocked
  File "<frozen importlib._bootstrap_external>", line 995, in exec_module
  File "<frozen importlib._bootstrap>", line 488, in _call_with_frames_removed
  File "/home/ec2-user/test_form/wsgi.py", line 3, in <module>
    application = create_app()
                  ^^^^^^^^^^^^
  File "/home/ec2-user/test_form/app/__init__.py", line 21, in create_app
    application.register_blueprint(routes)
  File "/home/ec2-user/test_form/.venv/lib64/python3.12/site-packages/flask/sansio/scaffold.py", line 47, in wrapper_func
    return f(self, *args, **kwargs)
           ^^^^^^^^^^^^^^^^^^^^^^^^
  File "/home/ec2-user/test_form/.venv/lib64/python3.12/site-packages/flask/sansio/app.py", line 595, in register_blueprint
    blueprint.register(self, options)
  File "/home/ec2-user/test_form/.venv/lib64/python3.12/site-packages/flask/sansio/blueprints.py", line 335, in register
    deferred(state)
  File "/home/ec2-user/test_form/.venv/lib64/python3.12/site-packages/flask/sansio/blueprints.py", line 434, in <lambda>
    lambda s: s.add_url_rule(
              ^^^^^^^^^^^^^^^
  File "/home/ec2-user/test_form/.venv/lib64/python3.12/site-packages/flask/sansio/blueprints.py", line 110, in add_url_rule
    self.app.add_url_rule(
  File "/home/ec2-user/test_form/.venv/lib64/python3.12/site-packages/flask/sansio/scaffold.py", line 47, in wrapper_func
    return f(self, *args, **kwargs)
           ^^^^^^^^^^^^^^^^^^^^^^^^
  File "/home/ec2-user/test_form/.venv/lib64/python3.12/site-packages/flask/sansio/app.py", line 653, in add_url_rule
    self.url_map.add(rule_obj)
  File "/home/ec2-user/test_form/.venv/lib64/python3.12/site-packages/werkzeug/routing/map.py", line 177, in add
    rule.bind(self)
  File "/home/ec2-user/test_form/.venv/lib64/python3.12/site-packages/werkzeug/routing/rules.py", line 581, in bind
    self.compile()
  File "/home/ec2-user/test_form/.venv/lib64/python3.12/site-packages/werkzeug/routing/rules.py", line 726, in compile
    self._parts.extend(self._parse_rule(rule))
  File "/home/ec2-user/test_form/.venv/lib64/python3.12/site-packages/werkzeug/routing/rules.py", line 618, in _parse_rule
    raise ValueError(f"malformed url rule: {rule!r}")
ValueError: malformed url rule: '/quetions/<int: questions_id>'
[2025-01-13 04:01:16 +0000] [197946] [INFO] Worker exiting (pid: 197946)
[2025-01-13 04:01:16 +0000] [197947] [ERROR] Exception in worker process
Traceback (most recent call last):
  File "/home/ec2-user/test_form/.venv/lib64/python3.12/site-packages/gunicorn/arbiter.py", line 608, in spawn_worker
    worker.init_process()
  File "/home/ec2-user/test_form/.venv/lib64/python3.12/site-packages/gunicorn/workers/base.py", line 135, in init_process
    self.load_wsgi()
  File "/home/ec2-user/test_form/.venv/lib64/python3.12/site-packages/gunicorn/workers/base.py", line 147, in load_wsgi
    self.wsgi = self.app.wsgi()
                ^^^^^^^^^^^^^^^
  File "/home/ec2-user/test_form/.venv/lib64/python3.12/site-packages/gunicorn/app/base.py", line 66, in wsgi
    self.callable = self.load()
                    ^^^^^^^^^^^
  File "/home/ec2-user/test_form/.venv/lib64/python3.12/site-packages/gunicorn/app/wsgiapp.py", line 57, in load
    return self.load_wsgiapp()
           ^^^^^^^^^^^^^^^^^^^
  File "/home/ec2-user/test_form/.venv/lib64/python3.12/site-packages/gunicorn/app/wsgiapp.py", line 47, in load_wsgiapp
    return util.import_app(self.app_uri)
           ^^^^^^^^^^^^^^^^^^^^^^^^^^^^^
  File "/home/ec2-user/test_form/.venv/lib64/python3.12/site-packages/gunicorn/util.py", line 370, in import_app
    mod = importlib.import_module(module)
          ^^^^^^^^^^^^^^^^^^^^^^^^^^^^^^^
  File "/usr/lib64/python3.12/importlib/__init__.py", line 90, in import_module
    return _bootstrap._gcd_import(name[level:], package, level)
           ^^^^^^^^^^^^^^^^^^^^^^^^^^^^^^^^^^^^^^^^^^^^^^^^^^^^
  File "<frozen importlib._bootstrap>", line 1387, in _gcd_import
  File "<frozen importlib._bootstrap>", line 1360, in _find_and_load
  File "<frozen importlib._bootstrap>", line 1331, in _find_and_load_unlocked
  File "<frozen importlib._bootstrap>", line 935, in _load_unlocked
  File "<frozen importlib._bootstrap_external>", line 995, in exec_module
  File "<frozen importlib._bootstrap>", line 488, in _call_with_frames_removed
  File "/home/ec2-user/test_form/wsgi.py", line 3, in <module>
    application = create_app()
                  ^^^^^^^^^^^^
  File "/home/ec2-user/test_form/app/__init__.py", line 21, in create_app
    application.register_blueprint(routes)
  File "/home/ec2-user/test_form/.venv/lib64/python3.12/site-packages/flask/sansio/scaffold.py", line 47, in wrapper_func
    return f(self, *args, **kwargs)
           ^^^^^^^^^^^^^^^^^^^^^^^^
  File "/home/ec2-user/test_form/.venv/lib64/python3.12/site-packages/flask/sansio/app.py", line 595, in register_blueprint
    blueprint.register(self, options)
  File "/home/ec2-user/test_form/.venv/lib64/python3.12/site-packages/flask/sansio/blueprints.py", line 335, in register
    deferred(state)
  File "/home/ec2-user/test_form/.venv/lib64/python3.12/site-packages/flask/sansio/blueprints.py", line 434, in <lambda>
    lambda s: s.add_url_rule(
              ^^^^^^^^^^^^^^^
  File "/home/ec2-user/test_form/.venv/lib64/python3.12/site-packages/flask/sansio/blueprints.py", line 110, in add_url_rule
    self.app.add_url_rule(
  File "/home/ec2-user/test_form/.venv/lib64/python3.12/site-packages/flask/sansio/scaffold.py", line 47, in wrapper_func
    return f(self, *args, **kwargs)
           ^^^^^^^^^^^^^^^^^^^^^^^^
  File "/home/ec2-user/test_form/.venv/lib64/python3.12/site-packages/flask/sansio/app.py", line 653, in add_url_rule
    self.url_map.add(rule_obj)
  File "/home/ec2-user/test_form/.venv/lib64/python3.12/site-packages/werkzeug/routing/map.py", line 177, in add
    rule.bind(self)
  File "/home/ec2-user/test_form/.venv/lib64/python3.12/site-packages/werkzeug/routing/rules.py", line 581, in bind
    self.compile()
  File "/home/ec2-user/test_form/.venv/lib64/python3.12/site-packages/werkzeug/routing/rules.py", line 726, in compile
    self._parts.extend(self._parse_rule(rule))
  File "/home/ec2-user/test_form/.venv/lib64/python3.12/site-packages/werkzeug/routing/rules.py", line 618, in _parse_rule
    raise ValueError(f"malformed url rule: {rule!r}")
ValueError: malformed url rule: '/quetions/<int: questions_id>'
[2025-01-13 04:01:16 +0000] [197947] [INFO] Worker exiting (pid: 197947)
[2025-01-13 04:01:17 +0000] [197940] [ERROR] Worker (pid:197942) exited with code 3
[2025-01-13 04:01:17 +0000] [197940] [ERROR] Worker (pid:197946) was sent SIGTERM!
[2025-01-13 04:01:17 +0000] [197940] [ERROR] Worker (pid:197947) was sent SIGTERM!
[2025-01-13 04:01:17 +0000] [197940] [ERROR] Worker (pid:197943) was sent SIGTERM!
[2025-01-13 04:01:17 +0000] [197940] [ERROR] Shutting down: Master
[2025-01-13 04:01:17 +0000] [197940] [ERROR] Reason: Worker failed to boot.
[2025-01-13 04:04:21 +0000] [198673] [INFO] Starting gunicorn 23.0.0
[2025-01-13 04:04:21 +0000] [198673] [INFO] Listening at: http://127.0.0.1:8000 (198673)
[2025-01-13 04:04:21 +0000] [198673] [INFO] Using worker: sync
[2025-01-13 04:04:21 +0000] [198675] [INFO] Booting worker with pid: 198675
[2025-01-13 04:04:21 +0000] [198676] [INFO] Booting worker with pid: 198676
[2025-01-13 04:04:21 +0000] [198678] [INFO] Booting worker with pid: 198678
[2025-01-13 04:04:21 +0000] [198680] [INFO] Booting worker with pid: 198680
[2025-01-13 04:04:23 +0000] [198676] [ERROR] Exception in worker process
Traceback (most recent call last):
  File "/home/ec2-user/test_form/.venv/lib64/python3.12/site-packages/gunicorn/arbiter.py", line 608, in spawn_worker
    worker.init_process()
  File "/home/ec2-user/test_form/.venv/lib64/python3.12/site-packages/gunicorn/workers/base.py", line 135, in init_process
    self.load_wsgi()
  File "/home/ec2-user/test_form/.venv/lib64/python3.12/site-packages/gunicorn/workers/base.py", line 147, in load_wsgi
    self.wsgi = self.app.wsgi()
                ^^^^^^^^^^^^^^^
  File "/home/ec2-user/test_form/.venv/lib64/python3.12/site-packages/gunicorn/app/base.py", line 66, in wsgi
    self.callable = self.load()
                    ^^^^^^^^^^^
  File "/home/ec2-user/test_form/.venv/lib64/python3.12/site-packages/gunicorn/app/wsgiapp.py", line 57, in load
    return self.load_wsgiapp()
           ^^^^^^^^^^^^^^^^^^^
  File "/home/ec2-user/test_form/.venv/lib64/python3.12/site-packages/gunicorn/app/wsgiapp.py", line 47, in load_wsgiapp
    return util.import_app(self.app_uri)
           ^^^^^^^^^^^^^^^^^^^^^^^^^^^^^
  File "/home/ec2-user/test_form/.venv/lib64/python3.12/site-packages/gunicorn/util.py", line 370, in import_app
    mod = importlib.import_module(module)
          ^^^^^^^^^^^^^^^^^^^^^^^^^^^^^^^
  File "/usr/lib64/python3.12/importlib/__init__.py", line 90, in import_module
    return _bootstrap._gcd_import(name[level:], package, level)
           ^^^^^^^^^^^^^^^^^^^^^^^^^^^^^^^^^^^^^^^^^^^^^^^^^^^^
  File "<frozen importlib._bootstrap>", line 1387, in _gcd_import
  File "<frozen importlib._bootstrap>", line 1360, in _find_and_load
  File "<frozen importlib._bootstrap>", line 1331, in _find_and_load_unlocked
  File "<frozen importlib._bootstrap>", line 935, in _load_unlocked
  File "<frozen importlib._bootstrap_external>", line 995, in exec_module
  File "<frozen importlib._bootstrap>", line 488, in _call_with_frames_removed
  File "/home/ec2-user/test_form/wsgi.py", line 3, in <module>
    application = create_app()
                  ^^^^^^^^^^^^
  File "/home/ec2-user/test_form/app/__init__.py", line 21, in create_app
    application.register_blueprint(routes)
  File "/home/ec2-user/test_form/.venv/lib64/python3.12/site-packages/flask/sansio/scaffold.py", line 47, in wrapper_func
    return f(self, *args, **kwargs)
           ^^^^^^^^^^^^^^^^^^^^^^^^
  File "/home/ec2-user/test_form/.venv/lib64/python3.12/site-packages/flask/sansio/app.py", line 595, in register_blueprint
    blueprint.register(self, options)
  File "/home/ec2-user/test_form/.venv/lib64/python3.12/site-packages/flask/sansio/blueprints.py", line 335, in register
    deferred(state)
  File "/home/ec2-user/test_form/.venv/lib64/python3.12/site-packages/flask/sansio/blueprints.py", line 434, in <lambda>
    lambda s: s.add_url_rule(
              ^^^^^^^^^^^^^^^
  File "/home/ec2-user/test_form/.venv/lib64/python3.12/site-packages/flask/sansio/blueprints.py", line 110, in add_url_rule
    self.app.add_url_rule(
  File "/home/ec2-user/test_form/.venv/lib64/python3.12/site-packages/flask/sansio/scaffold.py", line 47, in wrapper_func
    return f(self, *args, **kwargs)
           ^^^^^^^^^^^^^^^^^^^^^^^^
  File "/home/ec2-user/test_form/.venv/lib64/python3.12/site-packages/flask/sansio/app.py", line 653, in add_url_rule
    self.url_map.add(rule_obj)
  File "/home/ec2-user/test_form/.venv/lib64/python3.12/site-packages/werkzeug/routing/map.py", line 177, in add
    rule.bind(self)
  File "/home/ec2-user/test_form/.venv/lib64/python3.12/site-packages/werkzeug/routing/rules.py", line 581, in bind
    self.compile()
  File "/home/ec2-user/test_form/.venv/lib64/python3.12/site-packages/werkzeug/routing/rules.py", line 726, in compile
    self._parts.extend(self._parse_rule(rule))
  File "/home/ec2-user/test_form/.venv/lib64/python3.12/site-packages/werkzeug/routing/rules.py", line 618, in _parse_rule
    raise ValueError(f"malformed url rule: {rule!r}")
ValueError: malformed url rule: '/quetions/<int: questions_id>'
[2025-01-13 04:04:23 +0000] [198676] [INFO] Worker exiting (pid: 198676)
[2025-01-13 04:04:23 +0000] [198675] [ERROR] Exception in worker process
Traceback (most recent call last):
  File "/home/ec2-user/test_form/.venv/lib64/python3.12/site-packages/gunicorn/arbiter.py", line 608, in spawn_worker
    worker.init_process()
  File "/home/ec2-user/test_form/.venv/lib64/python3.12/site-packages/gunicorn/workers/base.py", line 135, in init_process
    self.load_wsgi()
  File "/home/ec2-user/test_form/.venv/lib64/python3.12/site-packages/gunicorn/workers/base.py", line 147, in load_wsgi
    self.wsgi = self.app.wsgi()
                ^^^^^^^^^^^^^^^
  File "/home/ec2-user/test_form/.venv/lib64/python3.12/site-packages/gunicorn/app/base.py", line 66, in wsgi
    self.callable = self.load()
                    ^^^^^^^^^^^
  File "/home/ec2-user/test_form/.venv/lib64/python3.12/site-packages/gunicorn/app/wsgiapp.py", line 57, in load
    return self.load_wsgiapp()
           ^^^^^^^^^^^^^^^^^^^
  File "/home/ec2-user/test_form/.venv/lib64/python3.12/site-packages/gunicorn/app/wsgiapp.py", line 47, in load_wsgiapp
    return util.import_app(self.app_uri)
           ^^^^^^^^^^^^^^^^^^^^^^^^^^^^^
  File "/home/ec2-user/test_form/.venv/lib64/python3.12/site-packages/gunicorn/util.py", line 370, in import_app
    mod = importlib.import_module(module)
          ^^^^^^^^^^^^^^^^^^^^^^^^^^^^^^^
  File "/usr/lib64/python3.12/importlib/__init__.py", line 90, in import_module
    return _bootstrap._gcd_import(name[level:], package, level)
           ^^^^^^^^^^^^^^^^^^^^^^^^^^^^^^^^^^^^^^^^^^^^^^^^^^^^
  File "<frozen importlib._bootstrap>", line 1387, in _gcd_import
  File "<frozen importlib._bootstrap>", line 1360, in _find_and_load
  File "<frozen importlib._bootstrap>", line 1331, in _find_and_load_unlocked
  File "<frozen importlib._bootstrap>", line 935, in _load_unlocked
  File "<frozen importlib._bootstrap_external>", line 995, in exec_module
  File "<frozen importlib._bootstrap>", line 488, in _call_with_frames_removed
  File "/home/ec2-user/test_form/wsgi.py", line 3, in <module>
    application = create_app()
                  ^^^^^^^^^^^^
  File "/home/ec2-user/test_form/app/__init__.py", line 21, in create_app
    application.register_blueprint(routes)
  File "/home/ec2-user/test_form/.venv/lib64/python3.12/site-packages/flask/sansio/scaffold.py", line 47, in wrapper_func
    return f(self, *args, **kwargs)
           ^^^^^^^^^^^^^^^^^^^^^^^^
  File "/home/ec2-user/test_form/.venv/lib64/python3.12/site-packages/flask/sansio/app.py", line 595, in register_blueprint
    blueprint.register(self, options)
  File "/home/ec2-user/test_form/.venv/lib64/python3.12/site-packages/flask/sansio/blueprints.py", line 335, in register
    deferred(state)
  File "/home/ec2-user/test_form/.venv/lib64/python3.12/site-packages/flask/sansio/blueprints.py", line 434, in <lambda>
    lambda s: s.add_url_rule(
              ^^^^^^^^^^^^^^^
  File "/home/ec2-user/test_form/.venv/lib64/python3.12/site-packages/flask/sansio/blueprints.py", line 110, in add_url_rule
    self.app.add_url_rule(
  File "/home/ec2-user/test_form/.venv/lib64/python3.12/site-packages/flask/sansio/scaffold.py", line 47, in wrapper_func
    return f(self, *args, **kwargs)
           ^^^^^^^^^^^^^^^^^^^^^^^^
  File "/home/ec2-user/test_form/.venv/lib64/python3.12/site-packages/flask/sansio/app.py", line 653, in add_url_rule
    self.url_map.add(rule_obj)
  File "/home/ec2-user/test_form/.venv/lib64/python3.12/site-packages/werkzeug/routing/map.py", line 177, in add
    rule.bind(self)
  File "/home/ec2-user/test_form/.venv/lib64/python3.12/site-packages/werkzeug/routing/rules.py", line 581, in bind
    self.compile()
  File "/home/ec2-user/test_form/.venv/lib64/python3.12/site-packages/werkzeug/routing/rules.py", line 726, in compile
    self._parts.extend(self._parse_rule(rule))
  File "/home/ec2-user/test_form/.venv/lib64/python3.12/site-packages/werkzeug/routing/rules.py", line 618, in _parse_rule
    raise ValueError(f"malformed url rule: {rule!r}")
ValueError: malformed url rule: '/quetions/<int: questions_id>'
[2025-01-13 04:04:23 +0000] [198675] [INFO] Worker exiting (pid: 198675)
[2025-01-13 04:04:23 +0000] [198680] [ERROR] Exception in worker process
Traceback (most recent call last):
  File "/home/ec2-user/test_form/.venv/lib64/python3.12/site-packages/gunicorn/arbiter.py", line 608, in spawn_worker
    worker.init_process()
  File "/home/ec2-user/test_form/.venv/lib64/python3.12/site-packages/gunicorn/workers/base.py", line 135, in init_process
    self.load_wsgi()
  File "/home/ec2-user/test_form/.venv/lib64/python3.12/site-packages/gunicorn/workers/base.py", line 147, in load_wsgi
    self.wsgi = self.app.wsgi()
                ^^^^^^^^^^^^^^^
  File "/home/ec2-user/test_form/.venv/lib64/python3.12/site-packages/gunicorn/app/base.py", line 66, in wsgi
    self.callable = self.load()
                    ^^^^^^^^^^^
  File "/home/ec2-user/test_form/.venv/lib64/python3.12/site-packages/gunicorn/app/wsgiapp.py", line 57, in load
    return self.load_wsgiapp()
           ^^^^^^^^^^^^^^^^^^^
  File "/home/ec2-user/test_form/.venv/lib64/python3.12/site-packages/gunicorn/app/wsgiapp.py", line 47, in load_wsgiapp
    return util.import_app(self.app_uri)
           ^^^^^^^^^^^^^^^^^^^^^^^^^^^^^
  File "/home/ec2-user/test_form/.venv/lib64/python3.12/site-packages/gunicorn/util.py", line 370, in import_app
    mod = importlib.import_module(module)
          ^^^^^^^^^^^^^^^^^^^^^^^^^^^^^^^
  File "/usr/lib64/python3.12/importlib/__init__.py", line 90, in import_module
    return _bootstrap._gcd_import(name[level:], package, level)
           ^^^^^^^^^^^^^^^^^^^^^^^^^^^^^^^^^^^^^^^^^^^^^^^^^^^^
  File "<frozen importlib._bootstrap>", line 1387, in _gcd_import
  File "<frozen importlib._bootstrap>", line 1360, in _find_and_load
  File "<frozen importlib._bootstrap>", line 1331, in _find_and_load_unlocked
  File "<frozen importlib._bootstrap>", line 935, in _load_unlocked
  File "<frozen importlib._bootstrap_external>", line 995, in exec_module
  File "<frozen importlib._bootstrap>", line 488, in _call_with_frames_removed
  File "/home/ec2-user/test_form/wsgi.py", line 3, in <module>
    application = create_app()
                  ^^^^^^^^^^^^
  File "/home/ec2-user/test_form/app/__init__.py", line 21, in create_app
    application.register_blueprint(routes)
  File "/home/ec2-user/test_form/.venv/lib64/python3.12/site-packages/flask/sansio/scaffold.py", line 47, in wrapper_func
    return f(self, *args, **kwargs)
           ^^^^^^^^^^^^^^^^^^^^^^^^
  File "/home/ec2-user/test_form/.venv/lib64/python3.12/site-packages/flask/sansio/app.py", line 595, in register_blueprint
    blueprint.register(self, options)
  File "/home/ec2-user/test_form/.venv/lib64/python3.12/site-packages/flask/sansio/blueprints.py", line 335, in register
    deferred(state)
  File "/home/ec2-user/test_form/.venv/lib64/python3.12/site-packages/flask/sansio/blueprints.py", line 434, in <lambda>
    lambda s: s.add_url_rule(
              ^^^^^^^^^^^^^^^
  File "/home/ec2-user/test_form/.venv/lib64/python3.12/site-packages/flask/sansio/blueprints.py", line 110, in add_url_rule
    self.app.add_url_rule(
  File "/home/ec2-user/test_form/.venv/lib64/python3.12/site-packages/flask/sansio/scaffold.py", line 47, in wrapper_func
    return f(self, *args, **kwargs)
           ^^^^^^^^^^^^^^^^^^^^^^^^
  File "/home/ec2-user/test_form/.venv/lib64/python3.12/site-packages/flask/sansio/app.py", line 653, in add_url_rule
    self.url_map.add(rule_obj)
  File "/home/ec2-user/test_form/.venv/lib64/python3.12/site-packages/werkzeug/routing/map.py", line 177, in add
    rule.bind(self)
  File "/home/ec2-user/test_form/.venv/lib64/python3.12/site-packages/werkzeug/routing/rules.py", line 581, in bind
    self.compile()
  File "/home/ec2-user/test_form/.venv/lib64/python3.12/site-packages/werkzeug/routing/rules.py", line 726, in compile
    self._parts.extend(self._parse_rule(rule))
  File "/home/ec2-user/test_form/.venv/lib64/python3.12/site-packages/werkzeug/routing/rules.py", line 618, in _parse_rule
    raise ValueError(f"malformed url rule: {rule!r}")
ValueError: malformed url rule: '/quetions/<int: questions_id>'
[2025-01-13 04:04:23 +0000] [198680] [INFO] Worker exiting (pid: 198680)
[2025-01-13 04:04:23 +0000] [198678] [ERROR] Exception in worker process
Traceback (most recent call last):
  File "/home/ec2-user/test_form/.venv/lib64/python3.12/site-packages/gunicorn/arbiter.py", line 608, in spawn_worker
    worker.init_process()
  File "/home/ec2-user/test_form/.venv/lib64/python3.12/site-packages/gunicorn/workers/base.py", line 135, in init_process
    self.load_wsgi()
  File "/home/ec2-user/test_form/.venv/lib64/python3.12/site-packages/gunicorn/workers/base.py", line 147, in load_wsgi
    self.wsgi = self.app.wsgi()
                ^^^^^^^^^^^^^^^
  File "/home/ec2-user/test_form/.venv/lib64/python3.12/site-packages/gunicorn/app/base.py", line 66, in wsgi
    self.callable = self.load()
                    ^^^^^^^^^^^
  File "/home/ec2-user/test_form/.venv/lib64/python3.12/site-packages/gunicorn/app/wsgiapp.py", line 57, in load
    return self.load_wsgiapp()
           ^^^^^^^^^^^^^^^^^^^
  File "/home/ec2-user/test_form/.venv/lib64/python3.12/site-packages/gunicorn/app/wsgiapp.py", line 47, in load_wsgiapp
    return util.import_app(self.app_uri)
           ^^^^^^^^^^^^^^^^^^^^^^^^^^^^^
  File "/home/ec2-user/test_form/.venv/lib64/python3.12/site-packages/gunicorn/util.py", line 370, in import_app
    mod = importlib.import_module(module)
          ^^^^^^^^^^^^^^^^^^^^^^^^^^^^^^^
  File "/usr/lib64/python3.12/importlib/__init__.py", line 90, in import_module
    return _bootstrap._gcd_import(name[level:], package, level)
           ^^^^^^^^^^^^^^^^^^^^^^^^^^^^^^^^^^^^^^^^^^^^^^^^^^^^
  File "<frozen importlib._bootstrap>", line 1387, in _gcd_import
  File "<frozen importlib._bootstrap>", line 1360, in _find_and_load
  File "<frozen importlib._bootstrap>", line 1331, in _find_and_load_unlocked
  File "<frozen importlib._bootstrap>", line 935, in _load_unlocked
  File "<frozen importlib._bootstrap_external>", line 995, in exec_module
  File "<frozen importlib._bootstrap>", line 488, in _call_with_frames_removed
  File "/home/ec2-user/test_form/wsgi.py", line 3, in <module>
    application = create_app()
                  ^^^^^^^^^^^^
  File "/home/ec2-user/test_form/app/__init__.py", line 21, in create_app
    application.register_blueprint(routes)
  File "/home/ec2-user/test_form/.venv/lib64/python3.12/site-packages/flask/sansio/scaffold.py", line 47, in wrapper_func
    return f(self, *args, **kwargs)
           ^^^^^^^^^^^^^^^^^^^^^^^^
  File "/home/ec2-user/test_form/.venv/lib64/python3.12/site-packages/flask/sansio/app.py", line 595, in register_blueprint
    blueprint.register(self, options)
  File "/home/ec2-user/test_form/.venv/lib64/python3.12/site-packages/flask/sansio/blueprints.py", line 335, in register
    deferred(state)
  File "/home/ec2-user/test_form/.venv/lib64/python3.12/site-packages/flask/sansio/blueprints.py", line 434, in <lambda>
    lambda s: s.add_url_rule(
              ^^^^^^^^^^^^^^^
  File "/home/ec2-user/test_form/.venv/lib64/python3.12/site-packages/flask/sansio/blueprints.py", line 110, in add_url_rule
    self.app.add_url_rule(
  File "/home/ec2-user/test_form/.venv/lib64/python3.12/site-packages/flask/sansio/scaffold.py", line 47, in wrapper_func
    return f(self, *args, **kwargs)
           ^^^^^^^^^^^^^^^^^^^^^^^^
  File "/home/ec2-user/test_form/.venv/lib64/python3.12/site-packages/flask/sansio/app.py", line 653, in add_url_rule
    self.url_map.add(rule_obj)
  File "/home/ec2-user/test_form/.venv/lib64/python3.12/site-packages/werkzeug/routing/map.py", line 177, in add
    rule.bind(self)
  File "/home/ec2-user/test_form/.venv/lib64/python3.12/site-packages/werkzeug/routing/rules.py", line 581, in bind
    self.compile()
  File "/home/ec2-user/test_form/.venv/lib64/python3.12/site-packages/werkzeug/routing/rules.py", line 726, in compile
    self._parts.extend(self._parse_rule(rule))
  File "/home/ec2-user/test_form/.venv/lib64/python3.12/site-packages/werkzeug/routing/rules.py", line 618, in _parse_rule
    raise ValueError(f"malformed url rule: {rule!r}")
ValueError: malformed url rule: '/quetions/<int: questions_id>'
[2025-01-13 04:04:23 +0000] [198678] [INFO] Worker exiting (pid: 198678)
[2025-01-13 04:04:23 +0000] [198673] [ERROR] Worker (pid:198676) exited with code 3
[2025-01-13 04:04:23 +0000] [198673] [ERROR] Worker (pid:198680) was sent SIGTERM!
[2025-01-13 04:04:23 +0000] [198673] [ERROR] Worker (pid:198675) exited with code 3
[2025-01-13 04:05:52 +0000] [199130] [INFO] Starting gunicorn 23.0.0
[2025-01-13 04:05:52 +0000] [199130] [INFO] Listening at: http://127.0.0.1:8000 (199130)
[2025-01-13 04:05:52 +0000] [199130] [INFO] Using worker: sync
[2025-01-13 04:05:52 +0000] [199132] [INFO] Booting worker with pid: 199132
[2025-01-13 04:05:52 +0000] [199135] [INFO] Booting worker with pid: 199135
[2025-01-13 04:05:52 +0000] [199136] [INFO] Booting worker with pid: 199136
[2025-01-13 04:05:52 +0000] [199137] [INFO] Booting worker with pid: 199137
[2025-01-13 04:05:54 +0000] [199132] [ERROR] Exception in worker process
Traceback (most recent call last):
  File "/home/ec2-user/test_form/.venv/lib64/python3.12/site-packages/gunicorn/arbiter.py", line 608, in spawn_worker
    worker.init_process()
  File "/home/ec2-user/test_form/.venv/lib64/python3.12/site-packages/gunicorn/workers/base.py", line 135, in init_process
    self.load_wsgi()
  File "/home/ec2-user/test_form/.venv/lib64/python3.12/site-packages/gunicorn/workers/base.py", line 147, in load_wsgi
    self.wsgi = self.app.wsgi()
                ^^^^^^^^^^^^^^^
  File "/home/ec2-user/test_form/.venv/lib64/python3.12/site-packages/gunicorn/app/base.py", line 66, in wsgi
    self.callable = self.load()
                    ^^^^^^^^^^^
  File "/home/ec2-user/test_form/.venv/lib64/python3.12/site-packages/gunicorn/app/wsgiapp.py", line 57, in load
    return self.load_wsgiapp()
           ^^^^^^^^^^^^^^^^^^^
  File "/home/ec2-user/test_form/.venv/lib64/python3.12/site-packages/gunicorn/app/wsgiapp.py", line 47, in load_wsgiapp
    return util.import_app(self.app_uri)
           ^^^^^^^^^^^^^^^^^^^^^^^^^^^^^
  File "/home/ec2-user/test_form/.venv/lib64/python3.12/site-packages/gunicorn/util.py", line 370, in import_app
    mod = importlib.import_module(module)
          ^^^^^^^^^^^^^^^^^^^^^^^^^^^^^^^
  File "/usr/lib64/python3.12/importlib/__init__.py", line 90, in import_module
    return _bootstrap._gcd_import(name[level:], package, level)
           ^^^^^^^^^^^^^^^^^^^^^^^^^^^^^^^^^^^^^^^^^^^^^^^^^^^^
  File "<frozen importlib._bootstrap>", line 1387, in _gcd_import
  File "<frozen importlib._bootstrap>", line 1360, in _find_and_load
  File "<frozen importlib._bootstrap>", line 1331, in _find_and_load_unlocked
  File "<frozen importlib._bootstrap>", line 935, in _load_unlocked
  File "<frozen importlib._bootstrap_external>", line 995, in exec_module
  File "<frozen importlib._bootstrap>", line 488, in _call_with_frames_removed
  File "/home/ec2-user/test_form/wsgi.py", line 3, in <module>
    application = create_app()
                  ^^^^^^^^^^^^
  File "/home/ec2-user/test_form/app/__init__.py", line 21, in create_app
    application.register_blueprint(routes)
  File "/home/ec2-user/test_form/.venv/lib64/python3.12/site-packages/flask/sansio/scaffold.py", line 47, in wrapper_func
    return f(self, *args, **kwargs)
           ^^^^^^^^^^^^^^^^^^^^^^^^
  File "/home/ec2-user/test_form/.venv/lib64/python3.12/site-packages/flask/sansio/app.py", line 595, in register_blueprint
    blueprint.register(self, options)
  File "/home/ec2-user/test_form/.venv/lib64/python3.12/site-packages/flask/sansio/blueprints.py", line 335, in register
    deferred(state)
  File "/home/ec2-user/test_form/.venv/lib64/python3.12/site-packages/flask/sansio/blueprints.py", line 434, in <lambda>
    lambda s: s.add_url_rule(
              ^^^^^^^^^^^^^^^
  File "/home/ec2-user/test_form/.venv/lib64/python3.12/site-packages/flask/sansio/blueprints.py", line 110, in add_url_rule
    self.app.add_url_rule(
  File "/home/ec2-user/test_form/.venv/lib64/python3.12/site-packages/flask/sansio/scaffold.py", line 47, in wrapper_func
    return f(self, *args, **kwargs)
           ^^^^^^^^^^^^^^^^^^^^^^^^
  File "/home/ec2-user/test_form/.venv/lib64/python3.12/site-packages/flask/sansio/app.py", line 653, in add_url_rule
    self.url_map.add(rule_obj)
  File "/home/ec2-user/test_form/.venv/lib64/python3.12/site-packages/werkzeug/routing/map.py", line 177, in add
    rule.bind(self)
  File "/home/ec2-user/test_form/.venv/lib64/python3.12/site-packages/werkzeug/routing/rules.py", line 581, in bind
    self.compile()
  File "/home/ec2-user/test_form/.venv/lib64/python3.12/site-packages/werkzeug/routing/rules.py", line 726, in compile
    self._parts.extend(self._parse_rule(rule))
  File "/home/ec2-user/test_form/.venv/lib64/python3.12/site-packages/werkzeug/routing/rules.py", line 618, in _parse_rule
    raise ValueError(f"malformed url rule: {rule!r}")
ValueError: malformed url rule: '/questions/<int: questions_id>'
[2025-01-13 04:05:54 +0000] [199132] [INFO] Worker exiting (pid: 199132)
[2025-01-13 04:05:54 +0000] [199135] [ERROR] Exception in worker process
Traceback (most recent call last):
  File "/home/ec2-user/test_form/.venv/lib64/python3.12/site-packages/gunicorn/arbiter.py", line 608, in spawn_worker
    worker.init_process()
  File "/home/ec2-user/test_form/.venv/lib64/python3.12/site-packages/gunicorn/workers/base.py", line 135, in init_process
    self.load_wsgi()
  File "/home/ec2-user/test_form/.venv/lib64/python3.12/site-packages/gunicorn/workers/base.py", line 147, in load_wsgi
    self.wsgi = self.app.wsgi()
                ^^^^^^^^^^^^^^^
  File "/home/ec2-user/test_form/.venv/lib64/python3.12/site-packages/gunicorn/app/base.py", line 66, in wsgi
    self.callable = self.load()
                    ^^^^^^^^^^^
  File "/home/ec2-user/test_form/.venv/lib64/python3.12/site-packages/gunicorn/app/wsgiapp.py", line 57, in load
    return self.load_wsgiapp()
           ^^^^^^^^^^^^^^^^^^^
  File "/home/ec2-user/test_form/.venv/lib64/python3.12/site-packages/gunicorn/app/wsgiapp.py", line 47, in load_wsgiapp
    return util.import_app(self.app_uri)
           ^^^^^^^^^^^^^^^^^^^^^^^^^^^^^
  File "/home/ec2-user/test_form/.venv/lib64/python3.12/site-packages/gunicorn/util.py", line 370, in import_app
    mod = importlib.import_module(module)
          ^^^^^^^^^^^^^^^^^^^^^^^^^^^^^^^
  File "/usr/lib64/python3.12/importlib/__init__.py", line 90, in import_module
    return _bootstrap._gcd_import(name[level:], package, level)
           ^^^^^^^^^^^^^^^^^^^^^^^^^^^^^^^^^^^^^^^^^^^^^^^^^^^^
  File "<frozen importlib._bootstrap>", line 1387, in _gcd_import
  File "<frozen importlib._bootstrap>", line 1360, in _find_and_load
  File "<frozen importlib._bootstrap>", line 1331, in _find_and_load_unlocked
  File "<frozen importlib._bootstrap>", line 935, in _load_unlocked
  File "<frozen importlib._bootstrap_external>", line 995, in exec_module
  File "<frozen importlib._bootstrap>", line 488, in _call_with_frames_removed
  File "/home/ec2-user/test_form/wsgi.py", line 3, in <module>
    application = create_app()
                  ^^^^^^^^^^^^
  File "/home/ec2-user/test_form/app/__init__.py", line 21, in create_app
    application.register_blueprint(routes)
  File "/home/ec2-user/test_form/.venv/lib64/python3.12/site-packages/flask/sansio/scaffold.py", line 47, in wrapper_func
    return f(self, *args, **kwargs)
           ^^^^^^^^^^^^^^^^^^^^^^^^
  File "/home/ec2-user/test_form/.venv/lib64/python3.12/site-packages/flask/sansio/app.py", line 595, in register_blueprint
    blueprint.register(self, options)
  File "/home/ec2-user/test_form/.venv/lib64/python3.12/site-packages/flask/sansio/blueprints.py", line 335, in register
    deferred(state)
  File "/home/ec2-user/test_form/.venv/lib64/python3.12/site-packages/flask/sansio/blueprints.py", line 434, in <lambda>
    lambda s: s.add_url_rule(
              ^^^^^^^^^^^^^^^
  File "/home/ec2-user/test_form/.venv/lib64/python3.12/site-packages/flask/sansio/blueprints.py", line 110, in add_url_rule
    self.app.add_url_rule(
  File "/home/ec2-user/test_form/.venv/lib64/python3.12/site-packages/flask/sansio/scaffold.py", line 47, in wrapper_func
    return f(self, *args, **kwargs)
           ^^^^^^^^^^^^^^^^^^^^^^^^
  File "/home/ec2-user/test_form/.venv/lib64/python3.12/site-packages/flask/sansio/app.py", line 653, in add_url_rule
    self.url_map.add(rule_obj)
  File "/home/ec2-user/test_form/.venv/lib64/python3.12/site-packages/werkzeug/routing/map.py", line 177, in add
    rule.bind(self)
  File "/home/ec2-user/test_form/.venv/lib64/python3.12/site-packages/werkzeug/routing/rules.py", line 581, in bind
    self.compile()
  File "/home/ec2-user/test_form/.venv/lib64/python3.12/site-packages/werkzeug/routing/rules.py", line 726, in compile
    self._parts.extend(self._parse_rule(rule))
  File "/home/ec2-user/test_form/.venv/lib64/python3.12/site-packages/werkzeug/routing/rules.py", line 618, in _parse_rule
    raise ValueError(f"malformed url rule: {rule!r}")
ValueError: malformed url rule: '/questions/<int: questions_id>'
[2025-01-13 04:05:54 +0000] [199135] [INFO] Worker exiting (pid: 199135)
[2025-01-13 04:05:54 +0000] [199136] [ERROR] Exception in worker process
Traceback (most recent call last):
  File "/home/ec2-user/test_form/.venv/lib64/python3.12/site-packages/gunicorn/arbiter.py", line 608, in spawn_worker
    worker.init_process()
  File "/home/ec2-user/test_form/.venv/lib64/python3.12/site-packages/gunicorn/workers/base.py", line 135, in init_process
    self.load_wsgi()
  File "/home/ec2-user/test_form/.venv/lib64/python3.12/site-packages/gunicorn/workers/base.py", line 147, in load_wsgi
    self.wsgi = self.app.wsgi()
                ^^^^^^^^^^^^^^^
  File "/home/ec2-user/test_form/.venv/lib64/python3.12/site-packages/gunicorn/app/base.py", line 66, in wsgi
    self.callable = self.load()
                    ^^^^^^^^^^^
  File "/home/ec2-user/test_form/.venv/lib64/python3.12/site-packages/gunicorn/app/wsgiapp.py", line 57, in load
    return self.load_wsgiapp()
           ^^^^^^^^^^^^^^^^^^^
  File "/home/ec2-user/test_form/.venv/lib64/python3.12/site-packages/gunicorn/app/wsgiapp.py", line 47, in load_wsgiapp
    return util.import_app(self.app_uri)
           ^^^^^^^^^^^^^^^^^^^^^^^^^^^^^
  File "/home/ec2-user/test_form/.venv/lib64/python3.12/site-packages/gunicorn/util.py", line 370, in import_app
    mod = importlib.import_module(module)
          ^^^^^^^^^^^^^^^^^^^^^^^^^^^^^^^
  File "/usr/lib64/python3.12/importlib/__init__.py", line 90, in import_module
    return _bootstrap._gcd_import(name[level:], package, level)
           ^^^^^^^^^^^^^^^^^^^^^^^^^^^^^^^^^^^^^^^^^^^^^^^^^^^^
  File "<frozen importlib._bootstrap>", line 1387, in _gcd_import
  File "<frozen importlib._bootstrap>", line 1360, in _find_and_load
  File "<frozen importlib._bootstrap>", line 1331, in _find_and_load_unlocked
  File "<frozen importlib._bootstrap>", line 935, in _load_unlocked
  File "<frozen importlib._bootstrap_external>", line 995, in exec_module
  File "<frozen importlib._bootstrap>", line 488, in _call_with_frames_removed
  File "/home/ec2-user/test_form/wsgi.py", line 3, in <module>
    application = create_app()
                  ^^^^^^^^^^^^
  File "/home/ec2-user/test_form/app/__init__.py", line 21, in create_app
    application.register_blueprint(routes)
  File "/home/ec2-user/test_form/.venv/lib64/python3.12/site-packages/flask/sansio/scaffold.py", line 47, in wrapper_func
    return f(self, *args, **kwargs)
           ^^^^^^^^^^^^^^^^^^^^^^^^
  File "/home/ec2-user/test_form/.venv/lib64/python3.12/site-packages/flask/sansio/app.py", line 595, in register_blueprint
    blueprint.register(self, options)
  File "/home/ec2-user/test_form/.venv/lib64/python3.12/site-packages/flask/sansio/blueprints.py", line 335, in register
    deferred(state)
  File "/home/ec2-user/test_form/.venv/lib64/python3.12/site-packages/flask/sansio/blueprints.py", line 434, in <lambda>
    lambda s: s.add_url_rule(
              ^^^^^^^^^^^^^^^
  File "/home/ec2-user/test_form/.venv/lib64/python3.12/site-packages/flask/sansio/blueprints.py", line 110, in add_url_rule
    self.app.add_url_rule(
  File "/home/ec2-user/test_form/.venv/lib64/python3.12/site-packages/flask/sansio/scaffold.py", line 47, in wrapper_func
    return f(self, *args, **kwargs)
           ^^^^^^^^^^^^^^^^^^^^^^^^
  File "/home/ec2-user/test_form/.venv/lib64/python3.12/site-packages/flask/sansio/app.py", line 653, in add_url_rule
    self.url_map.add(rule_obj)
  File "/home/ec2-user/test_form/.venv/lib64/python3.12/site-packages/werkzeug/routing/map.py", line 177, in add
    rule.bind(self)
  File "/home/ec2-user/test_form/.venv/lib64/python3.12/site-packages/werkzeug/routing/rules.py", line 581, in bind
    self.compile()
  File "/home/ec2-user/test_form/.venv/lib64/python3.12/site-packages/werkzeug/routing/rules.py", line 726, in compile
    self._parts.extend(self._parse_rule(rule))
  File "/home/ec2-user/test_form/.venv/lib64/python3.12/site-packages/werkzeug/routing/rules.py", line 618, in _parse_rule
    raise ValueError(f"malformed url rule: {rule!r}")
ValueError: malformed url rule: '/questions/<int: questions_id>'
[2025-01-13 04:05:54 +0000] [199136] [INFO] Worker exiting (pid: 199136)
[2025-01-13 04:05:54 +0000] [199137] [ERROR] Exception in worker process
Traceback (most recent call last):
  File "/home/ec2-user/test_form/.venv/lib64/python3.12/site-packages/gunicorn/arbiter.py", line 608, in spawn_worker
    worker.init_process()
  File "/home/ec2-user/test_form/.venv/lib64/python3.12/site-packages/gunicorn/workers/base.py", line 135, in init_process
    self.load_wsgi()
  File "/home/ec2-user/test_form/.venv/lib64/python3.12/site-packages/gunicorn/workers/base.py", line 147, in load_wsgi
    self.wsgi = self.app.wsgi()
                ^^^^^^^^^^^^^^^
  File "/home/ec2-user/test_form/.venv/lib64/python3.12/site-packages/gunicorn/app/base.py", line 66, in wsgi
    self.callable = self.load()
                    ^^^^^^^^^^^
  File "/home/ec2-user/test_form/.venv/lib64/python3.12/site-packages/gunicorn/app/wsgiapp.py", line 57, in load
    return self.load_wsgiapp()
           ^^^^^^^^^^^^^^^^^^^
  File "/home/ec2-user/test_form/.venv/lib64/python3.12/site-packages/gunicorn/app/wsgiapp.py", line 47, in load_wsgiapp
    return util.import_app(self.app_uri)
           ^^^^^^^^^^^^^^^^^^^^^^^^^^^^^
  File "/home/ec2-user/test_form/.venv/lib64/python3.12/site-packages/gunicorn/util.py", line 370, in import_app
    mod = importlib.import_module(module)
          ^^^^^^^^^^^^^^^^^^^^^^^^^^^^^^^
  File "/usr/lib64/python3.12/importlib/__init__.py", line 90, in import_module
    return _bootstrap._gcd_import(name[level:], package, level)
           ^^^^^^^^^^^^^^^^^^^^^^^^^^^^^^^^^^^^^^^^^^^^^^^^^^^^
  File "<frozen importlib._bootstrap>", line 1387, in _gcd_import
  File "<frozen importlib._bootstrap>", line 1360, in _find_and_load
  File "<frozen importlib._bootstrap>", line 1331, in _find_and_load_unlocked
  File "<frozen importlib._bootstrap>", line 935, in _load_unlocked
  File "<frozen importlib._bootstrap_external>", line 995, in exec_module
  File "<frozen importlib._bootstrap>", line 488, in _call_with_frames_removed
  File "/home/ec2-user/test_form/wsgi.py", line 3, in <module>
    application = create_app()
                  ^^^^^^^^^^^^
  File "/home/ec2-user/test_form/app/__init__.py", line 21, in create_app
    application.register_blueprint(routes)
  File "/home/ec2-user/test_form/.venv/lib64/python3.12/site-packages/flask/sansio/scaffold.py", line 47, in wrapper_func
    return f(self, *args, **kwargs)
           ^^^^^^^^^^^^^^^^^^^^^^^^
  File "/home/ec2-user/test_form/.venv/lib64/python3.12/site-packages/flask/sansio/app.py", line 595, in register_blueprint
    blueprint.register(self, options)
  File "/home/ec2-user/test_form/.venv/lib64/python3.12/site-packages/flask/sansio/blueprints.py", line 335, in register
    deferred(state)
  File "/home/ec2-user/test_form/.venv/lib64/python3.12/site-packages/flask/sansio/blueprints.py", line 434, in <lambda>
    lambda s: s.add_url_rule(
              ^^^^^^^^^^^^^^^
  File "/home/ec2-user/test_form/.venv/lib64/python3.12/site-packages/flask/sansio/blueprints.py", line 110, in add_url_rule
    self.app.add_url_rule(
  File "/home/ec2-user/test_form/.venv/lib64/python3.12/site-packages/flask/sansio/scaffold.py", line 47, in wrapper_func
    return f(self, *args, **kwargs)
           ^^^^^^^^^^^^^^^^^^^^^^^^
  File "/home/ec2-user/test_form/.venv/lib64/python3.12/site-packages/flask/sansio/app.py", line 653, in add_url_rule
    self.url_map.add(rule_obj)
  File "/home/ec2-user/test_form/.venv/lib64/python3.12/site-packages/werkzeug/routing/map.py", line 177, in add
    rule.bind(self)
  File "/home/ec2-user/test_form/.venv/lib64/python3.12/site-packages/werkzeug/routing/rules.py", line 581, in bind
    self.compile()
  File "/home/ec2-user/test_form/.venv/lib64/python3.12/site-packages/werkzeug/routing/rules.py", line 726, in compile
    self._parts.extend(self._parse_rule(rule))
  File "/home/ec2-user/test_form/.venv/lib64/python3.12/site-packages/werkzeug/routing/rules.py", line 618, in _parse_rule
    raise ValueError(f"malformed url rule: {rule!r}")
ValueError: malformed url rule: '/questions/<int: questions_id>'
[2025-01-13 04:05:54 +0000] [199137] [INFO] Worker exiting (pid: 199137)
[2025-01-13 04:05:55 +0000] [199130] [ERROR] Worker (pid:199132) exited with code 3
[2025-01-13 04:05:55 +0000] [199130] [ERROR] Worker (pid:199135) was sent SIGTERM!
[2025-01-13 04:05:55 +0000] [199130] [ERROR] Worker (pid:199136) was sent SIGTERM!
[2025-01-13 04:05:55 +0000] [199130] [ERROR] Worker (pid:199137) was sent SIGTERM!
[2025-01-13 04:05:55 +0000] [199130] [ERROR] Shutting down: Master
[2025-01-13 04:05:55 +0000] [199130] [ERROR] Reason: Worker failed to boot.
[2025-01-13 04:07:43 +0000] [199474] [INFO] Starting gunicorn 23.0.0
[2025-01-13 04:07:43 +0000] [199474] [INFO] Listening at: http://127.0.0.1:8000 (199474)
[2025-01-13 04:07:43 +0000] [199474] [INFO] Using worker: sync
[2025-01-13 04:07:43 +0000] [199476] [INFO] Booting worker with pid: 199476
[2025-01-13 04:07:43 +0000] [199479] [INFO] Booting worker with pid: 199479
[2025-01-13 04:07:43 +0000] [199480] [INFO] Booting worker with pid: 199480
[2025-01-13 04:07:43 +0000] [199482] [INFO] Booting worker with pid: 199482
[2025-01-13 04:08:02,620] ERROR in app: Exception on /questions/1 [GET]
Traceback (most recent call last):
  File "/home/ec2-user/test_form/.venv/lib64/python3.12/site-packages/flask/app.py", line 1511, in wsgi_app
    response = self.full_dispatch_request()
               ^^^^^^^^^^^^^^^^^^^^^^^^^^^^
  File "/home/ec2-user/test_form/.venv/lib64/python3.12/site-packages/flask/app.py", line 919, in full_dispatch_request
    rv = self.handle_user_exception(e)
         ^^^^^^^^^^^^^^^^^^^^^^^^^^^^^
  File "/home/ec2-user/test_form/.venv/lib64/python3.12/site-packages/flask/app.py", line 917, in full_dispatch_request
    rv = self.dispatch_request()
         ^^^^^^^^^^^^^^^^^^^^^^^
  File "/home/ec2-user/test_form/.venv/lib64/python3.12/site-packages/flask/app.py", line 902, in dispatch_request
    return self.ensure_sync(self.view_functions[rule.endpoint])(**view_args)  # type: ignore[no-any-return]
           ^^^^^^^^^^^^^^^^^^^^^^^^^^^^^^^^^^^^^^^^^^^^^^^^^^^^^^^^^^^^^^^^^
TypeError: question_page() got an unexpected keyword argument 'questions_id'
[2025-01-13 04:08:17,810] ERROR in app: Exception on /questions/1 [GET]
Traceback (most recent call last):
  File "/home/ec2-user/test_form/.venv/lib64/python3.12/site-packages/flask/app.py", line 1511, in wsgi_app
    response = self.full_dispatch_request()
               ^^^^^^^^^^^^^^^^^^^^^^^^^^^^
  File "/home/ec2-user/test_form/.venv/lib64/python3.12/site-packages/flask/app.py", line 919, in full_dispatch_request
    rv = self.handle_user_exception(e)
         ^^^^^^^^^^^^^^^^^^^^^^^^^^^^^
  File "/home/ec2-user/test_form/.venv/lib64/python3.12/site-packages/flask/app.py", line 917, in full_dispatch_request
    rv = self.dispatch_request()
         ^^^^^^^^^^^^^^^^^^^^^^^
  File "/home/ec2-user/test_form/.venv/lib64/python3.12/site-packages/flask/app.py", line 902, in dispatch_request
    return self.ensure_sync(self.view_functions[rule.endpoint])(**view_args)  # type: ignore[no-any-return]
           ^^^^^^^^^^^^^^^^^^^^^^^^^^^^^^^^^^^^^^^^^^^^^^^^^^^^^^^^^^^^^^^^^
TypeError: question_page() got an unexpected keyword argument 'questions_id'
[2025-01-13 04:10:09 +0000] [200296] [INFO] Starting gunicorn 23.0.0
[2025-01-13 04:10:09 +0000] [200296] [ERROR] Connection in use: ('127.0.0.1', 8000)
[2025-01-13 04:10:09 +0000] [200296] [ERROR] connection to ('127.0.0.1', 8000) failed: [Errno 98] Address already in use
[2025-01-13 04:10:10 +0000] [200296] [ERROR] Connection in use: ('127.0.0.1', 8000)
[2025-01-13 04:10:10 +0000] [200296] [ERROR] connection to ('127.0.0.1', 8000) failed: [Errno 98] Address already in use
[2025-01-13 04:10:11 +0000] [200296] [ERROR] Connection in use: ('127.0.0.1', 8000)
[2025-01-13 04:10:11 +0000] [200296] [ERROR] connection to ('127.0.0.1', 8000) failed: [Errno 98] Address already in use
[2025-01-13 04:10:12 +0000] [200296] [ERROR] Connection in use: ('127.0.0.1', 8000)
[2025-01-13 04:10:12 +0000] [200296] [ERROR] connection to ('127.0.0.1', 8000) failed: [Errno 98] Address already in use
[2025-01-13 04:10:13 +0000] [200296] [ERROR] Connection in use: ('127.0.0.1', 8000)
[2025-01-13 04:10:13 +0000] [200296] [ERROR] connection to ('127.0.0.1', 8000) failed: [Errno 98] Address already in use
[2025-01-13 04:10:14 +0000] [200296] [ERROR] Can't connect to ('127.0.0.1', 8000)
[2025-01-13 04:10:15,236] ERROR in app: Exception on /signup [POST]
Traceback (most recent call last):
  File "/home/ec2-user/test_form/.venv/lib64/python3.12/site-packages/sqlalchemy/engine/base.py", line 1964, in _exec_single_context
    self.dialect.do_execute(
  File "/home/ec2-user/test_form/.venv/lib64/python3.12/site-packages/sqlalchemy/engine/default.py", line 942, in do_execute
    cursor.execute(statement, parameters)
  File "/home/ec2-user/test_form/.venv/lib64/python3.12/site-packages/pymysql/cursors.py", line 153, in execute
    result = self._query(query)
             ^^^^^^^^^^^^^^^^^^
  File "/home/ec2-user/test_form/.venv/lib64/python3.12/site-packages/pymysql/cursors.py", line 322, in _query
    conn.query(q)
  File "/home/ec2-user/test_form/.venv/lib64/python3.12/site-packages/pymysql/connections.py", line 563, in query
    self._affected_rows = self._read_query_result(unbuffered=unbuffered)
                          ^^^^^^^^^^^^^^^^^^^^^^^^^^^^^^^^^^^^^^^^^^^^^^
  File "/home/ec2-user/test_form/.venv/lib64/python3.12/site-packages/pymysql/connections.py", line 825, in _read_query_result
    result.read()
  File "/home/ec2-user/test_form/.venv/lib64/python3.12/site-packages/pymysql/connections.py", line 1199, in read
    first_packet = self.connection._read_packet()
                   ^^^^^^^^^^^^^^^^^^^^^^^^^^^^^^
  File "/home/ec2-user/test_form/.venv/lib64/python3.12/site-packages/pymysql/connections.py", line 775, in _read_packet
    packet.raise_for_error()
  File "/home/ec2-user/test_form/.venv/lib64/python3.12/site-packages/pymysql/protocol.py", line 219, in raise_for_error
    err.raise_mysql_exception(self._data)
  File "/home/ec2-user/test_form/.venv/lib64/python3.12/site-packages/pymysql/err.py", line 150, in raise_mysql_exception
    raise errorclass(errno, errval)
pymysql.err.IntegrityError: (1062, "Duplicate entry 'adnjasi123@csokm.com' for key 'users.email'")

The above exception was the direct cause of the following exception:

Traceback (most recent call last):
  File "/home/ec2-user/test_form/.venv/lib64/python3.12/site-packages/flask/app.py", line 1511, in wsgi_app
    response = self.full_dispatch_request()
               ^^^^^^^^^^^^^^^^^^^^^^^^^^^^
  File "/home/ec2-user/test_form/.venv/lib64/python3.12/site-packages/flask/app.py", line 919, in full_dispatch_request
    rv = self.handle_user_exception(e)
         ^^^^^^^^^^^^^^^^^^^^^^^^^^^^^
  File "/home/ec2-user/test_form/.venv/lib64/python3.12/site-packages/flask/app.py", line 917, in full_dispatch_request
    rv = self.dispatch_request()
         ^^^^^^^^^^^^^^^^^^^^^^^
  File "/home/ec2-user/test_form/.venv/lib64/python3.12/site-packages/flask/app.py", line 902, in dispatch_request
    return self.ensure_sync(self.view_functions[rule.endpoint])(**view_args)  # type: ignore[no-any-return]
           ^^^^^^^^^^^^^^^^^^^^^^^^^^^^^^^^^^^^^^^^^^^^^^^^^^^^^^^^^^^^^^^^^
  File "/home/ec2-user/test_form/app/routes.py", line 17, in signup_page
    user = users.create_user()
           ^^^^^^^^^^^^^^^^^^^
  File "/home/ec2-user/test_form/app/services/users.py", line 15, in create_user
    db.session.commit()
  File "/home/ec2-user/test_form/.venv/lib64/python3.12/site-packages/sqlalchemy/orm/scoping.py", line 599, in commit
    return self._proxied.commit()
           ^^^^^^^^^^^^^^^^^^^^^^
  File "/home/ec2-user/test_form/.venv/lib64/python3.12/site-packages/sqlalchemy/orm/session.py", line 2032, in commit
    trans.commit(_to_root=True)
  File "<string>", line 2, in commit
  File "/home/ec2-user/test_form/.venv/lib64/python3.12/site-packages/sqlalchemy/orm/state_changes.py", line 139, in _go
    ret_value = fn(self, *arg, **kw)
                ^^^^^^^^^^^^^^^^^^^^
  File "/home/ec2-user/test_form/.venv/lib64/python3.12/site-packages/sqlalchemy/orm/session.py", line 1313, in commit
    self._prepare_impl()
  File "<string>", line 2, in _prepare_impl
  File "/home/ec2-user/test_form/.venv/lib64/python3.12/site-packages/sqlalchemy/orm/state_changes.py", line 139, in _go
    ret_value = fn(self, *arg, **kw)
                ^^^^^^^^^^^^^^^^^^^^
  File "/home/ec2-user/test_form/.venv/lib64/python3.12/site-packages/sqlalchemy/orm/session.py", line 1288, in _prepare_impl
    self.session.flush()
  File "/home/ec2-user/test_form/.venv/lib64/python3.12/site-packages/sqlalchemy/orm/session.py", line 4353, in flush
    self._flush(objects)
  File "/home/ec2-user/test_form/.venv/lib64/python3.12/site-packages/sqlalchemy/orm/session.py", line 4488, in _flush
    with util.safe_reraise():
         ^^^^^^^^^^^^^^^^^^^
  File "/home/ec2-user/test_form/.venv/lib64/python3.12/site-packages/sqlalchemy/util/langhelpers.py", line 146, in __exit__
    raise exc_value.with_traceback(exc_tb)
  File "/home/ec2-user/test_form/.venv/lib64/python3.12/site-packages/sqlalchemy/orm/session.py", line 4449, in _flush
    flush_context.execute()
  File "/home/ec2-user/test_form/.venv/lib64/python3.12/site-packages/sqlalchemy/orm/unitofwork.py", line 466, in execute
    rec.execute(self)
  File "/home/ec2-user/test_form/.venv/lib64/python3.12/site-packages/sqlalchemy/orm/unitofwork.py", line 642, in execute
    util.preloaded.orm_persistence.save_obj(
  File "/home/ec2-user/test_form/.venv/lib64/python3.12/site-packages/sqlalchemy/orm/persistence.py", line 93, in save_obj
    _emit_insert_statements(
  File "/home/ec2-user/test_form/.venv/lib64/python3.12/site-packages/sqlalchemy/orm/persistence.py", line 1233, in _emit_insert_statements
    result = connection.execute(
             ^^^^^^^^^^^^^^^^^^^
  File "/home/ec2-user/test_form/.venv/lib64/python3.12/site-packages/sqlalchemy/engine/base.py", line 1416, in execute
    return meth(
           ^^^^^
  File "/home/ec2-user/test_form/.venv/lib64/python3.12/site-packages/sqlalchemy/sql/elements.py", line 515, in _execute_on_connection
    return connection._execute_clauseelement(
           ^^^^^^^^^^^^^^^^^^^^^^^^^^^^^^^^^^
  File "/home/ec2-user/test_form/.venv/lib64/python3.12/site-packages/sqlalchemy/engine/base.py", line 1638, in _execute_clauseelement
    ret = self._execute_context(
          ^^^^^^^^^^^^^^^^^^^^^^
  File "/home/ec2-user/test_form/.venv/lib64/python3.12/site-packages/sqlalchemy/engine/base.py", line 1843, in _execute_context
    return self._exec_single_context(
           ^^^^^^^^^^^^^^^^^^^^^^^^^^
  File "/home/ec2-user/test_form/.venv/lib64/python3.12/site-packages/sqlalchemy/engine/base.py", line 1983, in _exec_single_context
    self._handle_dbapi_exception(
  File "/home/ec2-user/test_form/.venv/lib64/python3.12/site-packages/sqlalchemy/engine/base.py", line 2352, in _handle_dbapi_exception
    raise sqlalchemy_exception.with_traceback(exc_info[2]) from e
  File "/home/ec2-user/test_form/.venv/lib64/python3.12/site-packages/sqlalchemy/engine/base.py", line 1964, in _exec_single_context
    self.dialect.do_execute(
  File "/home/ec2-user/test_form/.venv/lib64/python3.12/site-packages/sqlalchemy/engine/default.py", line 942, in do_execute
    cursor.execute(statement, parameters)
  File "/home/ec2-user/test_form/.venv/lib64/python3.12/site-packages/pymysql/cursors.py", line 153, in execute
    result = self._query(query)
             ^^^^^^^^^^^^^^^^^^
  File "/home/ec2-user/test_form/.venv/lib64/python3.12/site-packages/pymysql/cursors.py", line 322, in _query
    conn.query(q)
  File "/home/ec2-user/test_form/.venv/lib64/python3.12/site-packages/pymysql/connections.py", line 563, in query
    self._affected_rows = self._read_query_result(unbuffered=unbuffered)
                          ^^^^^^^^^^^^^^^^^^^^^^^^^^^^^^^^^^^^^^^^^^^^^^
  File "/home/ec2-user/test_form/.venv/lib64/python3.12/site-packages/pymysql/connections.py", line 825, in _read_query_result
    result.read()
  File "/home/ec2-user/test_form/.venv/lib64/python3.12/site-packages/pymysql/connections.py", line 1199, in read
    first_packet = self.connection._read_packet()
                   ^^^^^^^^^^^^^^^^^^^^^^^^^^^^^^
  File "/home/ec2-user/test_form/.venv/lib64/python3.12/site-packages/pymysql/connections.py", line 775, in _read_packet
    packet.raise_for_error()
  File "/home/ec2-user/test_form/.venv/lib64/python3.12/site-packages/pymysql/protocol.py", line 219, in raise_for_error
    err.raise_mysql_exception(self._data)
  File "/home/ec2-user/test_form/.venv/lib64/python3.12/site-packages/pymysql/err.py", line 150, in raise_mysql_exception
    raise errorclass(errno, errval)
sqlalchemy.exc.IntegrityError: (pymysql.err.IntegrityError) (1062, "Duplicate entry 'adnjasi123@csokm.com' for key 'users.email'")
[SQL: INSERT INTO users (name, age, gender, email, created_at, updated_at) VALUES (%(name)s, %(age)s, %(gender)s, %(email)s, %(created_at)s, %(updated_at)s)]
[parameters: {'name': '헬th췍 요정', 'age': 'teen', 'gender': 'male', 'email': 'adnjasi123@csokm.com', 'created_at': datetime.datetime(2025, 1, 13, 13, 10, 15, 233626, tzinfo=zoneinfo.ZoneInfo(key='Asia/Seoul')), 'updated_at': datetime.datetime(2025, 1, 13, 13, 10, 15, 233633, tzinfo=zoneinfo.ZoneInfo(key='Asia/Seoul'))}]
(Background on this error at: https://sqlalche.me/e/20/gkpj)
[2025-01-13 04:10:23,265] ERROR in app: Exception on /questions/1 [GET]
Traceback (most recent call last):
  File "/home/ec2-user/test_form/.venv/lib64/python3.12/site-packages/flask/app.py", line 1511, in wsgi_app
    response = self.full_dispatch_request()
               ^^^^^^^^^^^^^^^^^^^^^^^^^^^^
  File "/home/ec2-user/test_form/.venv/lib64/python3.12/site-packages/flask/app.py", line 919, in full_dispatch_request
    rv = self.handle_user_exception(e)
         ^^^^^^^^^^^^^^^^^^^^^^^^^^^^^
  File "/home/ec2-user/test_form/.venv/lib64/python3.12/site-packages/flask/app.py", line 917, in full_dispatch_request
    rv = self.dispatch_request()
         ^^^^^^^^^^^^^^^^^^^^^^^
  File "/home/ec2-user/test_form/.venv/lib64/python3.12/site-packages/flask/app.py", line 902, in dispatch_request
    return self.ensure_sync(self.view_functions[rule.endpoint])(**view_args)  # type: ignore[no-any-return]
           ^^^^^^^^^^^^^^^^^^^^^^^^^^^^^^^^^^^^^^^^^^^^^^^^^^^^^^^^^^^^^^^^^
TypeError: question_page() got an unexpected keyword argument 'questions_id'
[2025-01-13 04:18:18 +0000] [201559] [INFO] Starting gunicorn 23.0.0
[2025-01-13 04:18:18 +0000] [201559] [ERROR] Connection in use: ('127.0.0.1', 8000)
[2025-01-13 04:18:18 +0000] [201559] [ERROR] connection to ('127.0.0.1', 8000) failed: [Errno 98] Address already in use
[2025-01-13 04:18:19 +0000] [201559] [ERROR] Connection in use: ('127.0.0.1', 8000)
[2025-01-13 04:18:19 +0000] [201559] [ERROR] connection to ('127.0.0.1', 8000) failed: [Errno 98] Address already in use
[2025-01-13 04:18:20 +0000] [201559] [ERROR] Connection in use: ('127.0.0.1', 8000)
[2025-01-13 04:18:20 +0000] [201559] [ERROR] connection to ('127.0.0.1', 8000) failed: [Errno 98] Address already in use
[2025-01-13 04:18:21 +0000] [201559] [ERROR] Connection in use: ('127.0.0.1', 8000)
[2025-01-13 04:18:21 +0000] [201559] [ERROR] connection to ('127.0.0.1', 8000) failed: [Errno 98] Address already in use
[2025-01-13 04:18:22 +0000] [201559] [ERROR] Connection in use: ('127.0.0.1', 8000)
[2025-01-13 04:18:22 +0000] [201559] [ERROR] connection to ('127.0.0.1', 8000) failed: [Errno 98] Address already in use
[2025-01-13 04:18:23 +0000] [201559] [ERROR] Can't connect to ('127.0.0.1', 8000)
[2025-01-13 04:18:26,905] ERROR in app: Exception on /questions/1 [GET]
Traceback (most recent call last):
  File "/home/ec2-user/test_form/.venv/lib64/python3.12/site-packages/flask/app.py", line 1511, in wsgi_app
    response = self.full_dispatch_request()
               ^^^^^^^^^^^^^^^^^^^^^^^^^^^^
  File "/home/ec2-user/test_form/.venv/lib64/python3.12/site-packages/flask/app.py", line 919, in full_dispatch_request
    rv = self.handle_user_exception(e)
         ^^^^^^^^^^^^^^^^^^^^^^^^^^^^^
  File "/home/ec2-user/test_form/.venv/lib64/python3.12/site-packages/flask/app.py", line 917, in full_dispatch_request
    rv = self.dispatch_request()
         ^^^^^^^^^^^^^^^^^^^^^^^
  File "/home/ec2-user/test_form/.venv/lib64/python3.12/site-packages/flask/app.py", line 902, in dispatch_request
    return self.ensure_sync(self.view_functions[rule.endpoint])(**view_args)  # type: ignore[no-any-return]
           ^^^^^^^^^^^^^^^^^^^^^^^^^^^^^^^^^^^^^^^^^^^^^^^^^^^^^^^^^^^^^^^^^
TypeError: question_page() got an unexpected keyword argument 'questions_id'
[2025-01-13 04:23:29,930] ERROR in app: Exception on /questions/1 [POST]
Traceback (most recent call last):
  File "/home/ec2-user/test_form/.venv/lib64/python3.12/site-packages/flask/app.py", line 1511, in wsgi_app
    response = self.full_dispatch_request()
               ^^^^^^^^^^^^^^^^^^^^^^^^^^^^
  File "/home/ec2-user/test_form/.venv/lib64/python3.12/site-packages/flask/app.py", line 919, in full_dispatch_request
    rv = self.handle_user_exception(e)
         ^^^^^^^^^^^^^^^^^^^^^^^^^^^^^
  File "/home/ec2-user/test_form/.venv/lib64/python3.12/site-packages/flask/app.py", line 917, in full_dispatch_request
    rv = self.dispatch_request()
         ^^^^^^^^^^^^^^^^^^^^^^^
  File "/home/ec2-user/test_form/.venv/lib64/python3.12/site-packages/flask/app.py", line 902, in dispatch_request
    return self.ensure_sync(self.view_functions[rule.endpoint])(**view_args)  # type: ignore[no-any-return]
           ^^^^^^^^^^^^^^^^^^^^^^^^^^^^^^^^^^^^^^^^^^^^^^^^^^^^^^^^^^^^^^^^^
TypeError: question_page() got an unexpected keyword argument 'questions_id'
[2025-01-13 04:25:29,496] ERROR in app: Exception on /questions/1 [POST]
Traceback (most recent call last):
  File "/home/ec2-user/test_form/.venv/lib64/python3.12/site-packages/flask/app.py", line 1511, in wsgi_app
    response = self.full_dispatch_request()
               ^^^^^^^^^^^^^^^^^^^^^^^^^^^^
  File "/home/ec2-user/test_form/.venv/lib64/python3.12/site-packages/flask/app.py", line 919, in full_dispatch_request
    rv = self.handle_user_exception(e)
         ^^^^^^^^^^^^^^^^^^^^^^^^^^^^^
  File "/home/ec2-user/test_form/.venv/lib64/python3.12/site-packages/flask/app.py", line 917, in full_dispatch_request
    rv = self.dispatch_request()
         ^^^^^^^^^^^^^^^^^^^^^^^
  File "/home/ec2-user/test_form/.venv/lib64/python3.12/site-packages/flask/app.py", line 902, in dispatch_request
    return self.ensure_sync(self.view_functions[rule.endpoint])(**view_args)  # type: ignore[no-any-return]
           ^^^^^^^^^^^^^^^^^^^^^^^^^^^^^^^^^^^^^^^^^^^^^^^^^^^^^^^^^^^^^^^^^
TypeError: question_page() got an unexpected keyword argument 'questions_id'
[2025-01-13 04:29:44 +0000] [199474] [INFO] Handling signal: term
[2025-01-13 04:29:44 +0000] [199476] [INFO] Worker exiting (pid: 199476)
[2025-01-13 04:29:44 +0000] [199479] [INFO] Worker exiting (pid: 199479)
[2025-01-13 04:29:44 +0000] [199480] [INFO] Worker exiting (pid: 199480)
[2025-01-13 04:29:44 +0000] [199482] [INFO] Worker exiting (pid: 199482)
[2025-01-13 04:29:44 +0000] [199474] [ERROR] Worker (pid:199476) was sent SIGTERM!
[2025-01-13 04:29:44 +0000] [199474] [ERROR] Worker (pid:199479) was sent SIGTERM!
[2025-01-13 04:29:45 +0000] [199474] [ERROR] Worker (pid:199480) was sent SIGTERM!
[2025-01-13 04:29:45 +0000] [199474] [INFO] Shutting down: Master
[2025-01-13 04:29:49 +0000] [203202] [INFO] Starting gunicorn 23.0.0
[2025-01-13 04:29:49 +0000] [203202] [INFO] Listening at: http://127.0.0.1:8000 (203202)
[2025-01-13 04:29:49 +0000] [203202] [INFO] Using worker: sync
[2025-01-13 04:29:49 +0000] [203204] [INFO] Booting worker with pid: 203204
[2025-01-13 04:29:50 +0000] [203207] [INFO] Booting worker with pid: 203207
[2025-01-13 04:29:50 +0000] [203208] [INFO] Booting worker with pid: 203208
[2025-01-13 04:29:50 +0000] [203209] [INFO] Booting worker with pid: 203209
[2025-01-13 04:31:09 +0000] [203202] [INFO] Handling signal: term
[2025-01-13 04:31:09 +0000] [203204] [INFO] Worker exiting (pid: 203204)
[2025-01-13 04:31:09 +0000] [203207] [INFO] Worker exiting (pid: 203207)
[2025-01-13 04:31:09 +0000] [203208] [INFO] Worker exiting (pid: 203208)
[2025-01-13 04:31:09 +0000] [203209] [INFO] Worker exiting (pid: 203209)
[2025-01-13 04:31:09 +0000] [203202] [ERROR] Worker (pid:203204) was sent SIGTERM!
[2025-01-13 04:31:09 +0000] [203202] [ERROR] Worker (pid:203207) was sent SIGTERM!
[2025-01-13 04:31:10 +0000] [203202] [ERROR] Worker (pid:203208) was sent SIGTERM!
[2025-01-13 04:31:10 +0000] [203202] [INFO] Shutting down: Master
[2025-01-13 04:31:17 +0000] [204103] [INFO] Starting gunicorn 23.0.0
[2025-01-13 04:31:17 +0000] [204103] [INFO] Listening at: http://127.0.0.1:8000 (204103)
[2025-01-13 04:31:17 +0000] [204103] [INFO] Using worker: sync
[2025-01-13 04:31:18 +0000] [204105] [INFO] Booting worker with pid: 204105
[2025-01-13 04:31:18 +0000] [204108] [INFO] Booting worker with pid: 204108
[2025-01-13 04:31:18 +0000] [204109] [INFO] Booting worker with pid: 204109
[2025-01-13 04:31:18 +0000] [204110] [INFO] Booting worker with pid: 204110
[2025-01-13 05:14:13 +0000] [204103] [INFO] Handling signal: term
[2025-01-13 05:14:13 +0000] [204105] [INFO] Worker exiting (pid: 204105)
[2025-01-13 05:14:13 +0000] [204108] [INFO] Worker exiting (pid: 204108)
[2025-01-13 05:14:13 +0000] [204109] [INFO] Worker exiting (pid: 204109)
[2025-01-13 05:14:13 +0000] [204110] [INFO] Worker exiting (pid: 204110)
[2025-01-13 05:14:14 +0000] [204103] [ERROR] Worker (pid:204105) was sent SIGTERM!
[2025-01-13 05:14:14 +0000] [204103] [ERROR] Worker (pid:204108) was sent SIGTERM!
[2025-01-13 05:14:14 +0000] [204103] [ERROR] Worker (pid:204109) was sent SIGTERM!
[2025-01-13 05:14:14 +0000] [204103] [INFO] Shutting down: Master
[2025-01-13 05:14:19 +0000] [207573] [INFO] Starting gunicorn 23.0.0
[2025-01-13 05:14:19 +0000] [207573] [INFO] Listening at: http://127.0.0.1:8000 (207573)
[2025-01-13 05:14:19 +0000] [207573] [INFO] Using worker: sync
[2025-01-13 05:14:19 +0000] [207574] [INFO] Booting worker with pid: 207574
[2025-01-13 05:14:19 +0000] [207576] [INFO] Booting worker with pid: 207576
[2025-01-13 05:14:19 +0000] [207578] [INFO] Booting worker with pid: 207578
[2025-01-13 05:14:19 +0000] [207579] [INFO] Booting worker with pid: 207579
[2025-01-13 05:24:27 +0000] [207573] [INFO] Handling signal: term
[2025-01-13 05:24:27 +0000] [207574] [INFO] Worker exiting (pid: 207574)
[2025-01-13 05:24:27 +0000] [207576] [INFO] Worker exiting (pid: 207576)
[2025-01-13 05:24:27 +0000] [207578] [INFO] Worker exiting (pid: 207578)
[2025-01-13 05:24:27 +0000] [207579] [INFO] Worker exiting (pid: 207579)
[2025-01-13 05:24:27 +0000] [207573] [ERROR] Worker (pid:207574) was sent SIGTERM!
[2025-01-13 05:24:28 +0000] [207573] [ERROR] Worker (pid:207576) was sent SIGTERM!
[2025-01-13 05:24:28 +0000] [207573] [ERROR] Worker (pid:207578) was sent SIGTERM!
[2025-01-13 05:24:28 +0000] [207573] [INFO] Shutting down: Master
[2025-01-13 05:24:31 +0000] [212810] [INFO] Starting gunicorn 23.0.0
[2025-01-13 05:24:31 +0000] [212810] [INFO] Listening at: http://127.0.0.1:8000 (212810)
[2025-01-13 05:24:31 +0000] [212810] [INFO] Using worker: sync
[2025-01-13 05:24:31 +0000] [212811] [INFO] Booting worker with pid: 212811
[2025-01-13 05:24:31 +0000] [212812] [INFO] Booting worker with pid: 212812
[2025-01-13 05:24:31 +0000] [212813] [INFO] Booting worker with pid: 212813
[2025-01-13 05:24:31 +0000] [212815] [INFO] Booting worker with pid: 212815
[2025-01-13 05:30:28 +0000] [212810] [INFO] Handling signal: term
[2025-01-13 05:30:28 +0000] [212811] [INFO] Worker exiting (pid: 212811)
[2025-01-13 05:30:28 +0000] [212812] [INFO] Worker exiting (pid: 212812)
[2025-01-13 05:30:28 +0000] [212813] [INFO] Worker exiting (pid: 212813)
[2025-01-13 05:30:28 +0000] [212815] [INFO] Worker exiting (pid: 212815)
[2025-01-13 05:30:29 +0000] [212810] [ERROR] Worker (pid:212811) was sent SIGTERM!
[2025-01-13 05:30:29 +0000] [212810] [ERROR] Worker (pid:212812) was sent SIGTERM!
[2025-01-13 05:30:29 +0000] [212810] [ERROR] Worker (pid:212813) was sent SIGTERM!
[2025-01-13 05:30:29 +0000] [212810] [INFO] Shutting down: Master
[2025-01-13 05:30:37 +0000] [213458] [INFO] Starting gunicorn 23.0.0
[2025-01-13 05:30:37 +0000] [213458] [INFO] Listening at: http://127.0.0.1:8000 (213458)
[2025-01-13 05:30:37 +0000] [213458] [INFO] Using worker: sync
[2025-01-13 05:30:37 +0000] [213460] [INFO] Booting worker with pid: 213460
[2025-01-13 05:30:37 +0000] [213462] [INFO] Booting worker with pid: 213462
[2025-01-13 05:30:37 +0000] [213464] [INFO] Booting worker with pid: 213464
[2025-01-13 05:30:37 +0000] [213465] [INFO] Booting worker with pid: 213465
[2025-01-13 05:33:55 +0000] [213458] [INFO] Handling signal: term
[2025-01-13 05:33:55 +0000] [213460] [INFO] Worker exiting (pid: 213460)
[2025-01-13 05:33:55 +0000] [213462] [INFO] Worker exiting (pid: 213462)
[2025-01-13 05:33:55 +0000] [213464] [INFO] Worker exiting (pid: 213464)
[2025-01-13 05:33:55 +0000] [213465] [INFO] Worker exiting (pid: 213465)
[2025-01-13 05:33:55 +0000] [213458] [ERROR] Worker (pid:213460) was sent SIGTERM!
[2025-01-13 05:33:55 +0000] [213458] [ERROR] Worker (pid:213462) was sent SIGTERM!
[2025-01-13 05:33:55 +0000] [213458] [ERROR] Worker (pid:213464) was sent SIGTERM!
[2025-01-13 05:33:56 +0000] [213458] [INFO] Shutting down: Master
[2025-01-13 05:33:57 +0000] [213793] [INFO] Starting gunicorn 23.0.0
[2025-01-13 05:33:57 +0000] [213793] [INFO] Listening at: http://127.0.0.1:8000 (213793)
[2025-01-13 05:33:57 +0000] [213793] [INFO] Using worker: sync
[2025-01-13 05:33:57 +0000] [213795] [INFO] Booting worker with pid: 213795
[2025-01-13 05:33:58 +0000] [213798] [INFO] Booting worker with pid: 213798
[2025-01-13 05:33:58 +0000] [213799] [INFO] Booting worker with pid: 213799
[2025-01-13 05:33:58 +0000] [213800] [INFO] Booting worker with pid: 213800
[2025-01-13 05:34:43,006] ERROR in app: Exception on /signup [POST]
Traceback (most recent call last):
  File "/home/ec2-user/test_form/.venv/lib64/python3.12/site-packages/sqlalchemy/engine/base.py", line 1964, in _exec_single_context
    self.dialect.do_execute(
  File "/home/ec2-user/test_form/.venv/lib64/python3.12/site-packages/sqlalchemy/engine/default.py", line 942, in do_execute
    cursor.execute(statement, parameters)
  File "/home/ec2-user/test_form/.venv/lib64/python3.12/site-packages/pymysql/cursors.py", line 153, in execute
    result = self._query(query)
             ^^^^^^^^^^^^^^^^^^
  File "/home/ec2-user/test_form/.venv/lib64/python3.12/site-packages/pymysql/cursors.py", line 322, in _query
    conn.query(q)
  File "/home/ec2-user/test_form/.venv/lib64/python3.12/site-packages/pymysql/connections.py", line 563, in query
    self._affected_rows = self._read_query_result(unbuffered=unbuffered)
                          ^^^^^^^^^^^^^^^^^^^^^^^^^^^^^^^^^^^^^^^^^^^^^^
  File "/home/ec2-user/test_form/.venv/lib64/python3.12/site-packages/pymysql/connections.py", line 825, in _read_query_result
    result.read()
  File "/home/ec2-user/test_form/.venv/lib64/python3.12/site-packages/pymysql/connections.py", line 1199, in read
    first_packet = self.connection._read_packet()
                   ^^^^^^^^^^^^^^^^^^^^^^^^^^^^^^
  File "/home/ec2-user/test_form/.venv/lib64/python3.12/site-packages/pymysql/connections.py", line 775, in _read_packet
    packet.raise_for_error()
  File "/home/ec2-user/test_form/.venv/lib64/python3.12/site-packages/pymysql/protocol.py", line 219, in raise_for_error
    err.raise_mysql_exception(self._data)
  File "/home/ec2-user/test_form/.venv/lib64/python3.12/site-packages/pymysql/err.py", line 150, in raise_mysql_exception
    raise errorclass(errno, errval)
pymysql.err.IntegrityError: (1062, "Duplicate entry 'asd12asd3a@asfd.com' for key 'users.email'")

The above exception was the direct cause of the following exception:

Traceback (most recent call last):
  File "/home/ec2-user/test_form/.venv/lib64/python3.12/site-packages/flask/app.py", line 1511, in wsgi_app
    response = self.full_dispatch_request()
               ^^^^^^^^^^^^^^^^^^^^^^^^^^^^
  File "/home/ec2-user/test_form/.venv/lib64/python3.12/site-packages/flask/app.py", line 919, in full_dispatch_request
    rv = self.handle_user_exception(e)
         ^^^^^^^^^^^^^^^^^^^^^^^^^^^^^
  File "/home/ec2-user/test_form/.venv/lib64/python3.12/site-packages/flask/app.py", line 917, in full_dispatch_request
    rv = self.dispatch_request()
         ^^^^^^^^^^^^^^^^^^^^^^^
  File "/home/ec2-user/test_form/.venv/lib64/python3.12/site-packages/flask/app.py", line 902, in dispatch_request
    return self.ensure_sync(self.view_functions[rule.endpoint])(**view_args)  # type: ignore[no-any-return]
           ^^^^^^^^^^^^^^^^^^^^^^^^^^^^^^^^^^^^^^^^^^^^^^^^^^^^^^^^^^^^^^^^^
  File "/home/ec2-user/test_form/app/routes.py", line 17, in signup_page
    user = users.create_user()
           ^^^^^^^^^^^^^^^^^^^
  File "/home/ec2-user/test_form/app/services/users.py", line 15, in create_user
    db.session.commit()
  File "/home/ec2-user/test_form/.venv/lib64/python3.12/site-packages/sqlalchemy/orm/scoping.py", line 599, in commit
    return self._proxied.commit()
           ^^^^^^^^^^^^^^^^^^^^^^
  File "/home/ec2-user/test_form/.venv/lib64/python3.12/site-packages/sqlalchemy/orm/session.py", line 2032, in commit
    trans.commit(_to_root=True)
  File "<string>", line 2, in commit
  File "/home/ec2-user/test_form/.venv/lib64/python3.12/site-packages/sqlalchemy/orm/state_changes.py", line 139, in _go
    ret_value = fn(self, *arg, **kw)
                ^^^^^^^^^^^^^^^^^^^^
  File "/home/ec2-user/test_form/.venv/lib64/python3.12/site-packages/sqlalchemy/orm/session.py", line 1313, in commit
    self._prepare_impl()
  File "<string>", line 2, in _prepare_impl
  File "/home/ec2-user/test_form/.venv/lib64/python3.12/site-packages/sqlalchemy/orm/state_changes.py", line 139, in _go
    ret_value = fn(self, *arg, **kw)
                ^^^^^^^^^^^^^^^^^^^^
  File "/home/ec2-user/test_form/.venv/lib64/python3.12/site-packages/sqlalchemy/orm/session.py", line 1288, in _prepare_impl
    self.session.flush()
  File "/home/ec2-user/test_form/.venv/lib64/python3.12/site-packages/sqlalchemy/orm/session.py", line 4353, in flush
    self._flush(objects)
  File "/home/ec2-user/test_form/.venv/lib64/python3.12/site-packages/sqlalchemy/orm/session.py", line 4488, in _flush
    with util.safe_reraise():
         ^^^^^^^^^^^^^^^^^^^
  File "/home/ec2-user/test_form/.venv/lib64/python3.12/site-packages/sqlalchemy/util/langhelpers.py", line 146, in __exit__
    raise exc_value.with_traceback(exc_tb)
  File "/home/ec2-user/test_form/.venv/lib64/python3.12/site-packages/sqlalchemy/orm/session.py", line 4449, in _flush
    flush_context.execute()
  File "/home/ec2-user/test_form/.venv/lib64/python3.12/site-packages/sqlalchemy/orm/unitofwork.py", line 466, in execute
    rec.execute(self)
  File "/home/ec2-user/test_form/.venv/lib64/python3.12/site-packages/sqlalchemy/orm/unitofwork.py", line 642, in execute
    util.preloaded.orm_persistence.save_obj(
  File "/home/ec2-user/test_form/.venv/lib64/python3.12/site-packages/sqlalchemy/orm/persistence.py", line 93, in save_obj
    _emit_insert_statements(
  File "/home/ec2-user/test_form/.venv/lib64/python3.12/site-packages/sqlalchemy/orm/persistence.py", line 1233, in _emit_insert_statements
    result = connection.execute(
             ^^^^^^^^^^^^^^^^^^^
  File "/home/ec2-user/test_form/.venv/lib64/python3.12/site-packages/sqlalchemy/engine/base.py", line 1416, in execute
    return meth(
           ^^^^^
  File "/home/ec2-user/test_form/.venv/lib64/python3.12/site-packages/sqlalchemy/sql/elements.py", line 515, in _execute_on_connection
    return connection._execute_clauseelement(
           ^^^^^^^^^^^^^^^^^^^^^^^^^^^^^^^^^^
  File "/home/ec2-user/test_form/.venv/lib64/python3.12/site-packages/sqlalchemy/engine/base.py", line 1638, in _execute_clauseelement
    ret = self._execute_context(
          ^^^^^^^^^^^^^^^^^^^^^^
  File "/home/ec2-user/test_form/.venv/lib64/python3.12/site-packages/sqlalchemy/engine/base.py", line 1843, in _execute_context
    return self._exec_single_context(
           ^^^^^^^^^^^^^^^^^^^^^^^^^^
  File "/home/ec2-user/test_form/.venv/lib64/python3.12/site-packages/sqlalchemy/engine/base.py", line 1983, in _exec_single_context
    self._handle_dbapi_exception(
  File "/home/ec2-user/test_form/.venv/lib64/python3.12/site-packages/sqlalchemy/engine/base.py", line 2352, in _handle_dbapi_exception
    raise sqlalchemy_exception.with_traceback(exc_info[2]) from e
  File "/home/ec2-user/test_form/.venv/lib64/python3.12/site-packages/sqlalchemy/engine/base.py", line 1964, in _exec_single_context
    self.dialect.do_execute(
  File "/home/ec2-user/test_form/.venv/lib64/python3.12/site-packages/sqlalchemy/engine/default.py", line 942, in do_execute
    cursor.execute(statement, parameters)
  File "/home/ec2-user/test_form/.venv/lib64/python3.12/site-packages/pymysql/cursors.py", line 153, in execute
    result = self._query(query)
             ^^^^^^^^^^^^^^^^^^
  File "/home/ec2-user/test_form/.venv/lib64/python3.12/site-packages/pymysql/cursors.py", line 322, in _query
    conn.query(q)
  File "/home/ec2-user/test_form/.venv/lib64/python3.12/site-packages/pymysql/connections.py", line 563, in query
    self._affected_rows = self._read_query_result(unbuffered=unbuffered)
                          ^^^^^^^^^^^^^^^^^^^^^^^^^^^^^^^^^^^^^^^^^^^^^^
  File "/home/ec2-user/test_form/.venv/lib64/python3.12/site-packages/pymysql/connections.py", line 825, in _read_query_result
    result.read()
  File "/home/ec2-user/test_form/.venv/lib64/python3.12/site-packages/pymysql/connections.py", line 1199, in read
    first_packet = self.connection._read_packet()
                   ^^^^^^^^^^^^^^^^^^^^^^^^^^^^^^
  File "/home/ec2-user/test_form/.venv/lib64/python3.12/site-packages/pymysql/connections.py", line 775, in _read_packet
    packet.raise_for_error()
  File "/home/ec2-user/test_form/.venv/lib64/python3.12/site-packages/pymysql/protocol.py", line 219, in raise_for_error
    err.raise_mysql_exception(self._data)
  File "/home/ec2-user/test_form/.venv/lib64/python3.12/site-packages/pymysql/err.py", line 150, in raise_mysql_exception
    raise errorclass(errno, errval)
sqlalchemy.exc.IntegrityError: (pymysql.err.IntegrityError) (1062, "Duplicate entry 'asd12asd3a@asfd.com' for key 'users.email'")
[SQL: INSERT INTO users (name, age, gender, email, created_at, updated_at) VALUES (%(name)s, %(age)s, %(gender)s, %(email)s, %(created_at)s, %(updated_at)s)]
[parameters: {'name': '헬th췍 요정', 'age': 'teen', 'gender': 'male', 'email': 'asd12asd3a@asfd.com', 'created_at': datetime.datetime(2025, 1, 13, 14, 34, 43, 3162, tzinfo=zoneinfo.ZoneInfo(key='Asia/Seoul')), 'updated_at': datetime.datetime(2025, 1, 13, 14, 34, 43, 3168, tzinfo=zoneinfo.ZoneInfo(key='Asia/Seoul'))}]
(Background on this error at: https://sqlalche.me/e/20/gkpj)
[2025-01-13 05:51:00 +0000] [213793] [INFO] Handling signal: term
[2025-01-13 05:51:00 +0000] [213795] [INFO] Worker exiting (pid: 213795)
[2025-01-13 05:51:00 +0000] [213798] [INFO] Worker exiting (pid: 213798)
[2025-01-13 05:51:00 +0000] [213799] [INFO] Worker exiting (pid: 213799)
[2025-01-13 05:51:00 +0000] [213800] [INFO] Worker exiting (pid: 213800)
[2025-01-13 05:51:01 +0000] [213793] [ERROR] Worker (pid:213795) was sent SIGTERM!
[2025-01-13 05:51:01 +0000] [213793] [ERROR] Worker (pid:213798) was sent SIGTERM!
[2025-01-13 05:51:01 +0000] [213793] [ERROR] Worker (pid:213799) was sent SIGTERM!
[2025-01-13 05:51:01 +0000] [213793] [INFO] Shutting down: Master
[2025-01-13 05:51:04 +0000] [214826] [INFO] Starting gunicorn 23.0.0
[2025-01-13 05:51:04 +0000] [214826] [INFO] Listening at: http://127.0.0.1:8000 (214826)
[2025-01-13 05:51:04 +0000] [214826] [INFO] Using worker: sync
[2025-01-13 05:51:04 +0000] [214828] [INFO] Booting worker with pid: 214828
[2025-01-13 05:51:04 +0000] [214831] [INFO] Booting worker with pid: 214831
[2025-01-13 05:51:04 +0000] [214832] [INFO] Booting worker with pid: 214832
[2025-01-13 05:51:04 +0000] [214833] [INFO] Booting worker with pid: 214833
[2025-01-13 05:52:46 +0000] [214826] [INFO] Handling signal: term
[2025-01-13 05:52:46 +0000] [214828] [INFO] Worker exiting (pid: 214828)
[2025-01-13 05:52:46 +0000] [214831] [INFO] Worker exiting (pid: 214831)
[2025-01-13 05:52:46 +0000] [214832] [INFO] Worker exiting (pid: 214832)
[2025-01-13 05:52:46 +0000] [214833] [INFO] Worker exiting (pid: 214833)
[2025-01-13 05:52:47 +0000] [214826] [ERROR] Worker (pid:214828) was sent SIGTERM!
[2025-01-13 05:52:47 +0000] [214826] [ERROR] Worker (pid:214831) was sent SIGTERM!
[2025-01-13 05:52:47 +0000] [214826] [ERROR] Worker (pid:214832) was sent SIGTERM!
[2025-01-13 05:52:47 +0000] [214826] [INFO] Shutting down: Master
[2025-01-13 05:52:53 +0000] [215218] [INFO] Starting gunicorn 23.0.0
[2025-01-13 05:52:53 +0000] [215218] [INFO] Listening at: http://127.0.0.1:8000 (215218)
[2025-01-13 05:52:53 +0000] [215218] [INFO] Using worker: sync
[2025-01-13 05:52:53 +0000] [215220] [INFO] Booting worker with pid: 215220
[2025-01-13 05:52:53 +0000] [215222] [INFO] Booting worker with pid: 215222
[2025-01-13 05:52:53 +0000] [215224] [INFO] Booting worker with pid: 215224
[2025-01-13 05:52:53 +0000] [215225] [INFO] Booting worker with pid: 215225
[2025-01-13 05:52:56,220] ERROR in app: Exception on /signup [POST]
Traceback (most recent call last):
  File "/home/ec2-user/test_form/.venv/lib64/python3.12/site-packages/sqlalchemy/engine/base.py", line 1964, in _exec_single_context
    self.dialect.do_execute(
  File "/home/ec2-user/test_form/.venv/lib64/python3.12/site-packages/sqlalchemy/engine/default.py", line 942, in do_execute
    cursor.execute(statement, parameters)
  File "/home/ec2-user/test_form/.venv/lib64/python3.12/site-packages/pymysql/cursors.py", line 153, in execute
    result = self._query(query)
             ^^^^^^^^^^^^^^^^^^
  File "/home/ec2-user/test_form/.venv/lib64/python3.12/site-packages/pymysql/cursors.py", line 322, in _query
    conn.query(q)
  File "/home/ec2-user/test_form/.venv/lib64/python3.12/site-packages/pymysql/connections.py", line 563, in query
    self._affected_rows = self._read_query_result(unbuffered=unbuffered)
                          ^^^^^^^^^^^^^^^^^^^^^^^^^^^^^^^^^^^^^^^^^^^^^^
  File "/home/ec2-user/test_form/.venv/lib64/python3.12/site-packages/pymysql/connections.py", line 825, in _read_query_result
    result.read()
  File "/home/ec2-user/test_form/.venv/lib64/python3.12/site-packages/pymysql/connections.py", line 1199, in read
    first_packet = self.connection._read_packet()
                   ^^^^^^^^^^^^^^^^^^^^^^^^^^^^^^
  File "/home/ec2-user/test_form/.venv/lib64/python3.12/site-packages/pymysql/connections.py", line 775, in _read_packet
    packet.raise_for_error()
  File "/home/ec2-user/test_form/.venv/lib64/python3.12/site-packages/pymysql/protocol.py", line 219, in raise_for_error
    err.raise_mysql_exception(self._data)
  File "/home/ec2-user/test_form/.venv/lib64/python3.12/site-packages/pymysql/err.py", line 150, in raise_mysql_exception
    raise errorclass(errno, errval)
pymysql.err.IntegrityError: (1062, "Duplicate entry 'adndsfsdjasi123@csokm.com' for key 'users.email'")

The above exception was the direct cause of the following exception:

Traceback (most recent call last):
  File "/home/ec2-user/test_form/.venv/lib64/python3.12/site-packages/flask/app.py", line 1511, in wsgi_app
    response = self.full_dispatch_request()
               ^^^^^^^^^^^^^^^^^^^^^^^^^^^^
  File "/home/ec2-user/test_form/.venv/lib64/python3.12/site-packages/flask/app.py", line 919, in full_dispatch_request
    rv = self.handle_user_exception(e)
         ^^^^^^^^^^^^^^^^^^^^^^^^^^^^^
  File "/home/ec2-user/test_form/.venv/lib64/python3.12/site-packages/flask/app.py", line 917, in full_dispatch_request
    rv = self.dispatch_request()
         ^^^^^^^^^^^^^^^^^^^^^^^
  File "/home/ec2-user/test_form/.venv/lib64/python3.12/site-packages/flask/app.py", line 902, in dispatch_request
    return self.ensure_sync(self.view_functions[rule.endpoint])(**view_args)  # type: ignore[no-any-return]
           ^^^^^^^^^^^^^^^^^^^^^^^^^^^^^^^^^^^^^^^^^^^^^^^^^^^^^^^^^^^^^^^^^
  File "/home/ec2-user/test_form/app/routes.py", line 17, in signup_page
    user = users.create_user()
           ^^^^^^^^^^^^^^^^^^^
  File "/home/ec2-user/test_form/app/services/users.py", line 15, in create_user
    db.session.commit()
  File "/home/ec2-user/test_form/.venv/lib64/python3.12/site-packages/sqlalchemy/orm/scoping.py", line 599, in commit
    return self._proxied.commit()
           ^^^^^^^^^^^^^^^^^^^^^^
  File "/home/ec2-user/test_form/.venv/lib64/python3.12/site-packages/sqlalchemy/orm/session.py", line 2032, in commit
    trans.commit(_to_root=True)
  File "<string>", line 2, in commit
  File "/home/ec2-user/test_form/.venv/lib64/python3.12/site-packages/sqlalchemy/orm/state_changes.py", line 139, in _go
    ret_value = fn(self, *arg, **kw)
                ^^^^^^^^^^^^^^^^^^^^
  File "/home/ec2-user/test_form/.venv/lib64/python3.12/site-packages/sqlalchemy/orm/session.py", line 1313, in commit
    self._prepare_impl()
  File "<string>", line 2, in _prepare_impl
  File "/home/ec2-user/test_form/.venv/lib64/python3.12/site-packages/sqlalchemy/orm/state_changes.py", line 139, in _go
    ret_value = fn(self, *arg, **kw)
                ^^^^^^^^^^^^^^^^^^^^
  File "/home/ec2-user/test_form/.venv/lib64/python3.12/site-packages/sqlalchemy/orm/session.py", line 1288, in _prepare_impl
    self.session.flush()
  File "/home/ec2-user/test_form/.venv/lib64/python3.12/site-packages/sqlalchemy/orm/session.py", line 4353, in flush
    self._flush(objects)
  File "/home/ec2-user/test_form/.venv/lib64/python3.12/site-packages/sqlalchemy/orm/session.py", line 4488, in _flush
    with util.safe_reraise():
         ^^^^^^^^^^^^^^^^^^^
  File "/home/ec2-user/test_form/.venv/lib64/python3.12/site-packages/sqlalchemy/util/langhelpers.py", line 146, in __exit__
    raise exc_value.with_traceback(exc_tb)
  File "/home/ec2-user/test_form/.venv/lib64/python3.12/site-packages/sqlalchemy/orm/session.py", line 4449, in _flush
    flush_context.execute()
  File "/home/ec2-user/test_form/.venv/lib64/python3.12/site-packages/sqlalchemy/orm/unitofwork.py", line 466, in execute
    rec.execute(self)
  File "/home/ec2-user/test_form/.venv/lib64/python3.12/site-packages/sqlalchemy/orm/unitofwork.py", line 642, in execute
    util.preloaded.orm_persistence.save_obj(
  File "/home/ec2-user/test_form/.venv/lib64/python3.12/site-packages/sqlalchemy/orm/persistence.py", line 93, in save_obj
    _emit_insert_statements(
  File "/home/ec2-user/test_form/.venv/lib64/python3.12/site-packages/sqlalchemy/orm/persistence.py", line 1233, in _emit_insert_statements
    result = connection.execute(
             ^^^^^^^^^^^^^^^^^^^
  File "/home/ec2-user/test_form/.venv/lib64/python3.12/site-packages/sqlalchemy/engine/base.py", line 1416, in execute
    return meth(
           ^^^^^
  File "/home/ec2-user/test_form/.venv/lib64/python3.12/site-packages/sqlalchemy/sql/elements.py", line 515, in _execute_on_connection
    return connection._execute_clauseelement(
           ^^^^^^^^^^^^^^^^^^^^^^^^^^^^^^^^^^
  File "/home/ec2-user/test_form/.venv/lib64/python3.12/site-packages/sqlalchemy/engine/base.py", line 1638, in _execute_clauseelement
    ret = self._execute_context(
          ^^^^^^^^^^^^^^^^^^^^^^
  File "/home/ec2-user/test_form/.venv/lib64/python3.12/site-packages/sqlalchemy/engine/base.py", line 1843, in _execute_context
    return self._exec_single_context(
           ^^^^^^^^^^^^^^^^^^^^^^^^^^
  File "/home/ec2-user/test_form/.venv/lib64/python3.12/site-packages/sqlalchemy/engine/base.py", line 1983, in _exec_single_context
    self._handle_dbapi_exception(
  File "/home/ec2-user/test_form/.venv/lib64/python3.12/site-packages/sqlalchemy/engine/base.py", line 2352, in _handle_dbapi_exception
    raise sqlalchemy_exception.with_traceback(exc_info[2]) from e
  File "/home/ec2-user/test_form/.venv/lib64/python3.12/site-packages/sqlalchemy/engine/base.py", line 1964, in _exec_single_context
    self.dialect.do_execute(
  File "/home/ec2-user/test_form/.venv/lib64/python3.12/site-packages/sqlalchemy/engine/default.py", line 942, in do_execute
    cursor.execute(statement, parameters)
  File "/home/ec2-user/test_form/.venv/lib64/python3.12/site-packages/pymysql/cursors.py", line 153, in execute
    result = self._query(query)
             ^^^^^^^^^^^^^^^^^^
  File "/home/ec2-user/test_form/.venv/lib64/python3.12/site-packages/pymysql/cursors.py", line 322, in _query
    conn.query(q)
  File "/home/ec2-user/test_form/.venv/lib64/python3.12/site-packages/pymysql/connections.py", line 563, in query
    self._affected_rows = self._read_query_result(unbuffered=unbuffered)
                          ^^^^^^^^^^^^^^^^^^^^^^^^^^^^^^^^^^^^^^^^^^^^^^
  File "/home/ec2-user/test_form/.venv/lib64/python3.12/site-packages/pymysql/connections.py", line 825, in _read_query_result
    result.read()
  File "/home/ec2-user/test_form/.venv/lib64/python3.12/site-packages/pymysql/connections.py", line 1199, in read
    first_packet = self.connection._read_packet()
                   ^^^^^^^^^^^^^^^^^^^^^^^^^^^^^^
  File "/home/ec2-user/test_form/.venv/lib64/python3.12/site-packages/pymysql/connections.py", line 775, in _read_packet
    packet.raise_for_error()
  File "/home/ec2-user/test_form/.venv/lib64/python3.12/site-packages/pymysql/protocol.py", line 219, in raise_for_error
    err.raise_mysql_exception(self._data)
  File "/home/ec2-user/test_form/.venv/lib64/python3.12/site-packages/pymysql/err.py", line 150, in raise_mysql_exception
    raise errorclass(errno, errval)
sqlalchemy.exc.IntegrityError: (pymysql.err.IntegrityError) (1062, "Duplicate entry 'adndsfsdjasi123@csokm.com' for key 'users.email'")
[SQL: INSERT INTO users (name, age, gender, email, created_at, updated_at) VALUES (%(name)s, %(age)s, %(gender)s, %(email)s, %(created_at)s, %(updated_at)s)]
[parameters: {'name': '도우미', 'age': 'teen', 'gender': 'male', 'email': 'adndsfsdjasi123@csokm.com', 'created_at': datetime.datetime(2025, 1, 13, 14, 52, 56, 216763, tzinfo=zoneinfo.ZoneInfo(key='Asia/Seoul')), 'updated_at': datetime.datetime(2025, 1, 13, 14, 52, 56, 216770, tzinfo=zoneinfo.ZoneInfo(key='Asia/Seoul'))}]
(Background on this error at: https://sqlalche.me/e/20/gkpj)
[2025-01-13 05:53:31,252] ERROR in app: Exception on /signup [POST]
Traceback (most recent call last):
  File "/home/ec2-user/test_form/.venv/lib64/python3.12/site-packages/flask/app.py", line 1511, in wsgi_app
    response = self.full_dispatch_request()
               ^^^^^^^^^^^^^^^^^^^^^^^^^^^^
  File "/home/ec2-user/test_form/.venv/lib64/python3.12/site-packages/flask/app.py", line 919, in full_dispatch_request
    rv = self.handle_user_exception(e)
         ^^^^^^^^^^^^^^^^^^^^^^^^^^^^^
  File "/home/ec2-user/test_form/.venv/lib64/python3.12/site-packages/flask/app.py", line 917, in full_dispatch_request
    rv = self.dispatch_request()
         ^^^^^^^^^^^^^^^^^^^^^^^
  File "/home/ec2-user/test_form/.venv/lib64/python3.12/site-packages/flask/app.py", line 902, in dispatch_request
    return self.ensure_sync(self.view_functions[rule.endpoint])(**view_args)  # type: ignore[no-any-return]
           ^^^^^^^^^^^^^^^^^^^^^^^^^^^^^^^^^^^^^^^^^^^^^^^^^^^^^^^^^^^^^^^^^
  File "/home/ec2-user/test_form/app/routes.py", line 18, in signup_page
    return jsonify({"message": f"{user.name}님 회원가입을 축하합니다"}, user), 201
           ^^^^^^^^^^^^^^^^^^^^^^^^^^^^^^^^^^^^^^^^^^^^^^^^^^^^^^^^^^^^^^^^^^
  File "/home/ec2-user/test_form/.venv/lib64/python3.12/site-packages/flask/json/__init__.py", line 170, in jsonify
    return current_app.json.response(*args, **kwargs)  # type: ignore[return-value]
           ^^^^^^^^^^^^^^^^^^^^^^^^^^^^^^^^^^^^^^^^^^
  File "/home/ec2-user/test_form/.venv/lib64/python3.12/site-packages/flask/json/provider.py", line 214, in response
    f"{self.dumps(obj, **dump_args)}\n", mimetype=self.mimetype
       ^^^^^^^^^^^^^^^^^^^^^^^^^^^^
  File "/home/ec2-user/test_form/.venv/lib64/python3.12/site-packages/flask/json/provider.py", line 179, in dumps
    return json.dumps(obj, **kwargs)
           ^^^^^^^^^^^^^^^^^^^^^^^^^
  File "/usr/lib64/python3.12/json/__init__.py", line 238, in dumps
    **kw).encode(obj)
          ^^^^^^^^^^^
  File "/usr/lib64/python3.12/json/encoder.py", line 200, in encode
    chunks = self.iterencode(o, _one_shot=True)
             ^^^^^^^^^^^^^^^^^^^^^^^^^^^^^^^^^^
  File "/usr/lib64/python3.12/json/encoder.py", line 258, in iterencode
    return _iterencode(o, 0)
           ^^^^^^^^^^^^^^^^^
  File "/home/ec2-user/test_form/.venv/lib64/python3.12/site-packages/flask/json/provider.py", line 121, in _default
    raise TypeError(f"Object of type {type(o).__name__} is not JSON serializable")
TypeError: Object of type User is not JSON serializable
[2025-01-13 05:55:16 +0000] [215218] [INFO] Handling signal: term
[2025-01-13 05:55:16 +0000] [215220] [INFO] Worker exiting (pid: 215220)
[2025-01-13 05:55:16 +0000] [215222] [INFO] Worker exiting (pid: 215222)
[2025-01-13 05:55:16 +0000] [215224] [INFO] Worker exiting (pid: 215224)
[2025-01-13 05:55:16 +0000] [215225] [INFO] Worker exiting (pid: 215225)
[2025-01-13 05:55:16 +0000] [215218] [ERROR] Worker (pid:215220) was sent SIGTERM!
[2025-01-13 05:55:16 +0000] [215218] [ERROR] Worker (pid:215222) was sent SIGTERM!
[2025-01-13 05:55:16 +0000] [215218] [ERROR] Worker (pid:215224) was sent SIGTERM!
[2025-01-13 05:55:17 +0000] [215218] [INFO] Shutting down: Master
[2025-01-13 05:55:21 +0000] [215944] [INFO] Starting gunicorn 23.0.0
[2025-01-13 05:55:21 +0000] [215944] [INFO] Listening at: http://127.0.0.1:8000 (215944)
[2025-01-13 05:55:21 +0000] [215944] [INFO] Using worker: sync
[2025-01-13 05:55:21 +0000] [215946] [INFO] Booting worker with pid: 215946
[2025-01-13 05:55:21 +0000] [215947] [INFO] Booting worker with pid: 215947
[2025-01-13 05:55:21 +0000] [215949] [INFO] Booting worker with pid: 215949
[2025-01-13 05:55:21 +0000] [215948] [INFO] Booting worker with pid: 215948
[2025-01-13 05:55:25,068] ERROR in app: Exception on /signup [POST]
Traceback (most recent call last):
  File "/home/ec2-user/test_form/.venv/lib64/python3.12/site-packages/sqlalchemy/engine/base.py", line 1964, in _exec_single_context
    self.dialect.do_execute(
  File "/home/ec2-user/test_form/.venv/lib64/python3.12/site-packages/sqlalchemy/engine/default.py", line 942, in do_execute
    cursor.execute(statement, parameters)
  File "/home/ec2-user/test_form/.venv/lib64/python3.12/site-packages/pymysql/cursors.py", line 153, in execute
    result = self._query(query)
             ^^^^^^^^^^^^^^^^^^
  File "/home/ec2-user/test_form/.venv/lib64/python3.12/site-packages/pymysql/cursors.py", line 322, in _query
    conn.query(q)
  File "/home/ec2-user/test_form/.venv/lib64/python3.12/site-packages/pymysql/connections.py", line 563, in query
    self._affected_rows = self._read_query_result(unbuffered=unbuffered)
                          ^^^^^^^^^^^^^^^^^^^^^^^^^^^^^^^^^^^^^^^^^^^^^^
  File "/home/ec2-user/test_form/.venv/lib64/python3.12/site-packages/pymysql/connections.py", line 825, in _read_query_result
    result.read()
  File "/home/ec2-user/test_form/.venv/lib64/python3.12/site-packages/pymysql/connections.py", line 1199, in read
    first_packet = self.connection._read_packet()
                   ^^^^^^^^^^^^^^^^^^^^^^^^^^^^^^
  File "/home/ec2-user/test_form/.venv/lib64/python3.12/site-packages/pymysql/connections.py", line 775, in _read_packet
    packet.raise_for_error()
  File "/home/ec2-user/test_form/.venv/lib64/python3.12/site-packages/pymysql/protocol.py", line 219, in raise_for_error
    err.raise_mysql_exception(self._data)
  File "/home/ec2-user/test_form/.venv/lib64/python3.12/site-packages/pymysql/err.py", line 150, in raise_mysql_exception
    raise errorclass(errno, errval)
pymysql.err.IntegrityError: (1062, "Duplicate entry 'adndsfsdjaasdsi123@csokm.com' for key 'users.email'")

The above exception was the direct cause of the following exception:

Traceback (most recent call last):
  File "/home/ec2-user/test_form/.venv/lib64/python3.12/site-packages/flask/app.py", line 1511, in wsgi_app
    response = self.full_dispatch_request()
               ^^^^^^^^^^^^^^^^^^^^^^^^^^^^
  File "/home/ec2-user/test_form/.venv/lib64/python3.12/site-packages/flask/app.py", line 919, in full_dispatch_request
    rv = self.handle_user_exception(e)
         ^^^^^^^^^^^^^^^^^^^^^^^^^^^^^
  File "/home/ec2-user/test_form/.venv/lib64/python3.12/site-packages/flask/app.py", line 917, in full_dispatch_request
    rv = self.dispatch_request()
         ^^^^^^^^^^^^^^^^^^^^^^^
  File "/home/ec2-user/test_form/.venv/lib64/python3.12/site-packages/flask/app.py", line 902, in dispatch_request
    return self.ensure_sync(self.view_functions[rule.endpoint])(**view_args)  # type: ignore[no-any-return]
           ^^^^^^^^^^^^^^^^^^^^^^^^^^^^^^^^^^^^^^^^^^^^^^^^^^^^^^^^^^^^^^^^^
  File "/home/ec2-user/test_form/app/routes.py", line 17, in signup_page
    user = users.create_user()
           ^^^^^^^^^^^^^^^^^^^
  File "/home/ec2-user/test_form/app/services/users.py", line 15, in create_user
    db.session.commit()
  File "/home/ec2-user/test_form/.venv/lib64/python3.12/site-packages/sqlalchemy/orm/scoping.py", line 599, in commit
    return self._proxied.commit()
           ^^^^^^^^^^^^^^^^^^^^^^
  File "/home/ec2-user/test_form/.venv/lib64/python3.12/site-packages/sqlalchemy/orm/session.py", line 2032, in commit
    trans.commit(_to_root=True)
  File "<string>", line 2, in commit
  File "/home/ec2-user/test_form/.venv/lib64/python3.12/site-packages/sqlalchemy/orm/state_changes.py", line 139, in _go
    ret_value = fn(self, *arg, **kw)
                ^^^^^^^^^^^^^^^^^^^^
  File "/home/ec2-user/test_form/.venv/lib64/python3.12/site-packages/sqlalchemy/orm/session.py", line 1313, in commit
    self._prepare_impl()
  File "<string>", line 2, in _prepare_impl
  File "/home/ec2-user/test_form/.venv/lib64/python3.12/site-packages/sqlalchemy/orm/state_changes.py", line 139, in _go
    ret_value = fn(self, *arg, **kw)
                ^^^^^^^^^^^^^^^^^^^^
  File "/home/ec2-user/test_form/.venv/lib64/python3.12/site-packages/sqlalchemy/orm/session.py", line 1288, in _prepare_impl
    self.session.flush()
  File "/home/ec2-user/test_form/.venv/lib64/python3.12/site-packages/sqlalchemy/orm/session.py", line 4353, in flush
    self._flush(objects)
  File "/home/ec2-user/test_form/.venv/lib64/python3.12/site-packages/sqlalchemy/orm/session.py", line 4488, in _flush
    with util.safe_reraise():
         ^^^^^^^^^^^^^^^^^^^
  File "/home/ec2-user/test_form/.venv/lib64/python3.12/site-packages/sqlalchemy/util/langhelpers.py", line 146, in __exit__
    raise exc_value.with_traceback(exc_tb)
  File "/home/ec2-user/test_form/.venv/lib64/python3.12/site-packages/sqlalchemy/orm/session.py", line 4449, in _flush
    flush_context.execute()
  File "/home/ec2-user/test_form/.venv/lib64/python3.12/site-packages/sqlalchemy/orm/unitofwork.py", line 466, in execute
    rec.execute(self)
  File "/home/ec2-user/test_form/.venv/lib64/python3.12/site-packages/sqlalchemy/orm/unitofwork.py", line 642, in execute
    util.preloaded.orm_persistence.save_obj(
  File "/home/ec2-user/test_form/.venv/lib64/python3.12/site-packages/sqlalchemy/orm/persistence.py", line 93, in save_obj
    _emit_insert_statements(
  File "/home/ec2-user/test_form/.venv/lib64/python3.12/site-packages/sqlalchemy/orm/persistence.py", line 1233, in _emit_insert_statements
    result = connection.execute(
             ^^^^^^^^^^^^^^^^^^^
  File "/home/ec2-user/test_form/.venv/lib64/python3.12/site-packages/sqlalchemy/engine/base.py", line 1416, in execute
    return meth(
           ^^^^^
  File "/home/ec2-user/test_form/.venv/lib64/python3.12/site-packages/sqlalchemy/sql/elements.py", line 515, in _execute_on_connection
    return connection._execute_clauseelement(
           ^^^^^^^^^^^^^^^^^^^^^^^^^^^^^^^^^^
  File "/home/ec2-user/test_form/.venv/lib64/python3.12/site-packages/sqlalchemy/engine/base.py", line 1638, in _execute_clauseelement
    ret = self._execute_context(
          ^^^^^^^^^^^^^^^^^^^^^^
  File "/home/ec2-user/test_form/.venv/lib64/python3.12/site-packages/sqlalchemy/engine/base.py", line 1843, in _execute_context
    return self._exec_single_context(
           ^^^^^^^^^^^^^^^^^^^^^^^^^^
  File "/home/ec2-user/test_form/.venv/lib64/python3.12/site-packages/sqlalchemy/engine/base.py", line 1983, in _exec_single_context
    self._handle_dbapi_exception(
  File "/home/ec2-user/test_form/.venv/lib64/python3.12/site-packages/sqlalchemy/engine/base.py", line 2352, in _handle_dbapi_exception
    raise sqlalchemy_exception.with_traceback(exc_info[2]) from e
  File "/home/ec2-user/test_form/.venv/lib64/python3.12/site-packages/sqlalchemy/engine/base.py", line 1964, in _exec_single_context
    self.dialect.do_execute(
  File "/home/ec2-user/test_form/.venv/lib64/python3.12/site-packages/sqlalchemy/engine/default.py", line 942, in do_execute
    cursor.execute(statement, parameters)
  File "/home/ec2-user/test_form/.venv/lib64/python3.12/site-packages/pymysql/cursors.py", line 153, in execute
    result = self._query(query)
             ^^^^^^^^^^^^^^^^^^
  File "/home/ec2-user/test_form/.venv/lib64/python3.12/site-packages/pymysql/cursors.py", line 322, in _query
    conn.query(q)
  File "/home/ec2-user/test_form/.venv/lib64/python3.12/site-packages/pymysql/connections.py", line 563, in query
    self._affected_rows = self._read_query_result(unbuffered=unbuffered)
                          ^^^^^^^^^^^^^^^^^^^^^^^^^^^^^^^^^^^^^^^^^^^^^^
  File "/home/ec2-user/test_form/.venv/lib64/python3.12/site-packages/pymysql/connections.py", line 825, in _read_query_result
    result.read()
  File "/home/ec2-user/test_form/.venv/lib64/python3.12/site-packages/pymysql/connections.py", line 1199, in read
    first_packet = self.connection._read_packet()
                   ^^^^^^^^^^^^^^^^^^^^^^^^^^^^^^
  File "/home/ec2-user/test_form/.venv/lib64/python3.12/site-packages/pymysql/connections.py", line 775, in _read_packet
    packet.raise_for_error()
  File "/home/ec2-user/test_form/.venv/lib64/python3.12/site-packages/pymysql/protocol.py", line 219, in raise_for_error
    err.raise_mysql_exception(self._data)
  File "/home/ec2-user/test_form/.venv/lib64/python3.12/site-packages/pymysql/err.py", line 150, in raise_mysql_exception
    raise errorclass(errno, errval)
sqlalchemy.exc.IntegrityError: (pymysql.err.IntegrityError) (1062, "Duplicate entry 'adndsfsdjaasdsi123@csokm.com' for key 'users.email'")
[SQL: INSERT INTO users (name, age, gender, email, created_at, updated_at) VALUES (%(name)s, %(age)s, %(gender)s, %(email)s, %(created_at)s, %(updated_at)s)]
[parameters: {'name': '도우미', 'age': 'teen', 'gender': 'male', 'email': 'adndsfsdjaasdsi123@csokm.com', 'created_at': datetime.datetime(2025, 1, 13, 14, 55, 25, 64189, tzinfo=zoneinfo.ZoneInfo(key='Asia/Seoul')), 'updated_at': datetime.datetime(2025, 1, 13, 14, 55, 25, 64196, tzinfo=zoneinfo.ZoneInfo(key='Asia/Seoul'))}]
(Background on this error at: https://sqlalche.me/e/20/gkpj)
[2025-01-13 06:00:13 +0000] [215944] [INFO] Handling signal: term
[2025-01-13 06:00:13 +0000] [215946] [INFO] Worker exiting (pid: 215946)
[2025-01-13 06:00:13 +0000] [215947] [INFO] Worker exiting (pid: 215947)
[2025-01-13 06:00:13 +0000] [215948] [INFO] Worker exiting (pid: 215948)
[2025-01-13 06:00:14 +0000] [215949] [INFO] Worker exiting (pid: 215949)
[2025-01-13 06:00:14 +0000] [215944] [ERROR] Worker (pid:215946) was sent SIGTERM!
[2025-01-13 06:00:14 +0000] [215944] [ERROR] Worker (pid:215947) was sent SIGTERM!
[2025-01-13 06:00:14 +0000] [215944] [ERROR] Worker (pid:215948) was sent SIGTERM!
[2025-01-13 06:00:14 +0000] [215944] [INFO] Shutting down: Master
[2025-01-13 06:00:16 +0000] [216503] [INFO] Starting gunicorn 23.0.0
[2025-01-13 06:00:16 +0000] [216503] [INFO] Listening at: http://127.0.0.1:8000 (216503)
[2025-01-13 06:00:16 +0000] [216503] [INFO] Using worker: sync
[2025-01-13 06:00:16 +0000] [216504] [INFO] Booting worker with pid: 216504
[2025-01-13 06:00:16 +0000] [216507] [INFO] Booting worker with pid: 216507
[2025-01-13 06:00:16 +0000] [216508] [INFO] Booting worker with pid: 216508
[2025-01-13 06:00:16 +0000] [216509] [INFO] Booting worker with pid: 216509
[2025-01-13 06:41:56 +0000] [216503] [INFO] Handling signal: term
[2025-01-13 06:41:56 +0000] [216504] [INFO] Worker exiting (pid: 216504)
[2025-01-13 06:41:56 +0000] [216507] [INFO] Worker exiting (pid: 216507)
[2025-01-13 06:41:56 +0000] [216508] [INFO] Worker exiting (pid: 216508)
[2025-01-13 06:41:56 +0000] [216509] [INFO] Worker exiting (pid: 216509)
[2025-01-13 06:41:56 +0000] [216503] [ERROR] Worker (pid:216504) was sent SIGTERM!
[2025-01-13 06:41:56 +0000] [216503] [ERROR] Worker (pid:216507) was sent SIGTERM!
[2025-01-13 06:41:57 +0000] [216503] [ERROR] Worker (pid:216508) was sent SIGTERM!
[2025-01-13 06:41:57 +0000] [216503] [INFO] Shutting down: Master
[2025-01-13 06:41:59 +0000] [218292] [INFO] Starting gunicorn 23.0.0
[2025-01-13 06:41:59 +0000] [218292] [INFO] Listening at: http://127.0.0.1:8000 (218292)
[2025-01-13 06:41:59 +0000] [218292] [INFO] Using worker: sync
[2025-01-13 06:41:59 +0000] [218293] [INFO] Booting worker with pid: 218293
[2025-01-13 06:42:00 +0000] [218295] [INFO] Booting worker with pid: 218295
[2025-01-13 06:42:00 +0000] [218297] [INFO] Booting worker with pid: 218297
[2025-01-13 06:42:00 +0000] [218299] [INFO] Booting worker with pid: 218299
[2025-01-13 06:46:19,628] ERROR in app: Exception on /questions/count [GET]
Traceback (most recent call last):
  File "/home/ec2-user/test_form/.venv/lib64/python3.12/site-packages/flask/app.py", line 1511, in wsgi_app
    response = self.full_dispatch_request()
               ^^^^^^^^^^^^^^^^^^^^^^^^^^^^
  File "/home/ec2-user/test_form/.venv/lib64/python3.12/site-packages/flask/app.py", line 919, in full_dispatch_request
    rv = self.handle_user_exception(e)
         ^^^^^^^^^^^^^^^^^^^^^^^^^^^^^
  File "/home/ec2-user/test_form/.venv/lib64/python3.12/site-packages/flask/app.py", line 917, in full_dispatch_request
    rv = self.dispatch_request()
         ^^^^^^^^^^^^^^^^^^^^^^^
  File "/home/ec2-user/test_form/.venv/lib64/python3.12/site-packages/flask/app.py", line 902, in dispatch_request
    return self.ensure_sync(self.view_functions[rule.endpoint])(**view_args)  # type: ignore[no-any-return]
           ^^^^^^^^^^^^^^^^^^^^^^^^^^^^^^^^^^^^^^^^^^^^^^^^^^^^^^^^^^^^^^^^^
  File "/home/ec2-user/test_form/app/routes.py", line 49, in count_question
    return  jasonify({"total": count})
            ^^^^^^^^
NameError: name 'jasonify' is not defined. Did you mean: 'jsonify'?
[2025-01-13 06:47:36 +0000] [218292] [INFO] Handling signal: term
[2025-01-13 06:47:36 +0000] [218293] [INFO] Worker exiting (pid: 218293)
[2025-01-13 06:47:36 +0000] [218295] [INFO] Worker exiting (pid: 218295)
[2025-01-13 06:47:36 +0000] [218297] [INFO] Worker exiting (pid: 218297)
[2025-01-13 06:47:36 +0000] [218299] [INFO] Worker exiting (pid: 218299)
[2025-01-13 06:47:37 +0000] [218292] [ERROR] Worker (pid:218293) was sent SIGTERM!
[2025-01-13 06:47:37 +0000] [218292] [ERROR] Worker (pid:218295) was sent SIGTERM!
[2025-01-13 06:47:37 +0000] [218292] [ERROR] Worker (pid:218297) was sent SIGTERM!
[2025-01-13 06:47:37 +0000] [218292] [INFO] Shutting down: Master
[2025-01-13 06:47:38 +0000] [219260] [INFO] Starting gunicorn 23.0.0
[2025-01-13 06:47:38 +0000] [219260] [INFO] Listening at: http://127.0.0.1:8000 (219260)
[2025-01-13 06:47:38 +0000] [219260] [INFO] Using worker: sync
[2025-01-13 06:47:38 +0000] [219262] [INFO] Booting worker with pid: 219262
[2025-01-13 06:47:38 +0000] [219263] [INFO] Booting worker with pid: 219263
[2025-01-13 06:47:38 +0000] [219266] [INFO] Booting worker with pid: 219266
[2025-01-13 06:47:39 +0000] [219267] [INFO] Booting worker with pid: 219267
[2025-01-13 06:48:15,150] ERROR in app: Exception on /answer [POST]
Traceback (most recent call last):
  File "/home/ec2-user/test_form/.venv/lib64/python3.12/site-packages/flask/app.py", line 1511, in wsgi_app
    response = self.full_dispatch_request()
               ^^^^^^^^^^^^^^^^^^^^^^^^^^^^
  File "/home/ec2-user/test_form/.venv/lib64/python3.12/site-packages/flask/app.py", line 919, in full_dispatch_request
    rv = self.handle_user_exception(e)
         ^^^^^^^^^^^^^^^^^^^^^^^^^^^^^
  File "/home/ec2-user/test_form/.venv/lib64/python3.12/site-packages/flask/app.py", line 917, in full_dispatch_request
    rv = self.dispatch_request()
         ^^^^^^^^^^^^^^^^^^^^^^^
  File "/home/ec2-user/test_form/.venv/lib64/python3.12/site-packages/flask/app.py", line 902, in dispatch_request
    return self.ensure_sync(self.view_functions[rule.endpoint])(**view_args)  # type: ignore[no-any-return]
           ^^^^^^^^^^^^^^^^^^^^^^^^^^^^^^^^^^^^^^^^^^^^^^^^^^^^^^^^^^^^^^^^^
  File "/home/ec2-user/test_form/app/routes.py", line 98, in create_answer
    print(request.get_jason())
          ^^^^^^^^^^^^^^^^^
AttributeError: 'Request' object has no attribute 'get_jason'. Did you mean: 'get_json'?
[2025-01-13 06:50:21 +0000] [219260] [INFO] Handling signal: term
[2025-01-13 06:50:21 +0000] [219262] [INFO] Worker exiting (pid: 219262)
[2025-01-13 06:50:21 +0000] [219263] [INFO] Worker exiting (pid: 219263)
[2025-01-13 06:50:21 +0000] [219266] [INFO] Worker exiting (pid: 219266)
[2025-01-13 06:50:21 +0000] [219267] [INFO] Worker exiting (pid: 219267)
[2025-01-13 06:50:21 +0000] [219260] [ERROR] Worker (pid:219262) was sent SIGTERM!
[2025-01-13 06:50:22 +0000] [219260] [ERROR] Worker (pid:219263) was sent SIGTERM!
[2025-01-13 06:50:22 +0000] [219260] [ERROR] Worker (pid:219266) was sent SIGTERM!
[2025-01-13 06:50:22 +0000] [219260] [INFO] Shutting down: Master
[2025-01-13 06:50:24 +0000] [220055] [INFO] Starting gunicorn 23.0.0
[2025-01-13 06:50:24 +0000] [220055] [INFO] Listening at: http://127.0.0.1:8000 (220055)
[2025-01-13 06:50:24 +0000] [220055] [INFO] Using worker: sync
[2025-01-13 06:50:24 +0000] [220056] [INFO] Booting worker with pid: 220056
[2025-01-13 06:50:24 +0000] [220057] [INFO] Booting worker with pid: 220057
[2025-01-13 06:50:24 +0000] [220060] [INFO] Booting worker with pid: 220060
[2025-01-13 06:50:24 +0000] [220061] [INFO] Booting worker with pid: 220061
[2025-01-13 06:50:31,217] ERROR in app: Exception on /answer [POST]
Traceback (most recent call last):
  File "/home/ec2-user/test_form/.venv/lib64/python3.12/site-packages/flask/app.py", line 1511, in wsgi_app
    response = self.full_dispatch_request()
               ^^^^^^^^^^^^^^^^^^^^^^^^^^^^
  File "/home/ec2-user/test_form/.venv/lib64/python3.12/site-packages/flask/app.py", line 919, in full_dispatch_request
    rv = self.handle_user_exception(e)
         ^^^^^^^^^^^^^^^^^^^^^^^^^^^^^
  File "/home/ec2-user/test_form/.venv/lib64/python3.12/site-packages/flask/app.py", line 917, in full_dispatch_request
    rv = self.dispatch_request()
         ^^^^^^^^^^^^^^^^^^^^^^^
  File "/home/ec2-user/test_form/.venv/lib64/python3.12/site-packages/flask/app.py", line 902, in dispatch_request
    return self.ensure_sync(self.view_functions[rule.endpoint])(**view_args)  # type: ignore[no-any-return]
           ^^^^^^^^^^^^^^^^^^^^^^^^^^^^^^^^^^^^^^^^^^^^^^^^^^^^^^^^^^^^^^^^^
  File "/home/ec2-user/test_form/app/routes.py", line 99, in create_answer
    answer = answers.create_answer(request.get_json())
             ^^^^^^^^^^^^^^^^^^^^^^^^^^^^^^^^^^^^^^^^^
  File "/home/ec2-user/test_form/app/services/answers.py", line 10, in create_answer
    user_id=data['user_id'],
            ~~~~^^^^^^^^^^^
TypeError: list indices must be integers or slices, not str
[2025-01-13 06:52:40,713] ERROR in app: Exception on /answer [POST]
Traceback (most recent call last):
  File "/home/ec2-user/test_form/.venv/lib64/python3.12/site-packages/flask/app.py", line 1511, in wsgi_app
    response = self.full_dispatch_request()
               ^^^^^^^^^^^^^^^^^^^^^^^^^^^^
  File "/home/ec2-user/test_form/.venv/lib64/python3.12/site-packages/flask/app.py", line 919, in full_dispatch_request
    rv = self.handle_user_exception(e)
         ^^^^^^^^^^^^^^^^^^^^^^^^^^^^^
  File "/home/ec2-user/test_form/.venv/lib64/python3.12/site-packages/flask/app.py", line 917, in full_dispatch_request
    rv = self.dispatch_request()
         ^^^^^^^^^^^^^^^^^^^^^^^
  File "/home/ec2-user/test_form/.venv/lib64/python3.12/site-packages/flask/app.py", line 902, in dispatch_request
    return self.ensure_sync(self.view_functions[rule.endpoint])(**view_args)  # type: ignore[no-any-return]
           ^^^^^^^^^^^^^^^^^^^^^^^^^^^^^^^^^^^^^^^^^^^^^^^^^^^^^^^^^^^^^^^^^
  File "/home/ec2-user/test_form/app/routes.py", line 99, in create_answer
    answer = answers.create_answer(request.get_json())
             ^^^^^^^^^^^^^^^^^^^^^^^^^^^^^^^^^^^^^^^^^
  File "/home/ec2-user/test_form/app/services/answers.py", line 10, in create_answer
    user_id=data['user_id'],
            ~~~~^^^^^^^^^^^
TypeError: list indices must be integers or slices, not str
[2025-01-13 06:53:25 +0000] [220055] [INFO] Handling signal: term
[2025-01-13 06:53:25 +0000] [220056] [INFO] Worker exiting (pid: 220056)
[2025-01-13 06:53:25 +0000] [220057] [INFO] Worker exiting (pid: 220057)
[2025-01-13 06:53:25 +0000] [220060] [INFO] Worker exiting (pid: 220060)
[2025-01-13 06:53:25 +0000] [220061] [INFO] Worker exiting (pid: 220061)
[2025-01-13 06:53:26 +0000] [220055] [ERROR] Worker (pid:220056) was sent SIGTERM!
[2025-01-13 06:53:26 +0000] [220055] [ERROR] Worker (pid:220057) was sent SIGTERM!
[2025-01-13 06:53:26 +0000] [220055] [ERROR] Worker (pid:220060) was sent SIGTERM!
[2025-01-13 06:53:26 +0000] [220055] [INFO] Shutting down: Master
[2025-01-13 06:53:28 +0000] [221137] [INFO] Starting gunicorn 23.0.0
[2025-01-13 06:53:28 +0000] [221137] [INFO] Listening at: http://127.0.0.1:8000 (221137)
[2025-01-13 06:53:28 +0000] [221137] [INFO] Using worker: sync
[2025-01-13 06:53:28 +0000] [221139] [INFO] Booting worker with pid: 221139
[2025-01-13 06:53:28 +0000] [221140] [INFO] Booting worker with pid: 221140
[2025-01-13 06:53:28 +0000] [221142] [INFO] Booting worker with pid: 221142
[2025-01-13 06:53:28 +0000] [221144] [INFO] Booting worker with pid: 221144
[2025-01-13 06:53:32,280] ERROR in app: Exception on /answer [POST]
Traceback (most recent call last):
  File "/home/ec2-user/test_form/.venv/lib64/python3.12/site-packages/flask/app.py", line 1511, in wsgi_app
    response = self.full_dispatch_request()
               ^^^^^^^^^^^^^^^^^^^^^^^^^^^^
  File "/home/ec2-user/test_form/.venv/lib64/python3.12/site-packages/flask/app.py", line 919, in full_dispatch_request
    rv = self.handle_user_exception(e)
         ^^^^^^^^^^^^^^^^^^^^^^^^^^^^^
  File "/home/ec2-user/test_form/.venv/lib64/python3.12/site-packages/flask/app.py", line 917, in full_dispatch_request
    rv = self.dispatch_request()
         ^^^^^^^^^^^^^^^^^^^^^^^
  File "/home/ec2-user/test_form/.venv/lib64/python3.12/site-packages/flask/app.py", line 902, in dispatch_request
    return self.ensure_sync(self.view_functions[rule.endpoint])(**view_args)  # type: ignore[no-any-return]
           ^^^^^^^^^^^^^^^^^^^^^^^^^^^^^^^^^^^^^^^^^^^^^^^^^^^^^^^^^^^^^^^^^
  File "/home/ec2-user/test_form/app/routes.py", line 99, in create_answer
    answer = answers.create_answer(request.get_json())
             ^^^^^^^^^^^^^^^^^^^^^^^^^^^^^^^^^^^^^^^^^
  File "/home/ec2-user/test_form/app/services/answers.py", line 10, in create_answer
    user_id=data['user_id'],
            ~~~~^^^^^^^^^^^
TypeError: list indices must be integers or slices, not str
[2025-01-13 06:57:33 +0000] [221137] [INFO] Handling signal: term
[2025-01-13 06:57:33 +0000] [221139] [INFO] Worker exiting (pid: 221139)
[2025-01-13 06:57:33 +0000] [221140] [INFO] Worker exiting (pid: 221140)
[2025-01-13 06:57:33 +0000] [221142] [INFO] Worker exiting (pid: 221142)
[2025-01-13 06:57:33 +0000] [221144] [INFO] Worker exiting (pid: 221144)
[2025-01-13 06:57:34 +0000] [221137] [ERROR] Worker (pid:221139) was sent SIGTERM!
[2025-01-13 06:57:34 +0000] [221137] [ERROR] Worker (pid:221140) was sent SIGTERM!
[2025-01-13 06:57:34 +0000] [221137] [ERROR] Worker (pid:221142) was sent SIGTERM!
[2025-01-13 06:57:34 +0000] [221137] [INFO] Shutting down: Master
[2025-01-13 06:57:36 +0000] [221637] [INFO] Starting gunicorn 23.0.0
[2025-01-13 06:57:36 +0000] [221637] [INFO] Listening at: http://127.0.0.1:8000 (221637)
[2025-01-13 06:57:36 +0000] [221637] [INFO] Using worker: sync
[2025-01-13 06:57:36 +0000] [221638] [INFO] Booting worker with pid: 221638
[2025-01-13 06:57:36 +0000] [221639] [INFO] Booting worker with pid: 221639
[2025-01-13 06:57:36 +0000] [221642] [INFO] Booting worker with pid: 221642
[2025-01-13 06:57:36 +0000] [221643] [INFO] Booting worker with pid: 221643
